Workbook

Sheet Rate
A1: Material | C1: Rate
A2: Cement | B2: Bag | C2: 22000
A3: R/Sand | B3: Sud | C3: 56000
A4: Brick | B4: No | C4: 280
A5: X-Met | B5: Rft | C5: 150
A6: Chipping | B6: Sud | C6: 220000
A7: Hardcore | B7: Sud | C7: 200000
A8: Bonding Agent | B8: Lit
A9: Early Strength (0.5Lit/1M³) | B9: Lit
A10: Fuel | B10: Gal | C10: 15000
A11: 5 Ply Wood | B11: Sht | C11: 60000
A12: J/Wood | B12: Ton | C12: 1200000
A13: Wire Nail | B13: Viss | C13: 10000
A14: Concrete Nail (1½") | B14: Box
A15: Concrete Nail (2") | B15: Box
A16: M.S Rod
A17: 6.5 mm Ø M.S Rod | B17: Ton | C17: 2800000
A18: 10 mm Ø M.S Rod | B18: Ton | C18: 2500000
A19: 16 mm Ø M.S Rod | B19: Ton | C19: 2200000
A21: Binding Wire | B21: viss | C21: 12000
A22: Roofing Sheet (Amcan) | B22: Rft. | C22: 4000
A23: Roofing Secrew | B23: Gross | C23: 9000
A24: 5"x5"Hollow | B24: No | C24: 100000
A25: 5" x 2.5" x 1.4 mm thk; Hollow | B25: No | C25: 55000
A26: 4"x2" Hollow (1.4mm thk;) | B26: No | C26: 45000
A27: 3" x 1.5" Hollow (1.2mm thk;) | B27: No | C27: 30000
A28: 1½" x 1½" x¼" thk; Angle | B28: No | C28: 45000
A29: Silicon | B29: No
A30: Welding Rod | B30: Pkt | C30: 20000
A31: Ridge Cover | B31: Rft | C31: 3000
A32: 10" Eave Board | B32: Ft | C32: 1500
A33: 3/4" x 3/4" Hollow | B33: No | C33: 18000
A34: Gutter | B34: Fr | C34: 5000
A35: Gutter Bracket | B35: No | C35: 1800
A36: 5"x 3" Chowket | B36: Ft | C36: 15000
A37: 5"x 2" Chowket | B37: Ft | C37: 9000
A38: Bracket | B38: No | C38: 1000
A39: Coal Tar | B39: Gal | C39: 10000
A40: Bamboo | B40: No | C40: 2000
A41: Coiryarn | B41: Viss | C41: 15000
...

Sheet SUM
A1: NAY PYI TAW
A2: One Storeyed RCC Building (46' 2" X 42' 6")
A3: Main Building (အုတ္စီ၊ ေခ်ာ၊ က်ည္းေဘာင္ေထာင္၊ အမိုးမိုး)
A4: Item | B4: Description | C4: Amount | D4: Remark
A5: 1 | B5: - Material Cost | C5: ='BQ '!G44 -> 86923110
A6: 2 | B6: - Labour Cost | C6: ='BQ '!G53 -> 41452330
A7: Total (Material + Labour) Amount | C7: =SUM(C5:C6) -> 128375440
B8: Transportation Charges (3% of Material) | C8: =ROUND(C5*0.03,-3) -> 2608000
A9: Preliminary Cost (5%) | C9: =ROUND(C7*0.05,-3) -> 6419000
A10: - Overhead & Contingency Charges (2%) | C10: =ROUND(C7*0.02,-3) -> 2568000
A11: Supervision Charges (10%) | C11: =ROUND(C7*0.1,-3) -> 12838000
A12: Total Cost | C12: =SUM(C7:C11) -> 152808440
A13: Say | C13: =ROUND(C12,-3) -> 152808000

Sheet BQ 
A1: One Storeyed RCC Building (46' 2" X 42' 6")
A2: Main Building (အုတ္စီ၊ ေခ်ာ၊ က်ည္းေဘာင္ေထာင္၊ အမိုးမိုး)
A3: Bill of Quantity
A4: No. | B4: Particular | C4: Unit | D4: Quantity | E4: Rate | F4: Per | G4: Amount
B6: Material
A7: 1 | B7: Cement | C7: Bag | D7: =SUMIF(Buil!B$6:B325,'BQ '!B7,Buil!D$6:D325) -> 792.61 | E7: =VLOOKUP(B7,Rate!A$1:C56,3,FALSE) -> 22000 | F7: =C7 -> Bag | G7: =D7*E7 -> 17437420 | J7: =J53 -> 0
A8: 2 | B8: R/Sand | C8: Sud | D8: =SUMIF(Buil!B$6:B326,'BQ '!B8,Buil!D$6:D326) -> 64.46 | E8: =VLOOKUP(B8,Rate!A$1:C57,3,FALSE) -> 56000 | F8: =C8 -> Sud | G8: =D8*E8 -> 3609760
A9: 3 | B9: Brick | C9: No | D9: =SUMIF(Buil!B$6:B327,'BQ '!B9,Buil!D$6:D327) -> 38335 | E9: =VLOOKUP(B9,Rate!A$1:C58,3,FALSE) -> 280 | F9: =C9 -> No | G9: =D9*E9 -> 10733800
A10: 4 | B10: X-Met | C10: Rft | D10: =SUMIF(Buil!B$6:B328,'BQ '!B10,Buil!D$6:D328) -> 3400 | E10: =VLOOKUP(B10,Rate!A$1:C59,3,FALSE) -> 150 | F10: =C10 -> Rft | G10: =D10*E10 -> 510000
A11: 5 | B11: Chipping | C11: Sud | D11: =SUMIF(Buil!B$6:B328,'BQ '!B11,Buil!D$6:D328) -> 26.44 | E11: =VLOOKUP(B11,Rate!A$1:C59,3,FALSE) -> 220000 | F11: =C11 -> Sud | G11: =D11*E11 -> 5816800
A12: 6 | B12: Hardcore | C12: Sud | D12: =SUMIF(Buil!B$6:B329,'BQ '!B12,Buil!D$6:D329) -> 4.66 | E12: =VLOOKUP(B12,Rate!A$1:C60,3,FALSE) -> 200000 | F12: =C12 -> Sud | G12: =D12*E12 -> 932000
A13: 7 | B13: Fuel | C13: Gal | D13: =SUMIF(Buil!B$6:B330,'BQ '!B13,Buil!D$6:D330) -> 52.08 | E13: =VLOOKUP(B13,Rate!A$1:C61,3,FALSE) -> 15000 | F13: =C13 -> Gal | G13: =D13*E13 -> 781200 | J13: =J7 -> 0
A14: 8 | B14: Bonding Agent | C14: Lit | D14: =SUMIF(Buil!B$6:B331,'BQ '!B14,Buil!D$6:D331) -> 2 | E14: =VLOOKUP(B14,Rate!A$1:C62,3,FALSE) -> 0 | F14: =C14 -> Lit | G14: =D14*E14 -> 0
A15: 9 | B15: Early Strength (0.5Lit/1M³) | C15: Lit | D15: =SUMIF(Buil!B$6:B331,'BQ '!B15,Buil!D$6:D331) -> 6 | E15: =VLOOKUP(B15,Rate!A$1:C62,3,FALSE) -> 0 | F15: =C15 -> Lit | G15: =D15*E15 -> 0
A16: 10 | B16: 5 Ply Wood | C16: Sht | D16: =SUMIF(Buil!B$6:B331,'BQ '!B16,Buil!D$6:D331) -> 60.82 | E16: =VLOOKUP(B16,Rate!A$1:C62,3,FALSE) -> 60000 | F16: =C16 -> Sht | G16: =D16*E16 -> 3649200
A17: 11 | B17: J/Wood | C17: Ton | D17: =SUMIF(Buil!B$6:B332,'BQ '!B17,Buil!D$6:D332) -> 5.13 | E17: =VLOOKUP(B17,Rate!A$1:C63,3,FALSE) -> 1200000 | F17: =C17 -> Ton | G17: =D17*E17 -> 6156000
A18: 12 | B18: Wire Nail | C18: Viss | D18: =SUMIF(Buil!B$6:B333,'BQ '!B18,Buil!D$6:D333) -> 47.72 | E18: =VLOOKUP(B18,Rate!A$1:C64,3,FALSE) -> 10000 | F18: =C18 -> Viss | G18: =D18*E18 -> 477200
A19: 13 | B19: Concrete Nail (1½") | C19: Box | D19: =SUMIF(Buil!B$6:B334,'BQ '!B19,Buil!D$6:D334) -> 1 | E19: =VLOOKUP(B19,Rate!A$1:C65,3,FALSE) -> 0 | F19: =C19 -> Box | G19: =D19*E19 -> 0 | J19: =J13 -> 0
A20: 14 | B20: Concrete Nail (2") | C20: Box | D20: =SUMIF(Buil!B$6:B335,'BQ '!B20,Buil!D$6:D335) -> 1 | E20: =VLOOKUP(B20,Rate!A$1:C66,3,FALSE) -> 0 | F20: =C20 -> Box | G20: =D20*E20 -> 0
A21: 15 | B21: M.S Rod
B22: 6.5 mm Ø M.S Rod | C22: Ton | D22: =SUMIF(Buil!B$6:B335,'BQ '!B22,Buil!D$6:D335) -> 0.05 | E22: =VLOOKUP(B22,Rate!A$1:C66,3,FALSE) -> 2800000 | F22: =C22 -> Ton | G22: =D22*E22 -> 140000
B23: 10 mm Ø M.S Rod | C23: Ton | D23: =SUMIF(Buil!B$6:B336,'BQ '!B23,Buil!D$6:D336) -> 2.92 | E23: =VLOOKUP(B23,Rate!A$1:C67,3,FALSE) -> 2500000 | F23: =C23 -> Ton | G23: =D23*E23 -> 7300000
B24: 16 mm Ø M.S Rod | C24: Ton | D24: =SUMIF(Buil!B$6:B337,'BQ '!B24,Buil!D$6:D337) -> 6.51 | E24: =VLOOKUP(B24,Rate!A$1:C68,3,FALSE) -> 2200000 | F24: =C24 -> Ton | G24: =D24*E24 -> 14322000
D25: =SUM(D22:D24) -> 9.48 | J25: =J19 -> 0
A26: 16 | B26: Binding Wire | C26: viss | D26: =SUMIF(Buil!B$6:B339,'BQ '!B26,Buil!D$6:D339) -> 48.39 | E26: =VLOOKUP(B26,Rate!A$1:C70,3,FALSE) -> 12000 | F26: =C26 -> viss | G26: =D26*E26 -> 580680
A27: 17 | B27: Roofing Sheet (Amcan) | C27: =Buil!C239 -> Rft. | D27: =SUMIF(Buil!B$6:B340,'BQ '!B27,Buil!D$6:D340) -> 1273 | E27: =VLOOKUP(B27,Rate!A$1:C71,3,FALSE) -> 4000 | F27: =C27 -> Rft. | G27: =D27*E27 -> 5092000
A28: 18 | B28: Roofing Secrew | C28: =Buil!C240 -> Gross | D28: =SUMIF(Buil!B$6:B341,'BQ '!B28,Buil!D$6:D341) -> 17.3 | E28: =VLOOKUP(B28,Rate!A$1:C72,3,FALSE) -> 9000 | F28: =C28 -> Gross | G28: =D28*E28 -> 155700
A29: 19 | B29: 5"x5"Hollow | C29: No | D29: =Buil!D254 -> 1 | E29: =VLOOKUP(B29,Rate!A$1:C73,3,FALSE) -> 100000 | F29: =C29 -> No | G29: =D29*E29 -> 100000
A30: 20 | B30: 5" x 2.5" x 1.4 mm thk; Hollow | C30: =Buil!C255 -> No | D30: =SUMIF(Buil!B$6:B342,'BQ '!B30,Buil!D$6:D342) -> 18.69 | E30: =VLOOKUP(B30,Rate!A$1:C73,3,FALSE) -> 55000 | F30: =C30 -> No | G30: =D30*E30 -> 1027950
A31: 21 | B31: 4"x2" Hollow (1.4mm thk;) | C31: =Buil!C256 -> No | D31: =SUMIF(Buil!B$6:B343,'BQ '!B31,Buil!D$6:D343) -> 40.66 | E31: =VLOOKUP(B31,Rate!A$1:C74,3,FALSE) -> 45000 | F31: =C31 -> No | G31: =D31*E31 -> 1829700
A32: 22 | B32: 3" x 1.5" Hollow (1.2mm thk;) | C32: =Buil!C257 -> No | D32: =SUMIF(Buil!B$6:B344,'BQ '!B32,Buil!D$6:D344) -> 94.42 | E32: =VLOOKUP(B32,Rate!A$1:C75,3,FALSE) -> 30000 | F32: =C32 -> No | G32: =D32*E32 -> 2832600
A33: 23 | B33: 1½" x 1½" x¼" thk; Angle | C33: =Buil!C258 -> No | D33: =SUMIF(Buil!B$6:B345,'BQ '!B33,Buil!D$6:D345) -> 1.92 | E33: =VLOOKUP(B33,Rate!A$1:C76,3,FALSE) -> 45000 | F33: =C33 -> No | G33: =D33*E33 -> 86400 | J33: =J25 -> 0
A34: 24 | B34: Silicon | C34: No | D34: =SUMIF(Buil!B$6:B346,'BQ '!B34,Buil!D$6:D346) -> 7 | E34: =VLOOKUP(B34,Rate!A$1:C77,3,FALSE) -> 0 | F34: =C34 -> No | G34: =D34*E34 -> 0
A35: 25 | B35: Welding Rod | C35: =Buil!C260 -> Pkt | D35: =SUMIF(Buil!B$6:B346,'BQ '!B35,Buil!D$6:D346) -> 3 | E35: =VLOOKUP(B35,Rate!A$1:C77,3,FALSE) -> 20000 | F35: =C35 -> Pkt | G35: =D35*E35 -> 60000
A36: 26 | B36: Ridge Cover | C36: =Buil!C267 -> Rft | D36: =SUMIF(Buil!B$6:B347,'BQ '!B36,Buil!D$6:D347) -> 305.65 | E36: =VLOOKUP(B36,Rate!A$1:C78,3,FALSE) -> 3000 | F36: =C36 -> Rft | G36: =D36*E36 -> 916950 | J36: =J26 -> 0
A37: 27 | B37: 5"x 3" Chowket | C37: Ft | D37: =SUMIF(Buil!B$6:B351,'BQ '!B37,Buil!D$6:D351) -> 41.5 | E37: =VLOOKUP(B37,Rate!A$1:C82,3,FALSE) -> 15000 | F37: =C37 -> Ft | G37: =D37*E37 -> 622500
A38: 28 | B38: 5"x 2" Chowket | C38: Ft | D38: =SUMIF(Buil!B$6:B352,'BQ '!B38,Buil!D$6:D352) -> 150 | E38: =VLOOKUP(B38,Rate!A$1:C83,3,FALSE) -> 9000 | F38: =C38 -> Ft | G38: =D38*E38 -> 1350000
A39: 29 | B39: Bracket | C39: No | D39: =SUMIF(Buil!B$6:B353,'BQ '!B39,Buil!D$6:D353) -> 74 | E39: =VLOOKUP(B39,Rate!A$1:C84,3,FALSE) -> 1000 | F39: =C39 -> No | G39: =D39*E39 -> 74000 | J39: =J33 -> 0
A40: 30 | B40: Coal Tar | C40: Gal | D40: =SUMIF(Buil!B$6:B354,'BQ '!B40,Buil!D$6:D354) -> 0.6 | E40: =VLOOKUP(B40,Rate!A$1:C85,3,FALSE) -> 10000 | F40: =C40 -> Gal | G40: =D40*E40 -> 6000
A41: 31 | B41: Bamboo | C41: No | D41: =SUMIF(Buil!B$6:B355,'BQ '!B41,Buil!D$6:D355) -> 78 | E41: =VLOOKUP(B41,Rate!A$1:C86,3,FALSE) -> 2000 | F41: =C41 -> No | G41: =D41*E41 -> 156000
...

Sheet ABS(M+L)
A1: ='BQ '!A1:G1 -> One Storeyed RCC Building (46' 2" X 42' 6")
A2: ='BQ '!A2:G2 -> Main Building (အုတ္စီ၊ ေခ်ာ၊ က်ည္းေဘာင္ေထာင္၊ အမိုးမိုး)
A3: Abstract Of Costs
A4: Sr | B4: Quantity | C4: Unit | D4: Particulars | E4: Rate | F4: Per | G4: Amount
A6: 1 | B6: =Buil!D7 -> 44.88 | C6: %Fs | D6: Site Clearing Work | E6: =G6/B6 -> 4500 | F6: =C6 -> %Fs | G6: =Buil!G10 -> 201960
A7: 2 | B7: =Buil!D12 -> 3248 | C7: Fs | D7: Staking Works For Preparation of Foundation | E7: =G7/B7 -> 57.2 | F7: =C7 -> Fs | G7: =Buil!G20 -> 185800
A8: =Buil!A23 -> 3 | B8: =Buil!D23 -> 60.25 | C8: %Fc | D8: Earth Work | E8: =G8/B8 -> 54000 | F8: =C8 -> %Fc | G8: =Buil!G26 -> 3253500
A9: =Buil!A28 -> 4 | B9: =Buil!D28 -> 4.66 | C9: =Buil!C28 -> %Fc | D9: =Buil!B28 -> 6" Thk; Hardcore with Sand Filling Work | G9: =Buil!G35 -> 1097710
A10: =Buil!A37 -> 5 | B10: =Buil!D37 -> 4.79 | C10: %Fc | D10: 3" thk; (1:3:6) Lean Conc; Work | E10: =G10/B10 -> 696565.76 | F10: =C10 -> %Fc | G10: =Buil!G47 -> 3336550
A11: =Buil!A49 -> 6 | B11: =Buil!D49 -> 16.26 | C11: %Fc | D11: Retaining Wall Work | E11: =G11/B11 -> 753783.52 | F11: =C11 -> %Fc | G11: =Buil!G57 -> 12256520
A12: =Buil!A59 -> 7 | D12: =Buil!B59 -> Concrete Casting Work For Footing
B13: =Buil!D60 -> 3.34 | C13: %Fc | D13: ( a ) (1:2:4) R.C Conc; Work | E13: =G13/B13 -> 889140.72 | F13: =C13 -> %Fc | G13: =Buil!G70 -> 2969730
B14: =Buil!D72 -> 3.22 | C14: %Fs | D14: ( b ) Formwork Work | E14: =G14/B14 -> 335503.11 | F14: =C14 -> %Fs | G14: =Buil!G80 -> 1080320
B15: =Buil!D82 -> 0.86 | C15: Ton | D15: ( c ) Rebar Work | E15: =G15/B15 -> 3014023.3 | F15: =C15 -> Ton | G15: =Buil!G90 -> 2592060
A17: =Buil!A92 -> 8 | D17: Concrete Casting Work For Column
B18: =Buil!D93 -> 3.82 | C18: %Fc | D18: ( a ) (1:2:4) R.C Conc; Work | E18: =G18/B18 -> 943044.5 | F18: =C18 -> %Fc | G18: =Buil!G104 -> 3602430
B19: =Buil!D106 -> 18.39 | C19: %Fs | D19: ( b ) Formwork Work | E19: =G19/B19 -> 336277.32 | F19: =C19 -> %Fs | G19: =Buil!G114 -> 6184140
B20: =Buil!D116 -> 2.93 | C20: Ton | D20: ( c ) Rebar Work | E20: =G20/B20 -> 3488587 | F20: =C20 -> Ton | G20: =Buil!G126 -> 10221560
A22: =Buil!A127 -> 9 | D22: R.C Conc; Casting Work Beam & Slab
B23: =Buil!D128 -> 7.74 | C23: %Fc | D23: ( a ) (1:2:4) R.C Conc; Casting Work | E23: =G23/B23 -> 889236.43 | F23: =C23 -> %Fc | G23: =Buil!G140 -> 6882690
B24: =Buil!D142 -> 23.73 | C24: %Fs | D24: ( b ) Formwork Work | E24: =G24/B24 -> 336067.43 | F24: =C24 -> %Fs | G24: =Buil!G152 -> 7974880
B25: =Buil!D153 -> 4.92 | C25: Ton | D25: ( c ) Rebar Work | E25: =G25/B25 -> 3189089.4 | F25: =C25 -> Ton | G25: =Buil!G165 -> 15690320
A26: =Buil!A166 -> 10 | B26: =Buil!D166 -> 2978.81 | C26: =Buil!C166 -> Fs | D26: =Buil!B166 -> 4½" Thk; Brick Walling Work | G26: =Buil!G176 -> 10078560
A27: =Buil!A178 -> 11 | D27: =Buil!B178 -> Lintel & Stiffener Work
B28: =Buil!D179 -> 1.03 | C28: =Buil!C179 -> %Fc | D28: =Buil!B179 -> ( a ) ( 1:2:4) RCC Concrete Work | E28: =G28/B28 -> 943766.99 | F28: =C28 -> %Fc | G28: =Buil!G189 -> 972080
B29: =Buil!D191 -> 5.43 | C29: =Buil!C191 -> %Fs | D29: =Buil!B191 -> ( b ) Formwork (3 Times used) | E29: =G29/B29 -> 335502.76 | F29: =C29 -> %Fs | G29: =Buil!G199 -> 1821780
B30: =Buil!D202+Buil!D203 -> 0.32 | C30: Ton | D30: =Buil!B201 -> ( c ) Re bar Work | E30: =G30/B30 -> 3892156.2 | F30: =C30 -> Ton | G30: =Buil!G212 -> 1245490
A31: =Buil!A214 -> 12 | B31: =Buil!D214 -> 8076.25 | C31: =Buil!C214 -> Fs | D31: =Buil!B214 -> Plastering Work | E31: =G31/B31 -> 1325.28 | F31: =C31 -> Fs | G31: =Buil!G222 -> 10703300
A32: =Buil!A224 -> 13 | B32: =Buil!D224 -> 191.5 | C32: =Buil!C224 -> Ft | D32: =Buil!B224 -> Providing & Fixing of Chowket Work | E32: =G32/B32 -> 11968.67 | F32: =C32 -> Ft | G32: =Buil!G235 -> 2292000
A33: =Buil!A236 -> 14 | D33: =Buil!B236 -> Roofing Work
B34: =Buil!D237 -> 2490.89 | C34: =Buil!C237 -> Fs | D34: =Buil!B237 -> (a) Amcan Metal Sheet Roofing Work | E34: =G34/B34 -> 2661.73 | F34: =C34 -> Fs | G34: =Buil!G244 -> 6630080
B35: =Buil!D245 -> 0 | C35: =Buil!C245 -> Ton | D35: =Buil!B245 -> ( b ) Steel Structure Work for Roofing | F35: =C35 -> Ton | G35: =Buil!G264 -> 5936650
B36: =Buil!D265 -> 272.9 | C36: =Buil!C265 -> Fr | D36: =Buil!B265 -> ( c ) Ridge Covering Work | E36: =G36/B36 -> 4193.66 | F36: =C36 -> Fr | G36: =Buil!G270 -> 1144450
A37: =Buil!A271 -> 15 | B37: =Buil!D271 -> 55.46 | C37: =Buil!C271 -> %Fc | D37: =Buil!B271 -> ( a ) Earth Filling Work | E37: =G37/B37 -> 9000 | F37: =C37 -> %Fc | G37: =Buil!G274 -> 499140
B38: =Buil!D276 -> 4.79 | C38: =Buil!C276 -> %Fc | D38: =Buil!B276 -> ( b ) Earth Carrying Work | E38: =G38/B38 -> 18000 | F38: =C38 -> %Fc | G38: =Buil!G279 -> 86220
A39: =Buil!A281 -> 16 | D39: Floor Work
B40: =Buil!D282 -> 29.44 | C40: %Fc | D40: =Buil!B282 -> ( a ) Sand Filling Work | E40: =G40/B40 -> 88000 | F40: =C40 -> %Fc | G40: =Buil!G287 -> 2590720
B41: =Buil!D289 -> 5.32 | C41: =Buil!C289 -> %Fc | D41: =Buil!B289 -> ( b )(1:3:6) Concrete Work | E41: =G41/B41 -> 696515.04 | F41: =C41 -> %Fc | G41: =Buil!G299 -> 3705460
B42: =Buil!D301 -> 1805.59 | C42: =Buil!C301 -> Fs | D42: =Buil!B301 -> ( c ) 1½"Thk; Floor Topping Work | E42: =G42/B42 -> 1252.18 | F42: =C42 -> Fs | G42: =Buil!G310 -> 2260930
A44: =Buil!A312 -> 17 | B44: =Buil!D312 -> 3210 | C44: =Buil!C312 -> Fs | D44: =Buil!B312 -> Scaffolding Work | E44: =G44/B44 -> 210.73 | F44: =C44 -> Fs | G44: =Buil!G319 -> 676450
...

Sheet Buil
A1: ='BQ '!A1:G1 -> One Storeyed RCC Building (46' 2" X 42' 6")
A2: ='BQ '!A2:G2 -> Main Building (အုတ္စီ၊ ေခ်ာ၊ က်ည္းေဘာင္ေထာင္၊ အမိုးမိုး)
A3: Builder's Estimate
A4: Item | B4: Particular | C4: Unit | D4: Quantity | E4: Rate | F4: Per | G4: Amount
I5: =680000/8 -> 85000 | J5: =I5*6 -> 510000
J6: =360000 -> 360000
A7: =Detail!A6 -> 1 | B7: Site Clearing Work | C7: %Fs | D7: =Detail!H7 -> 44.88 | I7: =680000+360000+15000 -> 1055000 | J7: 15000
B8: Labour | J8: =SUM(J5:J7) -> 885000
B9: Worker | C9: No | D9: =D7*0.25 -> 11.22 | E9: ='BQ '!E51 -> 18000 | F9: =C9 -> No | G9: =D9*E9 -> 201960
G10: =SUM(G9) -> 201960 | I10: Cement (Up to Plinth)
A12: =Detail!A9 -> 2 | B12: Staking Works For Preparation of Foundation | C12: Fs | D12: =Detail!H9 -> 3248
B13: Material | I13: =7.5*15 -> 112.5
B14: J/Wood | C14: Ton | D14: =D12/(100*100)*30/50/3 -> 0.06 | E14: ='BQ '!E17 -> 1200000 | F14: =C14 -> Ton | G14: =E14*D14 -> 72000 | I14: =1.33*2 -> 2.66
B15: Wire Nail | C15: Viss | D15: =D12/(100*100)*7.5/3.6 -> 0.68 | E15: ='BQ '!E18 -> 10000 | F15: =C15 -> Viss | G15: =E15*D15 -> 6800 | I15: =I13/I14 -> 42.293233
B16: Labour | I16: Width | J16: 1.33
B17: Surveyor | C17: No | D17: =D12/(100*100)*1 -> 0.32 | E17: ='BQ '!E49 -> 25000 | F17: =C17 -> No | G17: =E17*D17 -> 8000 | I17: Length | J17: 2
B18: Carpenter | C18: No | D18: =D12/(100*100)*5 -> 1.62 | E18: ='BQ '!E48 -> 25000 | F18: =C18 -> No | G18: =E18*D18 -> 40500 | J18: =J16*J17 -> 2.66
B19: Worker | C19: No | D19: =D12/(100*100)*10 -> 3.25 | E19: =E9 -> 18000 | F19: =C19 -> No | G19: =E19*D19 -> 58500
G20: =SUM(G14:G19) -> 185800
A23: =Detail!A12 -> 3 | B23: Earth Work | C23: %Fc | D23: =Detail!H36 -> 60.25
B24: Labour
B25: Worker | C25: No | D25: =D23*3 -> 180.75 | E25: =E9 -> 18000 | F25: =C25 -> No | G25: =D25*E25 -> 3253500
G26: =SUM(G25) -> 3253500
A28: =Detail!A37 -> 4 | B28: =Detail!B37 -> 6" Thk; Hardcore with Sand Filling Work | C28: =Detail!I42 -> %Fc | D28: =Detail!H42 -> 4.66
B29: Material
B30: Hardcore | C30: Sud | D30: =D28 -> 4.66 | E30: ='BQ '!E12 -> 200000 | F30: =C30 -> Sud | G30: =D30*E30 -> 932000
B31: R/Sand | C31: Sud | D31: =D28*0.25 -> 1.17 | E31: ='BQ '!E8 -> 56000 | F31: =C31 -> Sud | G31: =D31*E31 -> 65520
B32: Labour
B33: Mason | C33: No | D33: =D28*0.5 -> 2.33 | E33: ='BQ '!E46 -> 25000 | F33: =C33 -> No | G33: =D33*E33 -> 58250
B34: Worker | C34: No | D34: =D28*0.5 -> 2.33 | E34: ='BQ '!E51 -> 18000 | F34: =C34 -> No | G34: =D34*E34 -> 41940
G35: =SUM(G30:G34) -> 1097710
A37: =Detail!A44 -> 5 | B37: 3" thk; (1:3:6) Lean Conc; Work | C37: %Fc | D37: =Detail!H67 -> 4.79
B38: Material
B39: Cement | C39: Bag | D39: =D37*1440/112 -> 61.59 | E39: ='BQ '!E7 -> 22000 | F39: =C39 -> Bag | G39: =E39*D39 -> 1354980
B40: R/Sand | C40: Sud | D40: =D37*0.48 -> 2.3 | E40: ='BQ '!E8 -> 56000 | F40: =C40 -> Sud | G40: =E40*D40 -> 128800
B41: Chipping | C41: Sud | D41: =D37*0.96 -> 4.6 | E41: ='BQ '!E11 -> 220000 | F41: =C41 -> Sud | G41: =E41*D41 -> 1012000
B42: Fuel | C42: Gal | D42: =D37*2 -> 9.58 | E42: ='BQ '!E13 -> 15000 | F42: =C42 -> Gal | G42: =E42*D42 -> 143700
B43: Labour
B44: Mason | C44: No | D44: =D37*1 -> 4.79 | E44: ='BQ '!E46 -> 25000 | F44: =C44 -> No | G44: =E44*D44 -> 119750
B45: Operator | C45: No | D45: =D37*0.5 -> 2.4 | E45: ='BQ '!E50 -> 25000 | F45: =C45 -> No | G45: =E45*D45 -> 60000
...

Sheet Detail
A1: ='BQ '!A1:G1 -> One Storeyed RCC Building (46' 2" X 42' 6")
A2: ='BQ '!A2:G2 -> Main Building (အုတ္စီ၊ ေခ်ာ၊ က်ည္းေဘာင္ေထာင္၊ အမိုးမိုး)
A3: DETAILS OF MEASUREMENT
A4: Item | B4: Particular | C4: No. | D4: Measurement | G4: Deduction | H4: Contents | I4: Total of
D5: L | E5: B | F5: H | I5: Each
A6: 1 | B6: Site Clearing Work | C6: 1 | D6: =46+10+10 -> 66 | E6: =48+10+10 -> 68 | H6: =C6*D6*E6 -> 4488 | I6: Fs
H7: =H6/100 -> 44.88 | I7: %Fs
A9: 2 | B9: Staking Works For Preparation of Foundation | C9: =C6 -> 1 | D9: =46+10 -> 56 | E9: =48+10 -> 58 | H9: =C9*D9*E9 -> 3248 | I9: Fs
H10: =H9/100 -> 32.48 | I10: %Fs
A12: 3 | B12: Earth Work
B13: F1 (3' 0"x 3' 0"x0' 10") | C13: 5 | D13: 5 | E13: 5 | F13: =4.75 -> 4.75 | H13: =C13*D13*E13*F13 -> 593.75 | I13: Fc | K13: =1.2*3.281 -> 3.94 | L13: =18*3+4+20+18+4 -> 100
B14: F2 (4' 0"x 4' 0"x0' 10") | C14: 13 | D14: 6 | E14: 6 | F14: 4.75 | H14: =C14*D14*E14*F14 -> 2223 | I14: Fc
B15: F3 (5' 0"x 5' 0"x0' 10") | C15: 6 | D15: 7 | E15: 7 | F15: 4.75 | H15: =C15*D15*E15*F15 -> 1396.5 | I15: Fc
C16: =C13+C14+C15 -> 24
B17: For Retaining Wall Earth Work | K17: =3.5+10+10+-1+2+1 -> 25.5
B18: Line A, 42' L | C18: 1 | D18: =42.17-D13*1-D14*3 -> 19.17 | E18: 2.67 | F18: 3 | H18: =C18*D18*E18*F18 -> 153.55 | I18: Fc
B19: Line B, 42' L | C19: 1 | D19: =42-E15*2-1.5*E14-E13*0.5 -> 16.5 | E19: =E18 -> 2.67 | F19: =F18 -> 3 | H19: =C19*D19*E19*F19 -> 132.17 | I19: Fc
B20: Line C, 35' 8" L | C20: 1 | D20: =35.67-E15*2.5-E14*0.5 -> 15.17 | E20: =E19 -> 2.67 | F20: =F19 -> 3 | H20: =C20*D20*E20*F20 -> 121.51 | I20: Fc
B21: Line D, 35' 8" L | C21: 1 | D21: =35.67-E15-E14*2 -> 16.67 | E21: =E20 -> 2.67 | F21: =F20 -> 3 | H21: =C21*D21*E21*F21 -> 133.53 | I21: Fc
B22: Line E, 29' 4" L | C22: 1 | D22: =29.33-E14*3 -> 11.33 | E22: =E21 -> 2.67 | F22: =F21 -> 3 | H22: =C22*D22*E22*F22 -> 90.75 | I22: Fc
B23: Line 1, 46' 4" L | C23: 1 | D23: =46.33-E14*2.5-E15-E13 -> 19.33 | E23: =E22 -> 2.67 | F23: =F22 -> 3 | H23: =C23*D23*E23*F23 -> 154.83 | I23: Fc
B24: Line 2, 46' 4" L | C24: 1 | D24: =46.33-E15-E14*3 -> 21.33 | E24: =E23 -> 2.67 | F24: =F23 -> 3 | H24: =C24*D24*E24*F24 -> 170.85 | I24: Fc
B25: Line 3, 46' 4" L | C25: 1 | D25: =46.33-D15*3-D14 -> 19.33 | E25: =E24 -> 2.67 | F25: =F24 -> 3 | H25: =C25*D25*E25*F25 -> 154.83 | I25: Fc
B26: Line 4, 46' 4" L | C26: 1 | D26: =37.83-D15-D14 -> 24.83 | E26: =E25 -> 2.67 | F26: =F25 -> 3 | H26: =C26*D26*E26*F26 -> 198.89 | I26: Fc
B27: Line 5, 10' 8" L | C27: 1 | D27: =10.67-D13 -> 5.67 | E27: =E26 -> 2.67 | F27: =F26 -> 3 | H27: =C27*D27*E27*F27 -> 45.42 | I27: Fc
B28: Y-Dir Bet; Line C&D, 18' L | C28: 1 | D28: =18.5 -> 18.5 | E28: =E20 -> 2.67 | F28: =F20 -> 3 | H28: =C28*D28*E28*F28 -> 148.19 | I28: Fc
B29: X-Dir Bet; 2&3, 27' L | C29: 1 | D29: =27-E28*2.5 -> 20.33 | E29: =E28 -> 2.67 | F29: =F28 -> 3 | H29: =C29*D29*E29*F29 -> 162.84 | I29: Fc
B30: X-Dir Bet; 3&4, 10' 8"+8' 6" L | C30: 1 | D30: =10.67-E28+8.5-E28 -> 13.83 | E30: =E29 -> 2.67 | F30: =F29 -> 3 | H30: =C30*D30*E30*F30 -> 110.78 | I30: Fc
B31: Portico, Y-Dir | C31: 2
B32: Portico, X-Dir | C32: 1 | D32: =9.17-D13 -> 4.17 | E32: =E30 -> 2.67 | F32: =F30 -> 3 | H32: =C32*D32*E32*F32 -> 33.4 | I32: Fc
G34: =SUM(G13:G33) -> 0 | H34: =SUM(H13:H33) -> 6024.79
H35: =H34-G34 -> 6024.79 | I35: Fc
H36: =H35/100 -> 60.25 | I36: %Fc | K36: =H36*30000 -> 1807500
A37: 4 | B37: 6" Thk; Hardcore with Sand Filling Work
B38: F1 (3' 0"x 3' 0"x0' 10") | C38: =C13 -> 5 | D38: 4 | E38: 4 | F38: 0.75 | H38: =C38*D38*E38*F38 -> 60 | I38: Fc
B39: F2 (4' 0"x 4' 0"x0' 10") | C39: =C14 -> 13 | D39: 5 | E39: 5 | F39: 0.75 | H39: =C39*D39*E39*F39 -> 243.75 | I39: Fc
B40: F3 (5' 0"x 5' 0"x0' 10") | C40: =C15 -> 6 | D40: 6 | E40: 6 | F40: 0.75 | H40: =C40*D40*E40*F40 -> 162 | I40: Fc
C41: =SUM(C38:C40) -> 24 | H41: =SUM(H38:H40) -> 465.75 | I41: Fc
H42: =H41/100 -> 4.66 | I42: %Fc
A44: 5 | B44: (1:3:6) Lean Conc; Work
...

Sheet T W Rate
B1: Skilled | C1: 25000
B2: Worker | C2: 18000
B4: Excavation | D4: 2 | E4: =$C$2 -> 18000 | F4: =D4*E4 -> 36000 | H4: =SUM(F4) -> 36000
B5: Hardcore | D5: 1 | E5: =$C$2 -> 18000 | F5: =D5*E5 -> 18000 | H5: =SUM(F5) -> 18000
B6: Lean | D6: 1 | E6: =$C$1 -> 25000 | F6: =D6*E6 -> 25000 | H6: =SUM(F6:F7) -> 133000
D7: 6 | E7: =$C$2 -> 18000 | F7: =D7*E7 -> 108000
B8: 9" Brick Wall | D8: 4 | E8: =$C$1 -> 25000 | F8: =D8*E8 -> 100000 | H8: =SUM(F8:F9)*0.8 -> 166400
D9: 6 | E9: =$C$2 -> 18000 | F9: =D9*E9 -> 108000
B10: RC Concrete | D10: 1 | E10: =$C$1 -> 25000 | F10: =D10*E10 -> 25000 | H10: =SUM(F10:F11) -> 169000
D11: 8 | E11: =$C$2 -> 18000 | F11: =D11*E11 -> 144000
B12: Re Bar | D12: =20*0.75*0.5 -> 7.5 | E12: =$C$1 -> 25000 | F12: =D12*E12 -> 187500 | H12: =SUM(F12:F13)*0.8 -> 258000
D13: =D12 -> 7.5 | E13: =$C$2 -> 18000 | F13: =D13*E13 -> 135000
B14: F/W | D14: =4 -> 4 | E14: =$C$1 -> 25000 | F14: =D14*E14 -> 100000 | H14: =SUM(F14:F15) -> 136000
D15: 2 | E15: =$C$2 -> 18000 | F15: =D15*E15 -> 36000
B16: 4½ Wall | D16: 2 | E16: =$C$1 -> 25000 | F16: =D16*E16 -> 50000 | H16: =SUM(F16:F17) -> 104000
D17: 3 | E17: =$C$2 -> 18000 | F17: =D17*E17 -> 54000
B18: Plaster | D18: 1 | E18: =$C$1 -> 25000 | F18: =D18*E18 -> 25000 | H18: =SUM(F18:F19) -> 61000
D19: 2 | E19: =$C$2 -> 18000 | F19: =D19*E19 -> 36000
B20: Topping | D20: 0.75 | E20: =$C$1 -> 25000 | F20: =D20*E20 -> 18750 | H20: =SUM(F20:F21) -> 45750
D21: 1.5 | E21: =$C$2 -> 18000 | F21: =D21*E21 -> 27000
B22: SS Roof | H22: 1775

Sheet Roof
A1: Roofing Material List
E2: ကိုေအာင္ကိုမ်ိဳး
A3: Item | B3: Particular | C3: Unit | D3: NPT | E3: Refrence NPT | F3: After Design | G3: Total Qty | H3: Rate | I3: Amount
B4: Floor Area | D4: 1723 | E4: =25*35+6*12 -> 947
A5: 1 | B5: Roofing Sheet (Amcan) (ထပ္ၿပီး 2' 6"က်န္) | C5: ='BQ '!C27 -> Rft. | D5: ='BQ '!D27 -> 1273 | E5: ='POL Roof'!C9 -> 974 | F5: =[1]BE!$D$473 -> 18.9 | G5: =D5+F5 -> 1291.9 | H5: 4000 | I5: =G5*H5 -> 5167600 | K5: =(D5+E5)*H5 -> 8988000 | L5: =I5-K5 -> -3820400
A6: 2 | B6: Roofing Secrew | C6: ='BQ '!C28 -> Gross | D6: ='BQ '!D28 -> 17.3 | E6: =ROUND(D6*$E$4/$D$4,0) -> 10 | F6: =E6 -> 10 | G6: =D6+F6 -> 27.3 | I6: =G6*H6 -> 0 | K6: =(D6+E6)*H6 -> 0 | L6: =I6-K6 -> 0
A7: 3 | B7: 5" x 2.5" x 1.4 mm thk; Hollow | C7: ='BQ '!C30 -> No | D7: ='BQ '!D30 -> 18.69 | E7: =ROUND(D7*$E$4/$D$4,0) -> 10 | G7: =D7+F7 -> 18.69 | H7: =ROUND($H$8*J7/12,-3) -> 64000 | I7: =G7*H7 -> 1196160 | J7: =5+5+2.5+2.5 -> 15 | K7: =(D7+E7)*H7 -> 1836160 | L7: =I7-K7 -> -640000
A8: 4 | B8: 4"x2" Hollow (1.4mm thk;) | C8: ='BQ '!C31 -> No | D8: ='BQ '!D31 -> 40.66 | E8: =ROUND(D8*$E$4/$D$4,0) -> 22 | F8: =[1]BE!$D$470 -> 0.18 | G8: =D8+F8 -> 40.84 | H8: 50800 | I8: =G8*H8 -> 2074672 | J8: =(4+4+2+2) -> 12 | K8: =(D8+E8)*H8 -> 3183128 | L8: =I8-K8 -> -1108456
A9: 5 | B9: 3" x 2" Hollow (1.2mm thk;) | C9: ='BQ '!C32 -> No | D9: ='BQ '!D32 -> 94.42 | E9: =ROUND(D9*$E$4/$D$4,0) -> 52 | F9: =[1]BE!$D$471 -> 12.6 | G9: =D9+F9 -> 107.02 | H9: =ROUND($H$8*J9/12,-3) -> 42000 | I9: =G9*H9 -> 4494840 | J9: =(3+3+2+2) -> 10 | K9: =(D9+E9)*H9 -> 6149640 | L9: =I9-K9 -> -1654800
A10: 6 | B10: 1½" x 1½" x¼" thk; Angle | C10: ='BQ '!C33 -> No | D10: ='BQ '!D33 -> 1.92 | E10: =ROUND(D10*$E$4/$D$4,0) -> 1 | F10: =[1]BE!$D$472 -> 0 | G10: =D10+F10 -> 1.92 | H10: 40000 | I10: =G10*H10 -> 76800 | K10: =(D10+E10)*H10 -> 116800 | L10: =I10-K10 -> -40000
A11: 7 | B11: Welding Rod | C11: ='BQ '!C35 -> Pkt | D11: ='BQ '!D35 -> 3 | E11: =ROUND(D11*$E$4/$D$4,0) -> 2 | F11: =E11 -> 2 | G11: =D11+F11 -> 5 | H11: 30000 | I11: =G11*H11 -> 150000 | K11: =(D11+E11)*H11 -> 150000 | L11: =I11-K11 -> 0
A12: 8 | B12: Ridge Cover | C12: ='BQ '!C36 -> Rft | D12: ='BQ '!D36 -> 305.65 | E12: =29+22.5*2+28.5+6.75+10*2+6+3.5 -> 138.75 | F12: =[1]BE!$D$474 -> 18.9 | G12: =D12+F12 -> 324.55 | H12: 3000 | I12: =G12*H12 -> 973650 | K12: =(D12+E12)*H12 -> 1333200 | L12: =I12-K12 -> -359550
B13: 10" Eave Board | C13: ='BQ '!#REF! -> #REF! | D13: ='BQ '!#REF! -> #REF! | G13: =D13+E13 -> #REF!
B14: 3/4" x 3/4" Hollow | C14: ='BQ '!#REF! -> #REF! | D14: ='BQ '!#REF! -> #REF! | G14: =D14+E14 -> #REF!
B15: Gutter | C15: ='BQ '!#REF! -> #REF! | D15: ='BQ '!#REF! -> #REF! | G15: =D15+E15 -> #REF!
B16: Gutter Bracket | C16: ='BQ '!#REF! -> #REF! | D16: ='BQ '!#REF! -> #REF! | G16: =D16+E16 -> #REF!
I18: =SUM(I5:I17) -> 14133722
I20: 21756928
C24: 1 | D24: 2 | E24: 2 | H24: =D24*E24 -> 4
C25: 2 | D25: 5 | E25: 2 | H25: =D25*E25 -> 10
C26: 3 | D26: 8 | E26: 2 | H26: =D26*E26 -> 16
C27: 4 | D27: 9 | E27: 2 | H27: =D27*E27 -> 18
C28: 5 | D28: 9 | E28: 2 | H28: =D28*E28 -> 18
C29: 6 | D29: 9 | E29: 2 | H29: =D29*E29 -> 18
C30: 7 | D30: 12 | E30: 2 | H30: =D30*E30 -> 24
C31: 8 | D31: 14.5 | E31: 2 | H31: =D31*E31 -> 29
C32: 9 | D32: 17.5 | E32: 2 | H32: =D32*E32 -> 35
C33: 10 | D33: 20.5 | E33: 2 | H33: =D33*E33 -> 41
C34: 11 | D34: 23 | E34: 2 | H34: =D34*E34 -> 46
C35: 12 | D35: 23 | E35: 2 | H35: =D35*E35 -> 46
... C66: 21 | D66: 3 | E66: 2 | H66: =D66*E66 -> 6
H67: =SUM(H24:H66) -> 1094
B68: Lapping | D68: =16 -> 16 | E68: 1 | H68: =D68*E68 -> 16
H69: =SUM(H67:H68) -> 1110
H71: =H69*1.1 -> 1221

Sheet POL Roof
B2: Main (R & L Side) | C2: 2 | D2: =(19+27.67)/2 -> 23.335 | F2: 19 | H2: =C2*D2*F2 -> 886.73
C3: 2 | D3: 6 | F3: 7.5 | H3: =C3*D3*F3 -> 90
C4: 2 | D4: 3.5 | F4: 10 | H4: =C4*D4*F4 -> 70 | J4: =SQRT(3.83^2+7.83^2) -> 8.7165245
C5: 2 | D5: 29 | F5: 18 | H5: =C5*D5*F5 -> 1044 | J5: =SQRT(5.67^2+3.5^2) -> 6.66325
C6: 2 | D6: 6.75 | F6: 7.5 | H6: =C6*D6*F6 -> 101.25 | J6: =SQRT(17.08^2+8.5^2) -> 19.078166
H7: =SUM(H2:H6) -> 2191.98
K8: =H7-250 -> 1941.98
B9: Amcan Sheet | C9: =ROUND(H7/2.25,0) -> 974 | D9: Rft | K9: =K8/2.5*1.13 -> 877.77496
B12: 3" x 2" Hollow Purlin | C12: =C2*ROUND(F2/3+1,0) -> 14 | D12: =D2 -> 23.335 | H12: =C12*D12 -> 326.69 | I12: Ft
C13: =C3*ROUND(F3/3+1,0) -> 8 | D13: =D3 -> 6 | H13: =C13*D13 -> 48 | I13: Ft
C14: =C4*ROUND(F4/3+1,0) -> 8 | D14: =D4 -> 3.5 | H14: =C14*D14 -> 28 | I14: Ft
C15: =ROUND(F5/3+1,0) -> 7 | D15: =D5 -> 29 | H15: =C15*D15 -> 203 | I15: Ft
C16: =C15 -> 7 | D16: =D15/2 -> 14.5 | H16: =C16*D16 -> 101.5 | I16: Ft
C17: =ROUND(F6/3+1,0) -> 4 | D17: =(D6+0)/2 -> 3.375 | H17: =C17*D17 -> 13.5 | I17: Ft
C19: 4 | D19: 22.5
C20: 4
H24: =SUM(H12:H23) -> 720.69 | I24: Ft
H25: =H24/19.5 -> 36.958462 | I25: No

Sheet Sheet1
B2: =Detail!B231 -> GB1 ( 10" x 10'') | E2: =Detail!D238 -> 138.5 | F2: Ft
B3: =Detail!B239 -> GB2 ( 10" x 12'') | E3: =Detail!D244 -> 308.19 | F3: Ft
E4: =SUM(E2:E3) -> 446.69 | F4: 2 | G4: Side | H4: =E4*F4 -> 893.38 | I4: Ft
B6: Ready made F/W for PB | C6: B | E6: L | F6: Qty
B7: plywood + Frame တြဲၿပီး | C7: 14" | D7: x | E7: 6.5 | F7: 3 | H7: =E7*F7 -> 19.5
C8: 17 | D8: x | E8: 8 | F8: 1 | H8: =E8*F8 -> 8
C9: 14 | D9: x | E9: 8 | F9: 2 | H9: =E9*F9 -> 16
C10: 16 | D10: x | E10: 6.5 | F10: 1 | H10: =E10*F10 -> 6.5
C11: 14 | D11: x | E11: 5.5 | F11: 12 | H11: =E11*F11 -> 66
C12: 16 | D12: x | E12: 6 | F12: 1 | H12: =E12*F12 -> 6
C13: 17 | D13: x | E13: 6 | F13: 3 | H13: =E13*F13 -> 18
C14: 16 | D14: x | E14: 7 | F14: 3 | H14: =E14*F14 -> 21
H15: =SUM(H7:H14) -> 161
B16: Only Frame
C17: 16" | D17: x | E17: 8 | F17: 8 | H17: =E17*F17 -> 64
B19: MS Sheet + Frame
C20: 12" | E20: 6 | F20: 21 | H20: =E20*F20 -> 126
C21: 16" | E21: 6 | F21: 6 | H21: =E21*F21 -> 36
C22: 10" | E22: 6 | F22: 16 | H22: =E22*F22 -> 96
C23: 12" | E23: 8 | F23: 6 | H23: =E23*F23 -> 48
C24: 14" | E24: 8 | F24: 18 | H24: =E24*F24 -> 144
C25: 12" | E25: 4 | F25: 8 | H25: =E25*F25 -> 32
C26: 10" | E26: 4 | F26: 9 | H26: =E26*F26 -> 36
C27: 12" | E27: 3 | F27: 4 | H27: =E27*F27 -> 12
C28: 14" | E28: 4 | F28: 20 | H28: =E28*F28 -> 80
H29: =SUM(H20:H28) -> 610 | K29: =H29+H17+H15 -> 835
