Workbook

Sheet Material Rate
A1: Material | C1: Rate
A2: Cement | B2: Bag | C2: 24000
A3: R/Sand | B3: Sud | C3: 30000
A4: Brick | B4: No | C4: 350
A5: R/Shingle | B5: Sud | C5: 110000
A6: Hard Core | B6: Sud | C6: 200000
A7: Fuel | B7: Gal | C7: 20000
A8: 5 Ply Wood (8' x 4') | B8: Sht | C8: 70000 | E8: UPG
A9: Jungle Wood | B9: Ton | C9: 1500000 | E9: Unitex
A10: Wire Nail | B10: Lb | C10: =10000/3.6 -> 2778 | D10: Normal | E10: OE
A11: M.S Rod | D11: Good | E11: Premium
A12: 6.5 mm Ø M.S Rod | B12: Ton | C12: 3800000
A13: 10 mm Ø Re bar | B13: Ton | C13: 2500000
A14: 12 mm Ø Re bar | B14: Ton | C14: 2400000
A15: 16mmØ Re bar | B15: Ton | C15: 2800000
B16: Ton
A17: Binding Wire | B17: Lb | C17: =12000/3.6 -> 3333
A18: 4"x2"x1.4mm thk; Hollow | B18: No | C18: 60000
A19: 3"x1.5"x1.2mm thk; Hollow | B19: No | C19: 42000
A20: 2"x2" Angle | B20: No | C20: 40000
A21: Amcan Roofing Sheet | B21: Ft | C21: 4000
A22: Ridge Cover | B22: Ft | C22: 3000
A23: Roofing Secrew | B23: No | C23: 100
A24: 5"x3" Ready PKD Chowket | B24: Ft | C24: 15000
A25: 5"x2" Ready PKD Chowket | B25: Ft | C25: 12000
A26: Coal Tar | B26: Gal | C26: 10000
A27: Bracket for Chowket | B27: No | C27: 200
A28: X-Met | B28: Ft | C28: 160
A29: Bamboo | B29: No | C29: 2000
... A34: 4" Ø PVC Inlet Pipe (T) | B34: No | C34: 15000
A35: 5"x2" Ready PKD Chowket for Toilet | B35: Ft
A36: Glass block, IWC Pan & Accessories | B36: Set
A37: Teak Door with Accessories | B37: Fs
A38: 4 Angle Sheet | B38: Ft | C38: 4000
A39: Gypsum Borad (Regular) | B39: Sht | C39: 50000
A40: Gypsum Borad (Moisture) | B40: Sht | C40: 55000
A41: Shera Board | B41: Sht | C41: 72500
A42: L-Bar ​အထူ (10') | B42: No | C42: 3300
A43: C-channel (13') | B43: No | C43: 4500
A44: ငါးရိုး Secrew | B44: No
...

Sheet ALL SUM
A1: ='Detail-Skeleton'!A1 -> Ko Aung Ko Myo (Aung Myittar (B) 11 Street)
A2: ='Detail-Skeleton'!A2 -> Two Storeyed RCC Building (25' x 35' x (13+12)')
A3: Total Summary
A4: Item | B4: Description | C4: Amount | D4: Remark
A5: 1 | B5: Structure Work | C5: ='SUM(Structure)'!C14 -> 1.7936335e+08
A6: 2 | B6: Finishing Work | C6: ='SUM(Finishing)'!C13 -> 88916041
A8: Total Amount | C8: =SUM(C5:C7) -> 2.682794e+08
B9: Say | C9: =ROUND(C8,-4) -> 268280000

Sheet SUM(Structure)
A1: ='Detail-Skeleton'!A1 -> Ko Aung Ko Myo (Aung Myittar (B) 11 Street)
A2: ='Detail-Skeleton'!A2 -> Two Storeyed RCC Building (25' x 35' x (13+12)')
A3: Structure Work
A4: Item | B4: Description | C4: Amount | D4: Remark
A5: 1 | B5: - Material Cost | C5: =BQ!G555 -> 1.0485134e+08
A6: 2 | B6: - Labour Cost | C6: =BQ!G563 -> 45762500
A8: Total Amount | C8: =SUM(C5:C7) -> 1.5061384e+08
B9: Transportation Cost (3% of Material) | C9: =C5*0.03 -> 3145540.3
B10: Premiliminary Cost | C10: =C8*0.05 -> 7530692.2
B11: Overhead & Contingency Charges (2%) | C11: =C8*0.02 -> 3012276.9
A12: Supervision Charges (10%) | C12: =ROUND(C8*0.1,-3) -> 15061000
B13: Profit (15%) | C13: =C8*0.15 -> 22592077
A14: Total Amount | C14: =SUM(C8:C12) -> 1.7936335e+08
A15: Say

Sheet BQ
A1: ='Detail-Skeleton'!A1 -> Ko Aung Ko Myo (Aung Myittar (B) 11 Street)
A2: ='Detail-Skeleton'!A2 -> Two Storeyed RCC Building (25' x 35' x (13+12)')
A3: BUILDER'S ESTIMATE | H3: Abstract of Costs
A4: Item | B4: Particular | C4: Unit | D4: Quantity | E4: Rate | F4: Per | G4: Material | H4: Sub Total (M+L) | I4: AC (M+L) | J4: Sub Total (L) | K4: AC (L) | L4: Workdone(%) | O4: Mason
L5: M+L | M5: L
P6: =P7/12.92 -> 0.22119969
A7: ='Detail-Skeleton'!A7 -> 1 | B7: ='Detail-Skeleton'!B7 -> Site Cleaning Work | C7: ='Detail-Skeleton'!K8 -> %Fs | D7: ='Detail-Skeleton'!J8 -> 24 | H7: =SUM(G7:G9) -> 120000 | I7: =H7/D7 -> 5000 | J7: =SUM(G7:G9) -> 120000 | K7: =J7/D7 -> 5000 | L7: =ROUND(H7/$H$519,5) -> 0.0008 | M7: =ROUND(J7/$J$519,5) -> 0.0026 | O7: =M11+M19+M23+M31+M41+M50+M80+M172 -> 0.128 | P7: =SUM(P8:P16) -> 2.8579 | Q7: =SUM(Q8:Q16) -> 1.003 | R7: 550000
B8: Labour | N8: =B11 -> Staking Works For Preparation of Foundation | O8: =M11 -> 0.0011
B9: Worker | C9: No | D9: =D7*0.25 -> 6 | E9: =E560 -> 20000 | F9: =C9 -> No | G9: =E9*D9 -> 120000 | N9: =B19 -> Earth Work in Medium Soil | O9: =M19 -> 0.0259 | P9: =O9*85 -> 2.202 | Q9: =P9/$P$7 -> 0.77 | R9: =Q9*$R$7 -> 423500
N10: =B23 -> Hard Core Laying with sand Work | O10: =M23 -> 0.0007 | P10: =O10 -> 0.0007 | Q10: =P10/$P$7 -> 0.0002 | R10: =Q10*$R$7 -> 110
A11: 2 | B11: ='Detail-Skeleton'!B11 -> Staking Works For Preparation of Foundation | C11: ='Detail-Skeleton'!K12 -> Fs | D11: ='Detail-Skeleton'!J12 -> 1575 | H11: =SUM(G11:G17) -> 97266.74 | I11: =ROUND(H11/D11,2) -> 61.76 | J11: =SUM(G16:G17) -> 51350 | K11: =ROUND(J11/D11,2) -> 32.6 | L11: =ROUND(H11/$H$519,5) -> 0.0007 | M11: =ROUND(J11/$J$519,5) -> 0.0011 | N11: (1:3:6) Footing LeanWork | O11: =M31-O12 -> 0.0059 | P11: =O11 -> 0.0059 | Q11: =P11 -> 0.0059 | R11: =Q11*$R$7 -> 3245
B12: Material | N12: (1:3:6)RW Lean | O12: =0.75/100 -> 0.0075
B13: Jungle Wood | C13: Ton | D13: =D11/(100*100)*30/50/3 -> 0.03 | E13: =E532 -> 1500000 | F13: =C13 -> Ton | G13: =D13*E13 -> 45000 | N13: =B41 -> Retaining Wall Brick Work with (1:3) Cement Mortor | O13: =M41 -> 0.0521
B14: Wire Nail | C14: Viss | D14: =D11/(100*100)*7.5/3.6 -> 0.33 | E14: =E533 -> 2778 | F14: =C14 -> Viss | G14: =D14*E14 -> 916.74 | N14: =B49 -> Concrete Casting Work for Footing | O14: =M50 -> 0.0151 | P14: =O14*43 -> 0.6493 | Q14: =P14/$P$7 -> 0.2272 | R14: =Q14*$R$7 -> 124960
B15: Labour | N15: Up To Plinth Column | O15: =M80 -> 0.0079
B16: Carpenter | C16: No | D16: =D11/(100*100)*5 -> 0.79 | E16: =E557 -> 25000 | F16: =C16 -> No | G16: =E16*D16 -> 19750 | N16: PB | O16: =M172 -> 0.0118
B17: Worker | C17: No | D17: =D11/(100*100)*10 -> 1.58 | E17: =E560 -> 20000 | F17: =C17 -> No | G17: =E17*D17 -> 31600
A19: ='Detail-Skeleton'!A15 -> 3 | B19: ='Detail-Skeleton'!B15 -> Earth Work in Medium Soil | C19: ='Detail-Skeleton'!K32 -> %Fc | D19: ='Detail-Skeleton'!J32 -> 29.61 | H19: =SUM(G19:G21) -> 1184400 | J19: =SUM(G21) -> 1184400 | L19: =ROUND(H19/$H$519,5) -> 0.0079 | M19: =ROUND(J19/$J$519,5) -> 0.0259
B20: Labour
B21: Worker | C21: No | D21: =D19*2 -> 59.22 | E21: =E560 -> 20000 | F21: =C21 -> No | G21: =E21*D21 -> 1184400
A23: ='Detail-Skeleton'!A34 -> 4 | B23: ='Detail-Skeleton'!B34 -> Hard Core Laying with sand Work | C23: ='Detail-Skeleton'!K41 -> %Fc | D23: ='Detail-Skeleton'!J41 -> 1.47 | H23: =SUM(G25:G29) -> 338400 | J23: =SUM(G28:G29) -> 33300 | L23: =ROUND(H23/$H$519,5) -> 0.0023 | M23: =ROUND(J23/$J$519,5) -> 0.0007
B24: Material
B25: Hard Core | C25: Sud | D25: =D23 -> 1.47 | E25: =E529 -> 200000 | F25: =C25 -> Sud | G25: =D25*E25 -> 294000
B26: R/Sand | C26: Sud | D26: =D23*0.25 -> 0.37 | E26: =E526 -> 30000 | F26: =C26 -> Sud | G26: =D26*E26 -> 11100
B27: Labour
B28: Mason | C28: No | D28: =D23*0.5 -> 0.74 | E28: =E558 -> 25000 | G28: =E28*D28 -> 18500
B29: Worker | C29: No | D29: =D23*0.5 -> 0.74 | E29: =E560 -> 20000 | F29: =C29 -> No | G29: =E29*D29 -> 14800
A31: ='Detail-Skeleton'!A43 -> 5 | B31: ='Detail-Skeleton'!B43 -> (1:3:6) Lean Conc; Work | C31: ='Detail-Skeleton'!K67 -> %Fc | D31: ='Detail-Skeleton'!J67 -> 3.9 | H31: =SUM(G33:G40) -> 2437750 | I31: =H31/D31 -> 625064.1 | J31: =SUM(G38:G40) -> 614250 | L31: =ROUND(H31/$H$519,5) -> 0.0162 | M31: =ROUND(J31/$J$519,5) -> 0.0134
B32: Material
B33: Cement | C33: Bag | D33: =ROUNDDOWN(D31*1440/112,0) -> 50 | E33: =E525 -> 24000 | F33: =C33 -> Bag | G33: =E33*D33 -> 1200000
B34: R/Sand | C34: Sud | D34: =D31*0.48 -> 1.87 | E34: =E26 -> 30000 | F34: =C34 -> Sud | G34: =E34*D34 -> 56100
B35: R/Shingle | C35: Sud | D35: =D31*0.96 -> 3.74 | E35: =E528 -> 110000 | F35: =C35 -> Sud | G35: =E35*D35 -> 411400
B36: Fuel | C36: Gal | D36: =D31*2 -> 7.8 | E36: =E530 -> 20000 | F36: =C36 -> Gal | G36: =E36*D36 -> 156000
B37: Labour
B38: Mason | C38: No | D38: =D31*1 -> 3.9 | E38: =E558 -> 25000 | F38: =C38 -> No | G38: =E38*D38 -> 97500
B39: Operator | C39: No | D39: =D31*0.5 -> 1.95 | E39: =E561 -> 25000 | F39: =C39 -> No | G39: =E39*D39 -> 48750
B40: Worker | C40: No | D40: =D31*6 -> 23.4 | E40: =E560 -> 20000 | F40: =C40 -> No | G40: =E40*D40 -> 468000
A41: ='Detail-Skeleton'!A69 -> 6 | B41: ='Detail-Skeleton'!B69 -> Retaining Wall Brick Work with (1:3) Cement Mortor | C41: ='Detail-Skeleton'!K102 -> %Fc | D41: ='Detail-Skeleton'!J102 -> 10.84 | H41: =SUM(G43:G48) -> 9391300 | I41: =H41/D41 -> 866356.09 | J41: =SUM(G47:G48) -> 2384800 | L41: =ROUND(H41/$H$519,5) -> 0.0624 | M41: =ROUND(J41/$J$519,5) -> 0.0521
B42: Material
B43: Cement | C43: Bag | D43: =ROUNDDOWN(D41*780/112,0) -> 75 | E43: =E525 -> 24000 | F43: =C43 -> Bag | G43: =E43*D43 -> 1800000
...

Sheet Detail-Skeleton
A1: Ko Aung Ko Myo (Aung Myittar (B) 11 Street)
A2: Two Storeyed RCC Building (25' x 35' x (13+12)')
A3: DETAILS OF MEASUREMENT | M3: =8*8*7.5*6.25 -> 3000
A4: Item | B4: Particular | D4: No. | E4: Measurement | H4: Deduction | I4: Contents | J4: Total of Each | K4: Unit
E5: L | F5: B | G5: H
A7: 1 | B7: Site Cleaning Work | D7: 1 | E7: 40 | F7: 60 | I7: =D7*E7*F7 -> 2400 | K7: Fs
J8: =SUM(I7:I8)/100 -> 24 | K8: %Fs
A11: 2 | B11: Staking Works For Preparation of Foundation
D12: 1 | E12: =25+10 -> 35 | F12: =35+10 -> 45 | I12: =D12*E12*F12 -> 1575 | J12: =SUM(I12) -> 1575 | K12: Fs
A15: 3 | B15: Earth Work in Medium Soil
B16: F1 (3' 0" x 3' 0" x 10") | D16: 2 | E16: 3 | F16: =E16 -> 3 | G16: =5.75+1 -> 6.75 | I16: =D16*E16*F16*G16 -> 121.5 | K16: Fc
B17: F2 (4' 0" x 4' 0" x 10") | D17: 4 | E17: 4 | F17: =E17 -> 4 | G17: =G16 -> 6.75 | I17: =D17*E17*F17*G17 -> 432 | K17: Fc
B18: F3 (5' 0" x 5' 0" x 12") | D18: 7 | E18: 5 | F18: =E18 -> 5 | G18: =G16 -> 6.75 | I18: =D18*E18*F18*G18 -> 1181.3 | K18: Fc
B19: F4 (6' 0" x 6' 0" x 14") | D19: 1 | E19: 6 | F19: =E19 -> 6 | G19: =G16 -> 6.75 | I19: =D19*E19*F19*G19 -> 243 | J19: =SUM(I16:I19) -> 1977.8 | K19: Fc
D20: =SUM(D16:D19) -> 14
B21: Retaining Wall
B22: Line A | D22: 1 | E22: =13.5+11.5-2*E18 -> 15 | F22: =1.67+1 -> 2.67 | G22: =3 -> 3 | I22: =D22*E22*F22*G22 -> 120.15 | K22: Fc
B23: Line B | D23: 1 | E23: =13.5+11.5-1*E18-1*E19 -> 14 | F23: =F22 -> 2.67 | G23: =G22 -> 3 | I23: =D23*E23*F23*G23 -> 112.14 | K23: Fc
B24: Line C | D24: 1 | E24: =13.5+11.5-1*E17-1*E18 -> 16 | F24: =F23 -> 2.67 | G24: =G23 -> 3 | I24: =D24*E24*F24*G24 -> 128.16 | K24: Fc
B25: Line D' | D25: 1 | E25: =9.83-E16 -> 6.83 | F25: =F24 -> 2.67 | G25: =G24 -> 3 | I25: =D25*E25*F25*G25 -> 54.71 | K25: Fc
B26: Line 1,3 | D26: 2 | E26: =(16+9+10)-1.5*F18-1.5*F17 -> 21.5 | F26: =F22 -> 2.67 | G26: =G22 -> 3 | I26: =D26*E26*F26*G26 -> 344.43 | K26: Fc
B27: Line 2 | D27: 1 | E27: =(16+9+10)-F18*2-F19 -> 19 | F27: =F26 -> 2.67 | G27: =G26 -> 3 | I27: =D27*E27*F27*G27 -> 152.19 | K27: Fc
B28: Line 2' & 3' | D28: 2 | F28: =F26 -> 2.67 | G28: =G26 -> 3 | I28: =D28*E28*F28*G28 -> 0 | K28: Fc
B29: Line D' | D29: 1 | E29: =9.83-E16 -> 6.83 | F29: =F28 -> 2.67 | G29: =G28 -> 3 | I29: =D29*E29*F29*G29 -> 54.71 | K29: Fc
B30: For Main Brick Step (11' 0" L) | D30: 1 | E30: 11 | F30: 3 | G30: 0.5 | I30: =D30*E30*F30*G30 -> 16.5 | J30: =SUM(I22:I30) -> 982.99 | K30: Fc
J31: =SUM(I16:I31) -> 2960.79 | K31: Fc
J32: =J31/100 -> 29.61 | K32: %Fc
A34: 4 | B34: Hard Core Laying with sand Work
B35: Footing
B36: F1 (3' 0" x 3' 0" x 10") | D36: 2 | E36: 3 | F36: =E36 -> 3 | G36: =0.5 -> 0.5 | I36: =D36*E36*F36*G36 -> 9 | K36: Fc
B37: F2 (4' 0" x 4' 0" x 10") | D37: 4 | E37: 4 | F37: =E37 -> 4 | G37: 0.5 | I37: =D37*E37*F37*G37 -> 32 | K37: Fc
B38: F3 (5' 0" x 5' 0" x 12") | D38: 7 | E38: 5 | F38: =E38 -> 5 | G38: 0.5 | I38: =D38*E38*F38*G38 -> 87.5 | K38: Fc
B39: F4 (6' 0" x 6' 0" x 14") | D39: 1 | E39: 6 | F39: =E39 -> 6 | G39: 0.5 | I39: =D39*E39*F39*G39 -> 18 | K39: Fc
D40: =SUM(D36:D39) -> 14 | J40: =SUM(I36:I40) -> 146.5 | K40: Fc
J41: =J40/100 -> 1.47 | K41: %Fc
A43: 5 | B43: (1:3:6) Lean Conc; Work
B44: Footing
B45: F1 (3' 0" x 3' 0" x 10") | D45: 2 | E45: 3 | F45: =E45 -> 3 | G45: =0.25 -> 0.25 | I45: =D45*E45*F45*G45 -> 4.5 | K45: Fc
B46: F2 (4' 0" x 4' 0" x 10") | D46: 4 | E46: 4 | F46: =E46 -> 4 | G46: =0.25 -> 0.25 | I46: =D46*E46*F46*G46 -> 16 | K46: Fc
B47: F3 (5' 0" x 5' 0" x 12") | D47: 7 | E47: 5 | F47: =E47 -> 5 | G47: =0.25 -> 0.25 | I47: =D47*E47*F47*G47 -> 43.8 | K47: Fc
...

Sheet SUM(Finishing)
A1: ='Detail-Skeleton'!A1 -> Ko Aung Ko Myo (Aung Myittar (B) 11 Street)
A2: ='Detail-Skeleton'!A2 -> Two Storeyed RCC Building (25' x 35' x (13+12)')
A3: Item | B3: Description | C3: Amount | D3: Remark
A4: 1 | B4: - Material Cost | C4: ='BQ-Finishing'!G233 -> 61793438
A5: 2 | B5: - Labour Cost | C5: ='BQ-Finishing'!G248 -> 12618934
A7: Total Amount | C7: =SUM(C4:C6) -> 74412372
B8: Transportation Cost (3% of Material) | C8: =C4*0.03 -> 1853803.1
B9: Premiliminary Cost | C9: =C7*0.05 -> 3720618.6
B10: Overhead & Contingency Charges (2%) | C10: =C7*0.02 -> 1488247.4
A11: Supervision Charges (10%) | C11: =ROUND(C7*0.1,-3) -> 7441000
B12: Profit (15%) | C12: =C7*0.15 -> 11161856
A13: Total Amount | C13: =SUM(C7:C11) -> 88916041

Sheet BQ-Finishing
A1: ='Detail-Skeleton'!A1 -> Ko Aung Ko Myo (Aung Myittar (B) 11 Street)
A2: ='Detail-Skeleton'!A2 -> Two Storeyed RCC Building (25' x 35' x (13+12)')
A3: BUILDER'S ESTIMATE | H3: Abstract of Costs
A4: Item | B4: Particular | C4: Unit | D4: Quantity | E4: Rate | F4: Per | G4: Material | H4: Sub Total (M+L) | I4: AC (M+L) | J4: Sub Total (L) | K4: AC (L) | L4: Workdone(%)
L5: M+L | M5: L
A6: ='Detail-Finishing'!A7 -> 1 | B6: ='Detail-Finishing'!B7 -> Gypsum Borad Ceiling Work | C6: Fs | D6: =D7+D8+D9 -> 2223.45
B7: ='Detail-Finishing'!B9 -> ( a ) Gypsum Board (Regular) Ceiling | C7: ='Detail-Finishing'!J18 -> Fs | D7: ='Detail-Finishing'!I18 -> 1564.75 | H7: =SUM(G7:G7) -> 0 | I7: =H7/D7 -> 0 | J7: =SUM(G7:G7) -> 0 | K7: =J7/D7 -> 0 | L7: =ROUND(H7/$H$169,5) -> 0 | M7: =ROUND(J7/$J$169,5) -> 0
B8: ='Detail-Finishing'!B20 -> ( b ) Gypsum Board (Moisture) Ceiling | C8: ='Detail-Skeleton'!K12 -> Fs | D8: ='Detail-Finishing'!I24 -> 124 | H8: =SUM(G8:G22) -> 8983750 | I8: =ROUND(H8/D8,2) -> 72449.6 | J8: =SUM(G22:G22) -> 2223450 | K8: =ROUND(J8/D8,2) -> 17931.05 | L8: =ROUND(H8/$H$169,5) -> 0.3527 | M8: =ROUND(J8/$J$169,5) -> 0.3304
B9: ='Detail-Finishing'!B26 -> ( c ) External (Shera Board Ceiling) | C9: ='Detail-Finishing'!J40 -> Fs | D9: ='Detail-Finishing'!I40 -> 534.7
B10: Material
B11: Gypsum Borad (Regular) | C11: Sht | D11: =ROUND(D7/32*1.15,0) -> 56 | E11: =VLOOKUP(B11,'Material Rate'!A$1:C91,3,FALSE) -> 50000 | F11: =C11 -> Sht | G11: =E11*D11 -> 2800000
B12: Gypsum Borad (Moisture) | C12: Sht | D12: =ROUND(D8/32*1.15,0) -> 4 | E12: =VLOOKUP(B12,'Material Rate'!A$1:C92,3,FALSE) -> 55000 | F12: =C12 -> Sht | G12: =E12*D12 -> 220000
B13: Shera Board | C13: Sht | D13: =ROUND(D9/32*1.15,0) -> 19 | E13: =VLOOKUP(B13,'Material Rate'!A$1:C93,3,FALSE) -> 72500 | F13: =C13 -> Sht | G13: =E13*D13 -> 1377500
B14: L-Bar ​အထူ (10') | C14: No | D14: =ROUND('Detail-Finishing'!H59/10,0) -> 116 | E14: =VLOOKUP(B14,'Material Rate'!A$1:C94,3,FALSE) -> 3300 | F14: =C14 -> No | G14: =E14*D14 -> 382800
B15: C-channel (13') | C15: No | D15: =ROUND('Detail-Finishing'!H77/13,0) -> 440 | E15: =VLOOKUP(B15,'Material Rate'!A$1:C95,3,FALSE) -> 4500 | F15: =C15 -> No | G15: =E15*D15 -> 1980000
B16: ငါးရိုး Secrew | C16: No | D16: ='Detail-Finishing'!C79 -> 408 | E16: =VLOOKUP(B16,'Material Rate'!A$1:C96,3,FALSE) -> 0 | F16: =C16 -> No | G16: =E16*D16 -> 0
B17: 1" Black Secrew (85%) | C17: No | D17: ='Detail-Finishing'!C80 -> 1750 | E17: =VLOOKUP(B17,'Material Rate'!A$1:C97,3,FALSE) -> 0 | F17: =C17 -> No | G17: =E17*D17 -> 0
B18: 1½" Black Secrew (15%) | C18: No | D18: ='Detail-Finishing'!C81 -> 250 | E18: =VLOOKUP(B18,'Material Rate'!A$1:C98,3,FALSE) -> 0 | F18: =C18 -> No | G18: =E18*D18 -> 0
B19: ¼" သံ Wall Plug | C19: No | D19: ='Detail-Finishing'!C82 -> 250 | E19: =VLOOKUP(B19,'Material Rate'!A$1:C99,3,FALSE) -> 0 | F19: =C19 -> No | G19: =E19*D19 -> 0
B20: 1" Concrete Nail | C20: Box | D20: ='Detail-Finishing'!C83 -> 3 | E20: =VLOOKUP(B20,'Material Rate'!A$1:C105,3,FALSE) -> 0 | F20: =C20 -> Box | G20: =E20*D20 -> 0
B21: Labour
B22: Labour Charges for Ceiling | C22: Fs | D22: =D6 -> 2223.45 | E22: =VLOOKUP(B22,'Material Rate'!A$1:C107,3,FALSE) -> 1000 | F22: =C22 -> Fs | G22: =E22*D22 -> 2223450
A24: ='Detail-Finishing'!A85 -> 2 | B24: ='Detail-Finishing'!B85 -> Painting Work (UPG - Premier) | C24: ='Detail-Finishing'!J40 -> Fs | D24: =D25+D26+D27 -> 11266.94 | H24: =SUM(G24:G45) -> 16491376 | J24: =SUM(G45) -> 4506776 | L24: =ROUND(H24/$H$169,5) -> 0.6474 | M24: =ROUND(J24/$J$169,5) -> 0.6696
B25: ='Detail-Finishing'!B86 -> ( a ) External Paint (Putty 2, Sealer 2, Paint 2 Coat) | C25: Fs | D25: ='Detail-Finishing'!I114 -> 3279.29
B26: ='Detail-Finishing'!B116 -> ( b ) Internal Paint (Putty 2, Sealer 1, Paint 2 Coat) | C26: Fs | D26: ='Detail-Finishing'!I167 -> 5614.32
B27: ='Detail-Finishing'!B169 -> ( c ) Ceiling White | C27: Fs | D27: ='Detail-Finishing'!I174 -> 2373.33
B28: Material
B29: Putty | C29: Bag | D29: =ROUND((D25+D26)*0.6/100,0) -> 53 | E29: =E193 -> 24000 | F29: =C29 -> Bag | G29: =E29*D29 -> 1272000
B30: Sealer | C30: Lit | D30: =ROUND((D25*1.5)+(D26*0.8),0)/100 -> 94.1 | E30: =E194 -> 36000 | F30: =C30 -> Lit | G30: =E30*D30 -> 3387600
B31: External Paint | C31: Lit | D31: =ROUND(D25*2/100,0) -> 66 | E31: =E195 -> 31000 | F31: =C31 -> Lit | G31: =E31*D31 -> 2046000
B32: Internal Paint | C32: Lit | D32: =ROUND(D26*2/100,0) -> 112 | E32: =E196 -> 31000 | F32: =C32 -> Lit | G32: =E32*D32 -> 3472000
B33: Ceiling White | C33: Lit | D33: =ROUND(D27*2/100,0) -> 47 | E33: =E197 -> 31000 | F33: =C33 -> Lit | G33: =E33*D33 -> 1457000
B34: EC Putty | C34: Bag | D34: =ROUND(D27*1/750,0) -> 3 | E34: =E198 -> 55000 | F34: =C34 -> Bag | G34: =E34*D34 -> 165000
B35: ဇကာတိတ္ | C35: Ft | D35: =(D11+D12+D13)*12 -> 948 | E35: =VLOOKUP(B35,'Material Rate'!A$1:C120,3,FALSE) -> 50 | F35: =C35 -> Ft | G35: =E35*D35 -> 47400
B36: Sand Paper No.2 | C36: No | D36: =ROUND((D25+D26)*0.5/100,0) -> 44 | E36: =E200 -> 300 | F36: =C36 -> No | G36: =E36*D36 -> 13200
B37: P 360 ေကာ္ပတ္ | C37: Doz | D37: =ROUND((D25+D26)*0.1/100,0) -> 9 | E37: =E201 -> 2400 | F37: =C37 -> Doz | G37: =E37*D37 -> 21600
B38: သံဂ်ာ | C38: No | D38: =ROUND((D25+D26)*4/100/100,0) -> 4 | E38: =E202 -> 700 | F38: =C38 -> No | G38: =E38*D38 -> 2800
B39: Steel ျပား | C39: No | D39: 4 | E39: =E203 -> 3000 | F39: =C39 -> No | G39: =E39*D39 -> 12000
B40: Putty ျပား | C40: No | D40: =ROUND((D25+D26)*0.25/100,0) -> 22 | E40: =E204 -> 500 | F40: =C40 -> No | G40: =E40*D40 -> 11000
B41: Roller ကိုင္း | C41: No | D41: 7 | E41: =E205 -> 7000 | F41: =C41 -> No | G41: =E41*D41 -> 49000
...

Sheet Detail-Finishing
A1: Ko Aung Ko Myo (Aung Myittar (B) 11 Street)
A2: Two Storeyed RCC Building (25' x 35' x (13+12)')
A3: အေခ်ာထည္လုပ္ငန္း
A4: DETAILS OF MEASUREMENT
A5: Item | B5: Particular | C5: No. | D5: Measurement | G5: Deduction | H5: Contents | I5: Total of Each | J5: Unit
D6: L | E6: B | F6: H
A7: 1 | B7: Gypsum Borad Ceiling Work
B8: Internal Ceiling
B9: ( a ) Gypsum Board (Regular) Ceiling
B10: Ground Floor | C10: 1 | D10: 25 | E10: 35 | H10: =C10*D10*E10 -> 875 | J10: Fs
C11: 1 | D11: 3 | E11: 16 | H11: =C11*D11*E11 -> 48 | J11: Fs
B12: Deduction
B13: Bath & WC Room | C13: 1 | D13: 8 | E13: 5.5 | G13: =C13*D13*E13 -> 44 | J13: Fs
B14: Stair Room | C14: 1 | D14: 11.5 | E14: 9.5 | G14: =C14*D14*E14 -> 109.25 | J14: Fs
B15: 1st Floor | C15: 1 | D15: 25 | E15: 35 | H15: =C15*D15*E15 -> 875 | J15: Fs
B16: Deduction
B17: Bath & WC Room | C17: 1 | D17: 16 | E17: 5 | G17: =C17*D17*E17 -> 80 | J17: Fs
G18: =SUM(G10:G17) -> 233.25 | H18: =SUM(H10:H17) -> 1798 | I18: =H18-G18 -> 1564.75 | J18: Fs
B20: ( b ) Gypsum Board (Moisture) Ceiling
B21: Bath & WC Room (G.F) | C21: 1 | D21: 8 | E21: 5.5 | H21: =C21*D21*E21 -> 44 | J21: Fs
B22: Bath & WC Room (F.F) | C22: 1 | D22: 16 | E22: 5 | H22: =C22*D22*E22 -> 80 | J22: Fs
B23: Bath & WC Room (Under Landing) | J23: Fs
I24: =SUM(H21:H24) -> 124 | J24: Fs
B26: ( c ) External (Shera Board Ceiling)
B27: Portico Roof Eave | C27: 2 | D27: 5.33 | F27: 0.67 | H27: =C27*D27*F27 -> 7.14 | J27: Fs
B28: Portico Roof Softfit | C28: 2 | D28: 5.33 | F28: 1 | H28: =C28*D28*F28 -> 10.66 | J28: Fs
B29: Front Balcony Roof Eave (Incline) | C29: 2 | D29: 8.67 | F29: 0.67 | H29: =C29*D29*F29 -> 11.62 | J29: Fs
B30: Front Balcony Roof Softfit (Incline) | C30: 2 | D30: 8.67 | F30: 1 | H30: =C30*D30*F30 -> 17.34 | J30: Fs
B31: Front Balcony Roof Eave & Softfit (Y-Dir, Hor) | C31: 2 | D31: 3.5 | F31: 2.5 | H31: =C31*D31*F31 -> 17.5 | J31: Fs
B32: Line D (Eave) | C32: 2 | D32: 18 | F32: 0.67 | H32: =C32*D32*F32 -> 24.12 | J32: Fs
B33: Line D (Softfit) | C33: 2 | D33: 18 | F33: 2 | H33: =C33*D33*F33 -> 72 | J33: Fs
B34: Line 1 (Eave & Softfit) | C34: 1 | D34: 17.83 | F34: =1.33+1 -> 2.33 | H34: =C34*D34*F34 -> 41.54 | J34: Fs
B35: Line 1 (Eave & Softfit) | C35: 2 | D35: 16.5 | F35: =1+2 -> 3 | H35: =C35*D35*F35 -> 99 | J35: Fs
B36: Line A (Eave & Softfit) | C36: 1 | D36: 25 | F36: =0.83+2.17 -> 3 | H36: =C36*D36*F36 -> 75 | J36: Fs
B37: Line 3 (Eave & Softfit) | C37: 1 | D37: 17.83 | F37: =1.33+1 -> 2.33 | H37: =C37*D37*F37 -> 41.54 | J37: Fs
B38: Line 3 (Eave & Softfit) | C38: 2 | D38: 16.5 | F38: =1+2 -> 3 | H38: =C38*D38*F38 -> 99 | J38: Fs
B39: Line 3 (Eave & Softfit) | C39: 2 | D39: 6.08 | F39: 1.5 | H39: =C39*D39*F39 -> 18.24 | J39: Fs
I40: =SUM(H26:H40) -> 534.7 | J40: Fs
B42: L-BAR
B43: Ground Floor (Hall) | C43: 1 | D43: =22.5*2+24*2 -> 93 | H43: =C43*D43 -> 93 | J43: Ft
...

Sheet L-Rate
B1: Skilled | C1: 23000
B2: Worker | C2: 15000
B4: Excavation | D4: 2 | E4: =$C$2 -> 15000 | F4: =D4*E4 -> 30000 | H4: =SUM(F4) -> 30000
B5: Hardcore | D5: 1 | E5: =$C$2 -> 15000 | F5: =D5*E5 -> 15000 | H5: =SUM(F5) -> 15000
B6: Lean | D6: 1 | E6: =$C$1 -> 23000 | F6: =D6*E6 -> 23000 | H6: =SUM(F6:F7) -> 113000
D7: 6 | E7: =$C$2 -> 15000 | F7: =D7*E7 -> 90000
B8: 9" Brick Wall | D8: 4 | E8: =$C$1 -> 23000 | F8: =D8*E8 -> 92000 | H8: =SUM(F8:F9)*0.8 -> 145600
D9: 6 | E9: =$C$2 -> 15000 | F9: =D9*E9 -> 90000
B10: RC Concrete | D10: 1 | E10: =$C$1 -> 23000 | F10: =D10*E10 -> 23000 | H10: =SUM(F10:F11) -> 143000
D11: 8 | E11: =$C$2 -> 15000 | F11: =D11*E11 -> 120000
B12: Re Bar | D12: =20*0.75*0.5 -> 7.5 | E12: =$C$1 -> 23000 | F12: =D12*E12 -> 172500 | H12: =SUM(F12:F13)*0.8 -> 228000
D13: =D12 -> 7.5 | E13: =$C$2 -> 15000 | F13: =D13*E13 -> 112500
B14: F/W | D14: 2 | E14: =$C$1 -> 23000 | F14: =D14*E14 -> 46000 | H14: =SUM(F14:F15) -> 68500
D15: 1.5 | E15: =$C$2 -> 15000 | F15: =D15*E15 -> 22500
B16: 4½ Wall | D16: 2 | E16: =$C$1 -> 23000 | F16: =D16*E16 -> 46000 | H16: =SUM(F16:F17) -> 91000
D17: 3 | E17: =$C$2 -> 15000 | F17: =D17*E17 -> 45000
B18: Plaster | D18: 1 | E18: =$C$1 -> 23000 | F18: =D18*E18 -> 23000 | H18: =SUM(F18:F19) -> 53000
D19: 2 | E19: =$C$2 -> 15000 | F19: =D19*E19 -> 30000
B20: Topping | D20: 0.75 | E20: =$C$1 -> 23000 | F20: =D20*E20 -> 17250 | H20: =SUM(F20:F21) -> 39750
D21: 1.5 | E21: =$C$2 -> 15000 | F21: =D21*E21 -> 22500
B22: SS Roof | H22: 1775

Sheet Sheet2 (2)
A1: ေနာက္ဆက္တြဲ ၇။ (ခ)
A2: A | B2: ပါ၀င္ေသာလုပ္ငန္းမ်ား (ပစၥည္းဖိုး+လက္ခ အၿပီး) | C2: ပစၥည္းအမ်ိဳးအစား
A3: 1 | B3: Foundation လုပ္ငန္း
A4: 2 | B4: ကြန္ကရစ္လုပ္ငန္း
A5: 3 | B5: အုတ္စီ၊ ေခ်ာ၊ က်ည္းေဘာင္ေထာင္ | C5: 5"x2" ပ်ဥ္းကတိုးက်ည္းေဘာင္
A6: 4 | B6: မီးဖိုေခ်ာင္ခန္းေၾကြျပား | C6: အခင္းေၾကြျပား၊ နံရံေၾကြျပားအျမင့္ 5ေပ
A7: 5 | B7: အေပၚထပ္အတြင္းခန္းမ်ားကာရန္ျခင္း(8 ေပအျမင့္)၊ တံခါးအပါ | C7: 50x25 RHS Frame, 6mm Shera Board
A8: 7 | B8: ျပတင္းေပါက္တြင္ ဂ်ပန္ကြက္သံပန္းမ်ား | C8: ¾" M.S Flat ႏွင့္ 8mm M.S Plain Bar
A9: 8 | B9: အုတ္နံရံတြင္း/ျပင္၊ ကြန္ကရစ္မ်က္ႏွာျပင္ (တိုင္၊ ယက္မ၊ ပထမထပ္ Slab ႏွင့္ အမိုး Slab ေအာက္) ေဆးသုတ္ျခင္း | C9: အျပင္ေဆး Orient၊ အတြင္းေဆး UE
A10: 9 | B10: ေနာက္ဘက္ ေရခ်ိဳးခန္း၊ အိမ္သာခန္း
A11: 10 | B11: လုပ္ငန္းၿပီးဆံုးၿပီးေသာအခါ လုပ္ငန္းခြင္သန္႔ရွင္းေရး
A13: B | B13: ပစၥည္းစံခ်ိန္စံညႊန္း
B14: သံေခ်ာင္း | C14: HRB-400
B15: Cement | C15: Apachi, Double Rino
B16: RC Concrete | C16: G-25
A18: C | B18: ေငြေပးေခ်မႈ အစီအစဥ္ | C18: % | D18: ပမာဏ
A19: 1 | B19: လုပ္ငန္းစရန္ ႀကိဳတင္ေငြ (စာခ်ဳပ္ခ်ဳပ္ေသာေန႔တြင္) | C19: 0.3 | D19: =530*100000*0.3 -> 15900000
A20: 2 | B20: ေအာက္ခံခံုတံုးၿပီး၊ ေျမညီထပ္တိုင္ေထာင္ၿပီး | C20: 0.2 | D20: =530*100000*0.2 -> 10600000
A21: 3 | B21: အေပၚထပ္တိုင္ေထာင္၊ အမိုး Slab ေလာင္းၿပီး | C21: 0.2 | D21: =530*100000*0.2 -> 10600000
A22: 4 | B22: အုတ္စီ၊ က်ည္းေဘာင္ေထာင္၊ Plaster ေခ်ာၿပီး | C22: 0.2 | D22: =530*100000*0.2 -> 10600000 | G22: =265-180 -> 85
A23: 5 | B23: ေၾကြျပားခင္း၊ အေပၚထပ္တြင္းခန္းကာၿပီး | C23: 0.05 | D23: =530*100000*0.05 -> 2650000
A24: 6 | B24: ေဆးသုတ္လုပ္ငန္းၿပီး | C24: 0.05 | D24: =530*100000*0.05 -> 2650000
B25: စုစုေပါင္း | C25: =SUM(C19:C24) -> 1 | D25: =SUM(D19:D24) -> 53000000
A27: D | B27: စာခ်ဳပ္ပါေငြပမာဏ (၅၃၀သိန္းက်ပ္)တြင္ မပါ၀င္ေသးေသာလုပ္ငန္းမ်ား
A28: 1 | B28: ပါေကး | C28: အိမ္ရွင္စိတ္တိုင္းက် ဒီဇိုင္းပံုစံ၊ အရည္အေသြး ေရြးခ်ယ္ ၀ယ္ယူႏိုင္ရန္ခ်န္ထားျခင္းျဖစ္ပါသည္။
A29: 2 | B29: သစ္သားျပတင္းရြက္၊ သစ္သားတံခါးရြက္
A30: 3 | B30: ၀ရန္တာလက္ရန္း၊ ေလွခါးလက္ရန္း
A31: 4 | B31: လွ်ပ္စစ္မီးလုပ္ငန္း
A35: စဥ္ | B35: ေအာက္ထပ္ခန္းဖြဲ႔စည္းပံု
B36: အေရွ႕ဘက္ျခမ္း | C36: အတိုင္းအတာ
A37: 1 | B37: ဘုရားခန္း | C37: 6' 0" x 6' 0"
A38: 2 | B38: ဧည့္ခန္း | C38: 17' 6" x 9' 0"
A39: 3 | B39: အိပ္ခန္း နံပါတ္ (၁) | C39: 13' 0" x 9' 0"
A40: 4 | B40: အိပ္ခန္း နံပါတ္ (၂) | C40: 12' 6" x 9' 0"
B41: အေနာက္ဘက္ျခမ္း
A42: 5 | B42: ကားပါကင္ | C42: 14' 0" x 10' 0"
A43: 6 | B43: အိပ္ခန္း နံပါတ္ (၃) | C43: 10' 0" x 10' 0"
A44: 7 | B44: အေဆာင္သူ/သား ခ်က္ျပဳတ္ခန္း | C44: 6' 0" x 10' 0"
A45: 8 | B45: အိမ္ရွင္မီးဖိုေခ်ာင္ခန္း | C45: 13' 0" x 14' 0"
B46: အေပၚထပ္ခန္းဖြဲ႔စည္းပံု
...

Sheet Sheet1
B2: ေနာက္ဆက္တြဲ ၇။ (က)
B3: 1 | C3: Drawing Cover
B4: 2 | C4: Ground Floor Plan
B5: 3 | C5: First Floor Plan
B6: 4 | C6: Roof Plan
B7: 5 | C7: Front & Back Elevation
B8: 6 | C8: Left Side Elevation
B9: 7 | C9: Right Side Elevation
B10: 8 | C10: Door & Window Details
B11: 9 | C11: Foundation Plan
B12: 10 | C12: Plinth Beam Plan
B13: 11 | C13: Floor Beam & Slab Plan
B14: 12 | C14: Roof Beam & Slab Plan
... B16: 14 | C16: Beam & Slab Schedule

Sheet Sheet2
A1: ေနာက္ဆက္တြဲ ၇။ (ခ)
A2: A | B2: ပါ၀င္ေသာလုပ္ငန္းမ်ား (ပစၥည္းဖိုး+လက္ခ အၿပီး) | C2: ပစၥည္းအမ်ိဳးအစား
A3: 1 | B3: Foundation
A4: 2 | B4: ကြန္ကရစ္လုပ္ငန္း
A5: 3 | B5: အုတ္စီ၊ ေခ်ာ၊ က်ည္းေဘာင္ေထာင္ | C5: 5"x2" ပ်ဥ္းကတိုးက်ည္းေဘာင္
A6: 4 | B6: မီးဖိုေခ်ာင္ခန္းေၾကြျပား | C6: အခင္းေၾကြျပား၊ နံရံေၾကြျပားအျမင့္ 5ေပ
A7: 5 | B7: အေပၚထပ္အတြင္းခန္းမ်ားကာရန္ျခင္း(8 ေပအျမင့္)၊ တံခါးအပါ | C7: 50x25 RHS Frame, 6mm Shera Board
A8: 7 | B8: ျပတင္းေပါက္တြင္ ဂ်ပန္ကြက္သံပန္းမ်ား | C8: ¾" M.S Flat ႏွင့္ 8mm M.S Plain Bar
A9: 8 | B9: အုတ္နံရံတြင္း/ျပင္၊ ကြန္ကရစ္မ်က္ႏွာျပင္ (တိုင္၊ ယက္မ၊ ပထမထပ္ Slab ႏွင့္ အမိုး Slab ေအာက္) ေဆးသုတ္ျခင္း | C9: အျပင္ေဆး Orient၊ အတြင္းေဆး UE
A10: 9 | B10: ေနာက္ဘက္ ေရခ်ိဳးခန္း၊ အိမ္သာခန္း
A11: 10 | B11: လုပ္ငန္းၿပီးဆံုးၿပီးေသာအခါ လုပ္ငန္းခြင္သန္႔ရွင္းေရး
A13: B | B13: ေငြေပးေခ်မႈ အစီအစဥ္ | C13: % | D13: ပမာဏ
A14: 1 | B14: Down Payment | C14: 0.3 | D14: =530*100000*0.3 -> 15900000
A15: 2 | B15: ေအာက္ခံခံုတံုးၿပီး၊ ေျမညီထပ္တိုင္ေထာင္ၿပီး | C15: 0.2 | D15: =530*100000*0.2 -> 10600000
A16: 3 | B16: အေပၚထပ္တိုင္ေထာင္၊ အမိုး Slab ေလာင္းၿပီး | C16: 0.2 | D16: =530*100000*0.2 -> 10600000
A17: 4 | B17: အုတ္စီ၊ က်ည္းေဘာင္ေထာင္၊ Plaster ေခ်ာၿပီး | C17: 0.2 | D17: =530*100000*0.2 -> 10600000
A18: 5 | B18: ေၾကြျပားခင္း၊ အေပၚထပ္တြင္းခန္းကာၿပီး၊ ေဆးသုတ္လုပ္ငန္းၿပီး | C18: 0.1 | D18: =530*100000*0.1 -> 5300000
B19: စုစုေပါင္း | C19: =SUM(C14:C18) -> 1 | D19: =SUM(D14:D18) -> 53000000
A21: C | B21: လုပ္ငန္းလက္ခံသူေဆာင္ရြက္ရန္တာ၀န္
A22: 1 | B22: Archi, Structure Drawing၊ တာ၀န္ယူတည္ေဆာက္မည့္ အင္ဂ်င္နီယာလက္မွတ္
A23: 2 | B23: ေဆာက္လုပ္ေရးသံုးယႏၱယား၊ စက္ပစၥည္းမ်ား
A25: D | B25: လုပ္ငန္းအပ္ႏွံသူေဆာင္ရြက္ရန္တာ၀န္
A26: 1 | B26: လုပ္ငန္းခြင္သံုး ေရ၊ မီး၊ မီတာခ
A27: 2 | B27: အေဆာက္အဦ ေဆာက္လုပ္ခြင့္ စည္ပင္အခြန္အခ
A29: E | B29: လုပ္ငန္းလက္ခံထဲတြင္ မပါ၀င္ေသးေသာလုပ္ငန္းမ်ား
A30: 1 | B30: ပါေကး | C30: အိမ္ရွင္စိတ္တိုင္းက် ဒီဇိုင္းပံုစံ၊ အရည္အေသြး ေရြးခ်ယ္ ၀ယ္ယူႏိုင္ရန္ခ်န္ထားျခင္းျဖစ္ပါသည္။
A31: 2 | B31: သစ္သားျပတင္းရြက္၊ သစ္သားတံခါးရြက္
A32: 3 | B32: ၀ရန္တာလက္ရန္း၊ ေလွခါးလက္ရန္း
A33: 4 | B33: လွ်ပ္စစ္မီးလုပ္ငန္း
A36: စဥ္ | B36: ေအာက္ထပ္ခန္းဖြဲ႔စည္းပံု
B37: အေရွ႕ဘက္ျခမ္း | C37: အတိုင္းအတာ
A38: 1 | B38: ဘုရားခန္း | C38: 6' 0" x 6' 0"
A39: 2 | B39: ဧည့္ခန္း | C39: 17' 6" x 9' 0"
A40: 3 | B40: အိပ္ခန္း နံပါတ္ (၁) | C40: 13' 0" x 9' 0"
A41: 4 | B41: အိပ္ခန္း နံပါတ္ (၂) | C41: 12' 6" x 9' 0"
B42: အေနာက္ဘက္ျခမ္း
A43: 5 | B43: ကားပါကင္ | C43: 14' 0" x 10' 0"
A44: 6 | B44: အိပ္ခန္း နံပါတ္ (၃) | C44: 10' 0" x 10' 0"
A45: 7 | B45: အေဆာင္သူ/သား ခ်က္ျပဳတ္ခန္း | C45: 6' 0" x 10' 0"
A46: 8 | B46: အိမ္ရွင္မီးဖိုေခ်ာင္ခန္း | C46: 13' 0" x 14' 0"
...

Sheet Lab
B2: မူလလုပ္ငန္း | E2: 26.4.2021
A3: စဥ္ | B3: လုပ္ငန္းအမည္ | D3: ေငြပမာဏ (က်ပ္) | E3: ယေန႔ထိထုတ္ၿပီး | F3: က်န္ | H3: ရက္စြဲ
A4: 1 | B4: ပလင့္ခံုေလာင္းၿပီး | C4: =#REF! -> #REF! | D4: =1800000 -> 1800000 | E4: =500000+500000+800000 -> 1800000 | F4: =D4-E4 -> 0 | H4: ေပးေခ်ၿပီး
A5: 2 | B5: ပထမထပ္ ၾကမ္းခင္းဆလပ္ ေလာင္းၿပီး | C5: =#REF! -> #REF! | D5: =2000000 -> 2000000 | E5: =500000+1000000+500000 -> 2000000 | F5: =D5-E5 -> 0 | H5: ေပးေခ်ၿပီး
A6: 3 | B6: အမိုး ဆလပ္ေလာင္းၿပီး | C6: =#REF! -> #REF! | D6: =2000000 -> 2000000 | E6: =1000000+1000000 -> 2000000 | F6: =D6-E6 -> 0 | H6: ေပးေခ်ၿပီး
A7: 4 | B7: က်ည္းေဘာင္ေထာင္၊ နံရံအုတ္စီ၊ ေခ်ာၿပီး၊ ေရခ်ိဳးခန္း၊ အိမ္သာၿပီး | C7: =#REF! -> #REF! | D7: =2000000 -> 2000000 | E7: =500000+1000000 -> 1500000 | F7: =D7-E7 -> 500000 | H7: ေပးေခ်ၿပီး
A8: 5 | B8: ၾကမ္းခင္းသဲျဖည့္၊ ကြန္ကရစ္ေလာင္း၊ ေတာ္ပင္ေလာင္းၿပီး | C8: =#REF! -> #REF! | D8: =1814000 -> 1814000 | E8: =500000+800000+500000 -> 1800000 | F8: =D8-E8 -> 14000 | H8: 22.4.2021 | I8: 26.4.2021 | J8: 8.5.21
F9: =D9-E9 -> 0
B10: စုစုေပါင္း | C10: =SUM(C4:C9) -> #REF! | D10: =SUM(D4:D9) -> 9614000 | E10: =SUM(E4:E9) -> 9100000 | F10: =SUM(F4:F9) -> 514000 | G10: =23*44*2.5*3800 -> 9614000 | I10: =D10-E10 -> 514000
B12: ထပ္တိုးလုပ္ငန္း
A13: စဥ္ | B13: လုပ္ငန္းအမည္ | D13: ေငြပမာဏ | E13: ယေန႔ထိထုတ္ၿပီး | H13: ရက္စြဲ
A14: 1 | B14: အေပၚထပ္အတြင္းပိုင္းခန္းဖ႔ြဲကာ | D14: 500000 | E14: 500000 | H14: 22.4.2021
A15: 2 | B15: ေရစက္အိမ္ | D15: 60000 | E15: 60000 | H15: ေပးေခ်ၿပီး
A16: 3 | B16: ေၾကြးျပားလုပ္ငန္း (မီးဖိုေခ်ာင္၊ ေရခ်ိဳးခန္း၊ အိမ္သာ) ၃၅၀ႏႈန္း | D16: 190000 | E16: 100000 | H16: 26.4.2021
A17: 4 | B17: အမိုးေပၚေလွခါးအိမ္ | D17: 100000 | E17: 100000 | H17: 26.4.2021
B19: စုစုေပါင္း | D19: =SUM(D14:D18) -> 850000 | E19: =SUM(E14:E18) -> 760000 | I19: =D19-E19 -> 90000
B22: စုစုေပါင္း | D22: =D19+D10 -> 10464000
B24: ယခင္ထုတ္ၿပီး | D24: =E19+E10-1000000 -> 8860000
B25: ယေန႔ထုတ္ေငြ | D25: =1000000 -> 1000000
B26: ထုတ္ရန္က်န္ | D26: =D22-D24-D25 -> 604000
B29: =113 -> 113
B30: 21
B31: =4000*90/100000 -> 3.6
B32: =3.5 -> 3.5
B33: =6.5 -> 6.5
B34: 0.5
B35: =360*250/100000 -> 0.9
B36: =B29-B30-B31-B32-B33-B34-B35 -> 77

Sheet Sheet4
B1: ပလင့္ခံုအၿပီးထိ
A3: 1 | B3: C1 | D3: 216 | E3: ကြင္း
A5: 2 | B5: C2 | D5: 24 | E5: ကြင္း
A7: 3 | B7: PB1 | D7: 90 | E7: ကြင္း
A9: 4 | B9: PB2 | D9: 209 | E9: ကြင္း
A11: 5 | B11: PB3 | D11: 364 | E11: ကြင္း
B13: ေျမညီထပ္တိုင္
B14: C1 | D14: =18*27 -> 486 | E14: ကြင္း | K14: =216+486+450 -> 1152
K15: =24+90+54+90+50+90 -> 398
B16: C2 | D16: =2*27 -> 54 | E16: ကြင္း | K16: =209*3 -> 627
B17: ပထမထပ္ ဘင္း | K17: =364*3 -> 1092
B18: FB1
B20: FB2
B22: FB3
B23: ပထမထပ္တိုင္
B24: C1
B26: C2
B28: အမိုးဘင္း
B29: RB1
B31: RB2
B33: RB3
B36: Ready Made Formwork For Column (10 No)
A37: 1 | B37: Plain Sheet အထူ (4' Wide)
B38: 4' & 4' 6" Length Column Formwork
C39: 10 | D39: 2 | F39: 1 | G39: 4.5 | I39: =C39*D39*F39*G39 -> 90 | J39: Sft | M39: =I39/4 -> 22.5
C40: 10 | D40: 2 | F40: =1+2/12 -> 1.17 | G40: 4 | I40: =C40*D40*F40*G40 -> 93.6 | J40: Sft | L40: =I40/4 -> 23.4
B41: 6' & 6' 6" Length Column Formwork
C42: 10 | D42: 2 | F42: 1 | G42: 6 | I42: =C42*D42*F42*G42 -> 120 | J42: Sft | M42: =I42/4 -> 30
C43: 10 | D43: 2 | F43: =1+2/12 -> 1.17 | G43: 6.5 | I43: =C43*D43*F43*G43 -> 152.1 | J43: Sft | L43: =I43/4 -> 38.025
I44: =SUM(I39:I43) -> 455.7 | J44: Sft | M44: =L43+M42+23+24 -> 115.025
H45: 4' Wide | I45: =ROUNDUP(I44/4,0)+2 -> 116 | J45: Ft
I46: 1450 | J46: Ks/Ft
I47: =I45*I46 -> 168200 | J47: Ks
A48: 2 | B48: 2"x1" Hollow (1mm thk;)
B49: 4' & 4' 6" Length Column Formwork
C50: 10 | D50: 2 | E50: 2 | G50: 4 | I50: =C50*D50*E50*G50 -> 160 | J50: Ft
C51: 10 | D51: 2 | E51: 2 | G51: 4.5 | I51: =C51*D51*E51*G51 -> 180 | J51: Ft
B52: Strut | C52: 10 | D52: 2 | E52: 4 | G52: =8/12 -> 0.67 | I52: =C52*D52*E52*G52 -> 53.6 | J52: Ft | L52: =I52+I53+I57+I58 -> 270 | N52: =C52*D52*E52 -> 80
C53: 10 | D53: 2 | E53: 4 | G53: =10/12 -> 0.83 | I53: =C53*D53*E53*G53 -> 66.4 | J53: Ft | L53: =L52/19.5 -> 13.846154 | N53: =C53*D53*E53 -> 80
B54: 6' & 6' 6" Length Column Formwork | L54: =14*1200 -> 16800
...

Sheet Paint Survey
B2: External Paint | C2: Sud | D2: =65*2 -> 130
B3: Internal Paint | C3: Sud | D3: =365*2 -> 730
B4: Enamel Paint | C4: Sud | D4: =26*2 -> 52 | I4: Material | J4: Labour
B6: ဂ်ပန္ကြက္သံပန္း | C6: Sud | D6: =100*3*5.5/100 -> 16.5 | E6: =G6/D6 -> 2812.1212 | G6: =SUM(G7) -> 46400 | I6: =ROUNDUP(E6,-2) -> 2900 | J6: 5000 | K6: =SUM(I6:J6) -> 7900
B7: RED OXIDE | D7: 4 | E7: 11600 | G7: =D7*E7 -> 46400
B9: Putty (Ext+Int Area) | C9: Sud | D9: =D2+D3 -> 860 | E9: =G9/D9 -> 2583.2558 | G9: =SUM(G10:G14) -> 2221600 | I9: =ROUNDUP(E9,-2) -> 2600 | J9: 6500 | K9: =SUM(I9:J9) -> 9100
B10: PUTTY Bag | D10: 250 | E10: 8400 | G10: =D10*E10 -> 2100000
B11: SAND PAPER (No 2) | D11: 423 | E11: 200 | G11: =D11*E11 -> 84600
B12: သံဂ်ာ | D12: 20 | E12: 1000 | G12: =D12*E12 -> 20000
B13: Steel ျပား | D13: 2 | E13: 1000 | G13: =D13*E13 -> 2000
B14: Putty ျပား | D14: 50 | E14: 300 | G14: =D14*E14 -> 15000
B17: Int Paint | C17: Sud | D17: =D3 -> 730 | E17: =G17/D17 -> 2880.7534 | G17: =SUM(G18:G22) -> 2102950 | I17: =ROUNDUP(E17,-2) -> 2900 | J17: 3500 | K17: =SUM(I17:J17) -> 6400
B18: UE 9000 | D18: 23 | E18: =30900 -> 30900 | G18: =D18*E18 -> 710700
B19: UE 9101 | D19: 42 | E19: =30900 -> 30900 | G19: =D19*E19 -> 1297800
B20: SSUE 9505 | D20: 1.5 | E20: 47300 | G20: =D20*E20 -> 70950
B21: Roller ကိုင္း | D21: =ROUND(D17/50,0) -> 15 | E21: 1300 | G21: =D21*E21 -> 19500
B22: Roller ထုတ္ | D22: 2 | E22: 2000 | G22: =D22*E22 -> 4000
B24: Ext Paint | C24: Sud | D24: =D2 -> 130 | E24: =G24/D24 -> 5206.5385 | G24: =SUM(G25:G28) -> 676850 | I24: =ROUNDUP(E24,-2) -> 5300 | J24: 3500 | K24: =SUM(I24:J24) -> 8800
B25: OE 8201 | D25: 10 | E25: 60000 | G25: =D25*E25 -> 600000
B26: SSUE 9505 | D26: 1.5 | E26: 47300 | G26: =D26*E26 -> 70950
B27: Roller ကိုင္း | D27: =ROUND(D24/50,0) -> 3 | E27: 1300 | G27: =D27*E27 -> 3900
B28: Roller ထုတ္ | D28: 1 | E28: 2000 | G28: =D28*E28 -> 2000
B30: Enamel Paint | C30: Sud | D30: =D4 -> 52 | E30: =G30/D30 -> 14133.654 | G30: =SUM(G31:G39) -> 734950 | I30: =ROUNDUP(E30,-2) -> 14200 | J30: 20000 | K30: =SUM(I30:J30) -> 34200
B31: LA 1255 | D31: 4 | E31: 93500 | G31: =D31*E31 -> 374000
B32: UNDER COAT | D32: 4 | E32: 63400 | G32: =D32*E32 -> 253600
B33: TURPINTINE | D33: 8 | E33: 6000 | G33: =D33*E33 -> 48000
B34: SAND PAPER (180) | D34: 200 | E34: 200 | G34: =D34*E34 -> 40000
B35: 3" Brush | D35: 40 | E35: 300 | G35: =D35*E35 -> 12000
B36: 2" Brush | D36: 10 | E36: 200 | G36: =D36*E36 -> 2000
B37: 1" Brush | D37: 5 | E37: 150 | G37: =D37*E37 -> 750
B38: Roller ကိုင္း | D38: 2 | E38: 1300 | G38: =D38*E38 -> 2600
B39: Roller ထုတ္ | D39: 1 | E39: 2000 | G39: =D39*E39 -> 2000
C41: Mat | D41: Lab
B42: အတြင္းေဆး | C42: =I9+I17 -> 5500 | D42: =J9+J17 -> 10000 | F42: =SUM(C42:E42) -> 15500
B43: အျပင္ေဆး | C43: =I9+I24 -> 7900 | D43: =J9+J24 -> 10000 | F43: =SUM(C43:E43) -> 17900 | I43: 86 | K43: =C43*I43 -> 679400
B44: ဆီေဆး | C44: =I30 -> 14200 | D44: =J30 -> 20000 | F44: =SUM(C44:E44) -> 34200 | I44: 15 | K44: =C44*I44 -> 213000
K45: =SUM(K43:K44) -> 892400

Sheet Slab Concrete
A2: 1 | B2: Column | C2: 4 | D2: 1 | E2: 1 | F2: =14/12 -> 1.17 | H2: =C2*D2*E2*F2 -> 4.68 | J2: =H2/3.281/3.281/3.281 -> 0.13 | K2: M³ | L2: =J2 -> 0.13
B3: Line A Beam | C3: 1 | D3: 8 | E3: 0.75 | F3: 1 | H3: =C3*D3*E3*F3 -> 6 | J3: =H3/3.281/3.281/3.281 -> 0.17 | K3: M³ | L3: =L2+J3 -> 0.3
C4: 1 | D4: 3.5 | E4: 0.75 | F4: 0.75 | H4: =C4*D4*E4*F4 -> 1.97 | J4: =H4/3.281/3.281/3.281 -> 0.06 | K4: M³ | L4: =L3+J4 -> 0.36
C5: 1 | D5: 8 | E5: 0.75 | F5: 1 | H5: =C5*D5*E5*F5 -> 6 | J5: =H5/3.281/3.281/3.281 -> 0.17 | K5: M³ | L5: =L4+J5 -> 0.53
B6: Slab | C6: 1 | D6: =12.5 -> 12.5 | E6: 8.5 | F6: 0.33 | H6: =C6*D6*E6*F6 -> 35.06 | J6: =H6/3.281/3.281/3.281 -> 0.99 | K6: M³ | L6: =L5+J6 -> 1.52
C7: 1 | D7: 12.5 | E7: 3.5 | F7: 0.33 | H7: =C7*D7*E7*F7 -> 14.44 | J7: =H7/3.281/3.281/3.281 -> 0.41 | K7: M³ | L7: =L6+J7 -> 1.93
C8: 1 | D8: 12.5 | E8: 8.5 | F8: 0.33 | H8: =C8*D8*E8*F8 -> 35.06 | J8: =H8/3.281/3.281/3.281 -> 0.99 | K8: M³ | L8: =L7+J8 -> 2.92
B9: Line 1,2,3,5 Beam | C9: 4 | D9: 12 | E9: 0.75 | F9: =14/12 -> 1.17 | H9: =C9*D9*E9*F9 -> 42.12 | J9: =H9/3.281/3.281/3.281 -> 1.19 | K9: =SUM(J2:J9) -> 4.11 | L9: =L8+J9 -> 4.11
A10: 2 | B10: Column | C10: 4 | D10: 1 | E10: 1 | F10: =14/12 -> 1.17 | H10: =C10*D10*E10*F10 -> 4.68 | J10: =H10/3.281/3.281/3.281 -> 0.13 | K10: M³ | L10: =L9+J10 -> 4.24
B11: Line B Beam | C11: 1 | D11: 8 | E11: 0.75 | F11: 1 | H11: =C11*D11*E11*F11 -> 6 | J11: =H11/3.281/3.281/3.281 -> 0.17 | K11: M³ | L11: =L10+J11 -> 4.41
C12: 1 | D12: 3.5 | E12: 0.75 | F12: 0.75 | H12: =C12*D12*E12*F12 -> 1.97 | J12: =H12/3.281/3.281/3.281 -> 0.06 | K12: M³ | L12: =L11+J12 -> 4.47
C13: 1 | D13: 8 | E13: 0.75 | F13: 1 | H13: =C13*D13*E13*F13 -> 6 | J13: =H13/3.281/3.281/3.281 -> 0.17 | K13: M³ | L13: =L12+J13 -> 4.64
B14: Slab | C14: 1 | D14: =12.25 -> 12.25 | E14: 8.5 | F14: 0.33 | H14: =C14*D14*E14*F14 -> 34.36 | J14: =H14/3.281/3.281/3.281 -> 0.97 | K14: M³ | L14: =L13+J14 -> 5.61
C15: 1 | D15: 12.25 | E15: 3.5 | F15: 0.33 | H15: =C15*D15*E15*F15 -> 14.15 | J15: =H15/3.281/3.281/3.281 -> 0.4 | K15: M³ | L15: =L14+J15 -> 6.01
C16: 1 | D16: 12.25 | E16: 8.5 | F16: 0.33 | H16: =C16*D16*E16*F16 -> 34.36 | J16: =H16/3.281/3.281/3.281 -> 0.97 | K16: M³ | L16: =L15+J16 -> 6.98
B17: Line 1,2,3,5 Beam | C17: 4 | D17: 12 | E17: 0.75 | F17: =14/12 -> 1.17 | H17: =C17*D17*E17*F17 -> 42.12 | J17: =H17/3.281/3.281/3.281 -> 1.19 | K17: =SUM(J10:J17) -> 4.06 | L17: =L16+J17 -> 8.17
A18: 3 | B18: Column | C18: 4 | D18: 1 | E18: 1 | F18: =14/12 -> 1.17 | H18: =C18*D18*E18*F18 -> 4.68 | J18: =H18/3.281/3.281/3.281 -> 0.13 | K18: M³ | L18: =L17+J18 -> 8.3
B19: Line C Beam | C19: 1 | D19: 8 | E19: 0.75 | F19: 1 | H19: =C19*D19*E19*F19 -> 6 | J19: =H19/3.281/3.281/3.281 -> 0.17 | K19: M³ | L19: =L18+J19 -> 8.47
C20: 1 | D20: 3.5 | E20: 0.75 | F20: 0.75 | H20: =C20*D20*E20*F20 -> 1.97 | J20: =H20/3.281/3.281/3.281 -> 0.06 | K20: M³ | L20: =L19+J20 -> 8.53
C21: 1 | D21: 8 | E21: 0.75 | F21: 1 | H21: =C21*D21*E21*F21 -> 6 | J21: =H21/3.281/3.281/3.281 -> 0.17 | K21: M³ | L21: =L20+J21 -> 8.7
B22: Slab | C22: 1 | D22: =3.5 -> 3.5 | E22: 8.5 | F22: 0.33 | H22: =C22*D22*E22*F22 -> 9.82 | J22: =H22/3.281/3.281/3.281 -> 0.28 | K22: M³ | L22: =L21+J22 -> 8.98
C23: 1 | D23: 3.5 | E23: 3.5 | F23: 0.33 | H23: =C23*D23*E23*F23 -> 4.04 | J23: =H23/3.281/3.281/3.281 -> 0.11 | K23: M³ | L23: =L22+J23 -> 9.09
C24: 1 | D24: 3.5 | E24: 8.5 | F24: 0.33 | H24: =C24*D24*E24*F24 -> 9.82 | J24: =H24/3.281/3.281/3.281 -> 0.28 | K24: M³ | L24: =L23+J24 -> 9.37
B25: Line 1,2,3,5 Beam | C25: 4 | D25: 3.5 | E25: 0.75 | F25: 0.75 | H25: =C25*D25*E25*F25 -> 7.875 | J25: =H25/3.281/3.281/3.281 -> 0.22 | K25: =SUM(J18:J25) -> 1.42 | L25: =L24+J25 -> 9.59
A26: 4 | B26: Column | C26: 4 | D26: 1 | E26: 1 | F26: =14/12 -> 1.17 | H26: =C26*D26*E26*F26 -> 4.68 | J26: =H26/3.281/3.281/3.281 -> 0.13 | K26: M³ | L26: =L25+J26 -> 9.72
B27: Line D Beam | C27: 1 | D27: 8 | E27: 0.75 | F27: 1 | H27: =C27*D27*E27*F27 -> 6 | J27: =H27/3.281/3.281/3.281 -> 0.17 | K27: M³ | L27: =L26+J27 -> 9.89
C28: 1 | D28: 3.25 | E28: 0.75 | F28: 1 | H28: =C28*D28*E28*F28 -> 2.44 | J28: =H28/3.281/3.281/3.281 -> 0.07 | K28: M³ | L28: =L27+J28 -> 9.96
C29: 1 | D29: 9 | E29: 0.75 | F29: 1 | H29: =C29*D29*E29*F29 -> 6.75 | J29: =H29/3.281/3.281/3.281 -> 0.19 | K29: M³ | L29: =L28+J29 -> 10.15
B30: Slab | C30: 1 | D30: 13 | E30: 8.5 | F30: 0.33 | H30: =C30*D30*E30*F30 -> 36.47 | J30: =H30/3.281/3.281/3.281 -> 1.03 | K30: M³ | L30: =L29+J30 -> 11.18
C31: 1 | D31: 13 | E31: 9.25 | F31: 0.33 | H31: =C31*D31*E31*F31 -> 39.68 | J31: =H31/3.281/3.281/3.281 -> 1.12 | K31: M³ | L31: =L30+J31 -> 12.3
B32: Line 1,2,3,5 Beam | C32: 4 | D32: 12.5 | E32: 0.75 | F32: =14/12 -> 1.17 | H32: =C32*D32*E32*F32 -> 43.875 | J32: =H32/3.281/3.281/3.281 -> 1.24 | K32: =SUM(J26:J32) -> 3.95 | L32: =L31+J32 -> 13.54
A33: 5 | B33: Column | C33: 4 | D33: 1 | E33: 1 | F33: =14/12 -> 1.17 | H33: =C33*D33*E33*F33 -> 4.68 | J33: =H33/3.281/3.281/3.281 -> 0.13 | K33: M³ | L33: =L32+J33 -> 13.67
B34: Line E Beam | C34: 1 | D34: 8 | E34: 0.75 | F34: 1 | H34: =C34*D34*E34*F34 -> 6 | J34: =H34/3.281/3.281/3.281 -> 0.17 | K34: M³ | L34: =L33+J34 -> 13.84
C35: 1 | D35: 3.25 | E35: 0.75 | F35: 0.75 | H35: =C35*D35*E35*F35 -> 1.83 | J35: =H35/3.281/3.281/3.281 -> 0.05 | K35: M³ | L35: =L34+J35 -> 13.89
C36: 1 | D36: 9 | E36: 0.75 | F36: 1 | H36: =C36*D36*E36*F36 -> 6.75 | J36: =H36/3.281/3.281/3.281 -> 0.19 | K36: =SUM(J33:J36) -> 0.54 | L36: =L35+J36 -> 14.08
A37: 6 | B37: Stair | L37: =L36+J37 -> 14.08
B38: Column | C38: 1 | D38: 0.75 | E38: 0.75 | F38: 4.5 | H38: =C38*D38*E38*F38 -> 2.53 | J38: =H38/3.281/3.281/3.281 -> 0.07 | K38: M³ | L38: =L37+J38 -> 14.15
B39: Landing Beam | C39: 1 | D39: 2.75 | E39: 0.75 | F39: 1 | H39: =C39*D39*E39*F39 -> 2.06 | J39: =H39/3.281/3.281/3.281 -> 0.06 | K39: M³ | L39: =L38+J39 -> 14.21
B40: Waist | C40: 1 | D40: 16.5 | E40: 2.75 | F40: 0.42 | H40: =C40*D40*E40*F40 -> 19.06 | J40: =H40/3.281/3.281/3.281 -> 0.54 | K40: M³ | L40: =L39+J40 -> 14.75
B41: Step | C41: 1 | D41: 0.75 | E41: =2.75 -> 2.75 | F41: =6/12 -> 0.5 | H41: =C41*D41*E41*F41 -> 1.03 | J41: =H41/3.281/3.281/3.281 -> 0.03 | K41: M³ | L41: =L40+J41 -> 14.78
...
