Workbook
Name _1Excel_BuiltIn_Print_Area_2_1_1_1: #REF!
Name _1Excel_BuiltIn_Print_Area_2_1_1_1: #REF!
Name _1Excel_BuiltIn_Print_Area_2_1_1_1: #REF!
Name _1Excel_BuiltIn_Print_Area_2_1_1_1: #REF!
Name _1Excel_BuiltIn_Print_Area_2_1_1_1: #REF!
Name _1Excel_BuiltIn_Print_Area_2_1_1_1: #REF!
Name _1Excel_BuiltIn_Print_Area_2_1_1_1: #REF!
Name _1Excel_BuiltIn_Print_Area_2_1_1_1: #REF!
Name _1Excel_BuiltIn_Print_Area_2_1_1_1: #REF!
Name _1Excel_BuiltIn_Print_Area_2_1_1_1: #REF!
Name _1Excel_BuiltIn_Print_Area_2_1_1_1: #REF!
Name _2Excel_BuiltIn_Print_Titles_2_1_1_1: "$#REF!.$A$8:$IP$385"
Name add: #REF!
Name add: #REF!
Name add: #REF!
Name add: #REF!
Name add: #REF!
Name Excel_BuiltIn_Print_Area_10_1: #REF!
Name Excel_BuiltIn_Print_Area_10_1: #REF!
Name Excel_BuiltIn_Print_Area_10_1: #REF!
Name Excel_BuiltIn_Print_Area_10_1: #REF!
Name Excel_BuiltIn_Print_Area_10_1: #REF!
Name Excel_BuiltIn_Print_Area_10_1: #REF!
Name Excel_BuiltIn_Print_Area_10_1: #REF!
Name Excel_BuiltIn_Print_Area_10_1: #REF!
Name Excel_BuiltIn_Print_Area_10_1: #REF!
Name Excel_BuiltIn_Print_Area_10_1: #REF!
Name Excel_BuiltIn_Print_Area_10_1: #REF!
Name Excel_BuiltIn_Print_Area_10_1: #REF!
Name Excel_BuiltIn_Print_Area_10_1_1: "$#REF!.$A$8:$M$385"
Name Excel_BuiltIn_Print_Area_11_1: #REF!
Name Excel_BuiltIn_Print_Area_11_1: #REF!
Name Excel_BuiltIn_Print_Area_11_1: #REF!
Name Excel_BuiltIn_Print_Area_11_1: #REF!
Name Excel_BuiltIn_Print_Area_11_1: #REF!
Name Excel_BuiltIn_Print_Area_11_1: #REF!
Name Excel_BuiltIn_Print_Area_11_1: #REF!
Name Excel_BuiltIn_Print_Area_11_1: #REF!
Name Excel_BuiltIn_Print_Area_11_1: #REF!
Name Excel_BuiltIn_Print_Area_11_1: #REF!
Name Excel_BuiltIn_Print_Area_11_1: #REF!
Name Excel_BuiltIn_Print_Area_11_1: #REF!
Name Excel_BuiltIn_Print_Area_11_1_1: "$#REF!.$A$8:$M$385"
Name Excel_BuiltIn_Print_Area_12_1: "$#REF!.$A$8:$M$385"
Name Excel_BuiltIn_Print_Area_13_1: "$#REF!.$A$1:$I$32"
Name Excel_BuiltIn_Print_Area_13_1_1: "$#REF!.$A$8:$M$419"
Name Excel_BuiltIn_Print_Area_14_1: "$#REF!.$A$1:$T$32"
Name Excel_BuiltIn_Print_Area_14_1_1: "$#REF!.$A$8:$M$385"
Name Excel_BuiltIn_Print_Area_15: "$#REF!.$A$1:$U$53"
Name Excel_BuiltIn_Print_Area_15_1: "$#REF!.$A$8:$M$385"
Name Excel_BuiltIn_Print_Area_16: "$#REF!.$A$1:$I$30"
Name Excel_BuiltIn_Print_Area_17: "$#REF!.$A$8:$M$477"
Name Excel_BuiltIn_Print_Area_18: "$#REF!.$A$8:$M$385"
Name Excel_BuiltIn_Print_Area_19: "$#REF!.$A$8:$M$385"
Name Excel_BuiltIn_Print_Area_2_1: #REF!
Name Excel_BuiltIn_Print_Area_2_1: #REF!
Name Excel_BuiltIn_Print_Area_2_1: #REF!
Name Excel_BuiltIn_Print_Area_2_1: #REF!
Name Excel_BuiltIn_Print_Area_2_1: #REF!
Name Excel_BuiltIn_Print_Area_2_1: #REF!

Sheet Summary Of Cost
A1: Three Storeyed RCC Building
A2: 33'-6"x36'-6"x41'-0" Ht;
A3: Total Summary | E3: Date : | F3: =TODAY() -> 46185
A4: No. | B4: Particular | C4: Amount | D4: Remark
A6: 1 | B6: Main Building | C6: ='Summary (Civil)'!D15 -> 477800000 | F6: 459900000 | H6: အုတ်ဖိုးပြောင်း
A7: 2 | B7: Ground Tank | C7: =[1]Summary!$C$13 -> 4900000 | F7: 462500000 | H7: ဘိလပ်မြေဖိုးပြောင်း
A8: 3 | B8: Septic Tank | C8: =[2]Summary!$C$12 -> 3700000 | F8: 478800000 | H8: သစ်ဖိုးပြောင်း
F9: 459000000 | G9: =F9-F10 -> 1600000 | H9: ၉" အုတ်ရိုးထပ်ဖြည့် | J9: =F8-F9 -> 19800000
B10: Total Cost | C10: =SUM(C6:C9) -> 486400000 | F10: 457400000
B11: မြေပြန်ဖြည့်ခ | D11: Backhoe 1 duty
B12: Say (For 1 No.) | C12: =ROUNDDOWN(C10,-4) -> 486400000 | F12: =C12-[3]Summary!$C$14 -> 229100000
B14: Area | D14: Sq-ft
B15: PAE Rate | C15: =C12/C14 -> #DIV/0! | D15: per Sq-ft
B16: Area | C16: ='Summary (Civil)'!D19 -> 5346.844 | D16: Sq-ft | F16: 20000
B17: (33.5*36*4)+16*4+(17.5*4+16*4)*0.4+17.5*4*0.4+(33.5*25+(13.5+16)*3.58)*0.4
B18: PAE Rate | C18: =C12/C16 -> 90969.551 | D18: per Sq-ft | F18: =C16*F16 -> 106936880

Sheet Summary (Civil)
A1: Three Storeyed RCC Building
A2: 33'-6"x36'-6"x41'-0" Ht; | G2: =13+12+11+3 -> 39
A3: Summary | F3: Date : | G3: =TODAY() -> 46185
A4: No. | B4: Particular | D4: Amount | E4: Remark
A6: 1 | B6: Material Cost | D6: =BQ!G61 -> 2.6228171e+08 | G6: =[4]Summary!$C$6+[5]Summary!$C$6 -> 32096652
A7: 2 | B7: Labour Cost | D7: =BQ!G70 -> 1.3939064e+08 | G7: =[4]Summary!$C$7+[5]Summary!$C$7 -> 11754110
B9: Total Cost | D9: =SUM(D6:D7) -> 4.0167235e+08
B10: မြေပြန်ဖြည့်ခ | E10: Backhoe 1 duty
B11: Transportation Charges | C11: 0.03 | D11: =D9*C11 -> 12050171
B12: Preliminary Charges | C12: 0.05 | D12: =(D9+D11)*C12 -> 20686126
B13: Supervision Charges | C13: 0.1 | D13: =(D12+D11+D9)*C13 -> 43440865
B14: Grand Total Cost | D14: =SUM(D9:D13) -> 4.7784951e+08 | G14: =BQ!G74 -> 4.3440865e+08 | H14: =D14-G14 -> 43440865
B15: Say (For 1 No.) | D15: =ROUNDDOWN(D14,-5) -> 477800000 | E15: Main Building | G15: =D15-[3]Summary!$C$14 -> 220500000
B17: Area | E17: Sq-ft
B18: PAE Rate | D18: =D15/D17 -> #DIV/0! | E18: per Sq-ft
B19: Area | D19: =(33.5*36*4)+16*4+(17.5*4+16*4)*0.4+17.5*4*0.4+(33.5*25+(13.5+16)*3.58)*0.4 -> 5346.844 | F19: =45*34 -> 1530
B20: PAE Rate | D20: =D15/D19 -> 89361.126 | E20: Main Builing

Sheet Abstract of Cost
A1: Project : Three Storeyed RCC Residential Building, Magway
A2: Work Item : Main Building ( Civil Work )
A3: Abstract Of Cost
A4: No | B4: Particular | C4: Quantity | D4: Nos | E4: Rate | F4: Per | G4: Amount
A6: 1 | B6: =VLOOKUP(A6,'Builder Estimate'!A:H,2,FALSE) -> Site Clearing Work | C6: =VLOOKUP(A6,'Builder Estimate'!A:H,3,FALSE) -> 3246.75 | D6: =VLOOKUP(A6,'Builder Estimate'!$A:$H,4,FALSE) -> 3246.75 | E6: =G6/C6 -> 217.8 | F6: =VLOOKUP(A6,'Builder Estimate'!$A:$H,5,FALSE) -> Sft | G6: =VLOOKUP(A6,'Builder Estimate'!$A:$H,8,FALSE) -> 707142.15
A8: 2 | B8: =VLOOKUP(A8,'Builder Estimate'!A:H,2,FALSE) -> Surveying & Leveling Work | C8: =VLOOKUP(A8,'Builder Estimate'!A:H,3,FALSE) -> 2206.75 | D8: =VLOOKUP(A8,'Builder Estimate'!$A:$H,4,FALSE) -> 2206.75 | E8: =G8/C8 -> 83.93 | F8: =VLOOKUP(A8,'Builder Estimate'!$A:$H,5,FALSE) -> Sft | G8: =VLOOKUP(A8,'Builder Estimate'!$A:$H,8,FALSE) -> 185212.53
A10: 3 | B10: =VLOOKUP(A10,'Builder Estimate'!A:H,2,FALSE) -> Earth Work Excavating Foundation in Ordinary Soil to a depth of 5Ft. | C10: =VLOOKUP(A10,'Builder Estimate'!A:H,3,FALSE) -> 11624.031 | D10: =VLOOKUP(A10,'Builder Estimate'!$A:$H,4,FALSE) -> 11624.031 | E10: =G10/C10 -> 435.6 | F10: =VLOOKUP(A10,'Builder Estimate'!$A:$H,5,FALSE) -> Cft | G10: =VLOOKUP(A10,'Builder Estimate'!$A:$H,8,FALSE) -> 5063428
A12: 4 | B12: =VLOOKUP(A12,'Builder Estimate'!A:H,2,FALSE) -> Plumb Concrete with (6"x9") Stone and (1:3:6)Lean Concrete | C12: =VLOOKUP(A12,'Builder Estimate'!A:H,3,FALSE) -> 1375.625 | D12: =VLOOKUP(A12,'Builder Estimate'!$A:$H,4,FALSE) -> 1375.625 | E12: =G12/C12 -> 5295.9675 | F12: =VLOOKUP(A12,'Builder Estimate'!$A:$H,5,FALSE) -> Cft | G12: =VLOOKUP(A12,'Builder Estimate'!$A:$H,8,FALSE) -> 7285265.3
B13: HardCore
B14: (1:3:6) Concrete
A16: 5 | B16: =VLOOKUP(A16,'Builder Estimate'!A:H,2,FALSE) -> Hardcore Filling Work | C16: =VLOOKUP(A16,'Builder Estimate'!A:H,3,FALSE) -> 454.10417 | D16: =VLOOKUP(A16,'Builder Estimate'!$A:$H,4,FALSE) -> 454.10417 | E16: =G16/C16 -> 2966.15 | F16: =VLOOKUP(A16,'Builder Estimate'!$A:$H,5,FALSE) -> Cft | G16: =VLOOKUP(A16,'Builder Estimate'!$A:$H,8,FALSE) -> 1346941.1
A18: 6 | B18: =VLOOKUP(A18,'Builder Estimate'!A:H,2,FALSE) -> 1:3:6 Lean Concrete Laying Work | C18: =VLOOKUP(A18,'Builder Estimate'!A:H,3,FALSE) -> 779.45833 | D18: =VLOOKUP(A18,'Builder Estimate'!$A:$H,4,FALSE) -> 779.45833 | E18: =G18/C18 -> 6283.9857 | F18: =VLOOKUP(A18,'Builder Estimate'!$A:$H,5,FALSE) -> Cft | G18: =VLOOKUP(A18,'Builder Estimate'!$A:$H,8,FALSE) -> 4898105
A20: 7 | B20: =VLOOKUP(A20,'Builder Estimate'!A:H,2,FALSE) -> Sand Filling Work | C20: =VLOOKUP(A20,'Builder Estimate'!A:H,3,FALSE) -> 2236.875 | D20: =VLOOKUP(A20,'Builder Estimate'!$A:$H,4,FALSE) -> 2236.875 | E20: =G20/C20 -> 905.3 | F20: =VLOOKUP(A20,'Builder Estimate'!$A:$H,5,FALSE) -> Cft | G20: =VLOOKUP(A20,'Builder Estimate'!$A:$H,8,FALSE) -> 2025042.9
A22: 8 | B22: =VLOOKUP(A22,'Builder Estimate'!A:H,2,FALSE) -> 1:2:4 Reinforced Cement Concrete Work | C22: =VLOOKUP(A22,'Builder Estimate'!A:H,3,FALSE) -> 6206.1623 | D22: =VLOOKUP(A22,'Builder Estimate'!$A:$H,4,FALSE) -> 6206.1623 | E22: =G22/C22 -> 9313.3767 | F22: =VLOOKUP(A22,'Builder Estimate'!$A:$H,5,FALSE) -> Cft | G22: =VLOOKUP(A22,'Builder Estimate'!$A:$H,8,FALSE) -> 57800327
A24: 9 | B24: =VLOOKUP(A24,'Builder Estimate'!A:H,2,FALSE) -> Earth Filling & Watering Work | C24: =VLOOKUP(A24,'Builder Estimate'!A:H,3,FALSE) -> 8322.6019 | D24: =VLOOKUP(A24,'Builder Estimate'!$A:$H,4,FALSE) -> 8322.6019 | E24: =G24/C24 -> 217.8 | F24: =VLOOKUP(A24,'Builder Estimate'!$A:$H,5,FALSE) -> Cft | G24: =VLOOKUP(A24,'Builder Estimate'!$A:$H,8,FALSE) -> 1812662.7
A26: 10 | B26: =VLOOKUP(A26,'Builder Estimate'!A:H,2,FALSE) -> Form Work - 3 Time Used | C26: =VLOOKUP(A26,'Builder Estimate'!A:H,3,FALSE) -> 12491.302 | D26: =VLOOKUP(A26,'Builder Estimate'!$A:$H,4,FALSE) -> 12491.302 | E26: =G26/C26 -> 8023.6292 | F26: =VLOOKUP(A26,'Builder Estimate'!$A:$H,5,FALSE) -> Sft | G26: =VLOOKUP(A26,'Builder Estimate'!$A:$H,8,FALSE) -> 1.0022558e+08
A28: 11(a) | B28: =VLOOKUP(A28,'Builder Estimate'!A:H,2,FALSE) -> Mild Steel Work for Footing | C28: =VLOOKUP(A28,'Builder Estimate'!A:H,3,FALSE) -> 9.1803088 | D28: =VLOOKUP(A28,'Builder Estimate'!$A:$H,4,FALSE) -> 9.1803088 | E28: =G28/C28 -> 4099700 | F28: =VLOOKUP(A28,'Builder Estimate'!$A:$H,5,FALSE) -> Ton | G28: =VLOOKUP(A28,'Builder Estimate'!$A:$H,8,FALSE) -> 37636512
A30: 11(b) | B30: =VLOOKUP(A30,'Builder Estimate'!A:H,2,FALSE) -> Mild Steel Work for Basement Wall | C30: =VLOOKUP(A30,'Builder Estimate'!A:H,3,FALSE) -> 1.3835556 | D30: =VLOOKUP(A30,'Builder Estimate'!$A:$H,4,FALSE) -> 1.3835556 | E30: =G30/C30 -> 3835904.7 | F30: =VLOOKUP(A30,'Builder Estimate'!$A:$H,5,FALSE) -> Ton | G30: =VLOOKUP(A30,'Builder Estimate'!$A:$H,8,FALSE) -> 5307187.3
A32: 11(c) | B32: =VLOOKUP(A32,'Builder Estimate'!A:H,2,FALSE) -> Mild Steel Work for Column | C32: =VLOOKUP(A32,'Builder Estimate'!A:H,3,FALSE) -> 3.9821284 | D32: =VLOOKUP(A32,'Builder Estimate'!$A:$H,4,FALSE) -> 3.9821284 | E32: =G32/C32 -> 4172661.1 | F32: =VLOOKUP(A32,'Builder Estimate'!$A:$H,5,FALSE) -> Ton | G32: =VLOOKUP(A32,'Builder Estimate'!$A:$H,8,FALSE) -> 16616072
A34: 11(d) | B34: =VLOOKUP(A34,'Builder Estimate'!A:H,2,FALSE) -> Mild Steel Work for Beam | C34: =VLOOKUP(A34,'Builder Estimate'!A:H,3,FALSE) -> 7.5441725 | D34: =VLOOKUP(A34,'Builder Estimate'!$A:$H,4,FALSE) -> 7.5441725 | E34: =G34/C34 -> 4105912 | F34: =VLOOKUP(A34,'Builder Estimate'!$A:$H,5,FALSE) -> Ton | G34: =VLOOKUP(A34,'Builder Estimate'!$A:$H,8,FALSE) -> 30975709
A36: 11(e) | B36: =VLOOKUP(A36,'Builder Estimate'!A:H,2,FALSE) -> Mild Steel Work for Slab | C36: =VLOOKUP(A36,'Builder Estimate'!A:H,3,FALSE) -> 8.8262704 | D36: =VLOOKUP(A36,'Builder Estimate'!$A:$H,4,FALSE) -> 8.8262704 | E36: =G36/C36 -> 4087670.6 | F36: =VLOOKUP(A36,'Builder Estimate'!$A:$H,5,FALSE) -> Ton | G36: =VLOOKUP(A36,'Builder Estimate'!$A:$H,8,FALSE) -> 36078886
A38: 11(f) | B38: =VLOOKUP(A38,'Builder Estimate'!A:H,2,FALSE) -> Mild Steel Work for Stiffner | C38: =VLOOKUP(A38,'Builder Estimate'!A:H,3,FALSE) -> 1.8414569 | D38: =VLOOKUP(A38,'Builder Estimate'!$A:$H,4,FALSE) -> 1.8414569 | E38: =G38/C38 -> 4661323 | F38: =VLOOKUP(A38,'Builder Estimate'!$A:$H,5,FALSE) -> Ton | G38: =VLOOKUP(A38,'Builder Estimate'!$A:$H,8,FALSE) -> 8583625.3
A40: 12 | B40: =VLOOKUP(A40,'Builder Estimate'!A:H,2,FALSE) -> 1½" thk; 1:2:4 Cement Concrete | C40: =VLOOKUP(A40,'Builder Estimate'!A:H,3,FALSE) -> 4865.5 | D40: =VLOOKUP(A40,'Builder Estimate'!$A:$H,4,FALSE) -> 4865.5 | E40: =G40/C40 -> 1294.0025 | F40: =VLOOKUP(A40,'Builder Estimate'!$A:$H,5,FALSE) -> Sft | G40: =VLOOKUP(A40,'Builder Estimate'!$A:$H,8,FALSE) -> 6295969.4
A42: 13 | B42: =VLOOKUP(A42,'Builder Estimate'!A:H,2,FALSE) -> 9" & above Thk Brick Retaining Wall | C42: =VLOOKUP(A42,'Builder Estimate'!A:H,3,FALSE) -> 752.53906 | D42: =VLOOKUP(A42,'Builder Estimate'!$A:$H,4,FALSE) -> 752.53906 | E42: =G42/C42 -> 8301.6214 | F42: =VLOOKUP(A42,'Builder Estimate'!$A:$H,5,FALSE) -> Cft | G42: =VLOOKUP(A42,'Builder Estimate'!$A:$H,8,FALSE) -> 6247294.4
A44: 14 | B44: =VLOOKUP(A44,'Builder Estimate'!A:H,2,FALSE) -> 4½" thk; Brick Walling With 1:3 Cement Mortar | C44: =VLOOKUP(A44,'Builder Estimate'!A:H,3,FALSE) -> 6536.9306 | D44: =VLOOKUP(A44,'Builder Estimate'!$A:$H,4,FALSE) -> 6536.9306 | E44: =G44/C44 -> 3906.705 | F44: =VLOOKUP(A44,'Builder Estimate'!$A:$H,5,FALSE) -> Sft | G44: =VLOOKUP(A44,'Builder Estimate'!$A:$H,8,FALSE) -> 25537859
A46: 15 | B46: =VLOOKUP(A46,'Builder Estimate'!A:H,2,FALSE) -> 3/4" thk; 1:3 Cement Mortar Plastering Work | C46: =VLOOKUP(A46,'Builder Estimate'!A:H,3,FALSE) -> 17350.625 | D46: =VLOOKUP(A46,'Builder Estimate'!$A:$H,4,FALSE) -> 17350.625 | E46: =G46/C46 -> 1687.1545 | F46: =VLOOKUP(A46,'Builder Estimate'!$A:$H,5,FALSE) -> Sft | G46: =VLOOKUP(A46,'Builder Estimate'!$A:$H,8,FALSE) -> 29273184
A48: 16 | B48: =VLOOKUP(A48,'Builder Estimate'!A:H,2,FALSE) -> Making Door Chowket | C48: =VLOOKUP(A48,'Builder Estimate'!A:H,3,FALSE) -> 268.16667 | D48: =VLOOKUP(A48,'Builder Estimate'!$A:$H,4,FALSE) -> 268.16667 | E48: =G48/C48 -> 14056.34 | F48: =VLOOKUP(A48,'Builder Estimate'!$A:$H,5,FALSE) -> Rft | G48: =VLOOKUP(A48,'Builder Estimate'!$A:$H,8,FALSE) -> 3769441.8
A50: 17 | B50: =VLOOKUP(A50,'Builder Estimate'!A:H,2,FALSE) -> Scaffolding Works With Bamboo ,Double Layer | C50: =VLOOKUP(A50,'Builder Estimate'!A:H,3,FALSE) -> 7380 | D50: =VLOOKUP(A50,'Builder Estimate'!$A:$H,4,FALSE) -> 7380 | E50: =G50/C50 -> 746.31944 | F50: =VLOOKUP(A50,'Builder Estimate'!$A:$H,5,FALSE) -> Sft | G50: =VLOOKUP(A50,'Builder Estimate'!$A:$H,8,FALSE) -> 5507837.5
A52: 18 | B52: =VLOOKUP(A52,'Builder Estimate'!A:H,2,FALSE) -> False Work | C52: =VLOOKUP(A52,'Builder Estimate'!A:H,3,FALSE) -> 495 | D52: =VLOOKUP(A52,'Builder Estimate'!$A:$H,4,FALSE) -> 450 | E52: =G52/C52 -> 8962.963 | F52: =VLOOKUP(A52,'Builder Estimate'!$A:$H,5,FALSE) -> Nos. | G52: =VLOOKUP(A52,'Builder Estimate'!$A:$H,8,FALSE) -> 4436666.7
A54: 19 | B54: =VLOOKUP(A54,'Builder Estimate'!A:H,2,FALSE) -> Water Stopper (or) Polyswell Installation | C54: =VLOOKUP(A54,'Builder Estimate'!A:H,3,FALSE) -> 127.66667 | D54: =VLOOKUP(A54,'Builder Estimate'!$A:$H,4,FALSE) -> 127.66667 | E54: =G54/C54 -> 6800 | F54: =VLOOKUP(A54,'Builder Estimate'!$A:$H,5,FALSE) -> Rft | G54: =VLOOKUP(A54,'Builder Estimate'!$A:$H,8,FALSE) -> 868133.33
A56: 20 | B56: =VLOOKUP(A56,'Builder Estimate'!A:H,2,FALSE) -> Water Proofing Membrane with Polyfoam | C56: =VLOOKUP(A56,'Builder Estimate'!A:H,3,FALSE) -> 522.66667 | D56: =VLOOKUP(A56,'Builder Estimate'!$A:$H,4,FALSE) -> 522.66667 | E56: =G56/C56 -> 6100 | F56: =VLOOKUP(A56,'Builder Estimate'!$A:$H,5,FALSE) -> Sft | G56: =VLOOKUP(A56,'Builder Estimate'!$A:$H,8,FALSE) -> 3188266.7
B58: Total Cost | G58: =SUM(G6:G57) -> 4.0167235e+08 | H58: ='Builder Estimate'!H648 -> 4.0167235e+08 | I58: =G58-H58 -> 0
B59: Transportation Charges | F59: 0.03 | G59: =G58*F59 -> 12050171
B60: Preliminary Charges | F60: 0.05 | G60: =(G59+G58)*F60 -> 20686126
B61: Supervision Charges | F61: 0.1
B62: Grand Total Cost | G62: =SUM(G58:G61) -> 4.3440865e+08

Sheet BQ
A1: Project : Three Storeyed RCC Residential Building, Magway
A2: Work Item : Main Building ( Civil Work )
A3: Bill Of Quantity
A4: No | B4: Particular | C4: Quantity | D4: Unit | E4: Rate | F4: Per | G4: Amount
B6: Materials
A7: 1 | B7: Cement | C7: =SUMIF('Builder Estimate'!$B$6:$B$645,B7,'Builder Estimate'!$C$6:$C$645) -> 2291.2145 | D7: =VLOOKUP(B7,'Builder Estimate'!$B:$H,4,FALSE) -> Bag | E7: =VLOOKUP(B7,'Price '!B:D,3,FALSE) -> 18400 | F7: =VLOOKUP(B7,'Price '!$B:$D,2,FALSE) -> Bags | G7: =E7*C7 -> 42158346
A8: 2 | B8: Sand | C8: =SUMIF('Builder Estimate'!$B$6:$B$645,B8,'Builder Estimate'!$C$6:$C$645) -> 99.348876 | D8: =VLOOKUP(B8,'Builder Estimate'!$B:$H,4,FALSE) -> Sud | E8: =VLOOKUP(B8,'Price '!B:D,3,FALSE) -> 50000 | F8: =VLOOKUP(B8,'Price '!$B:$D,2,FALSE) -> Suds | G8: =E8*C8 -> 4967443.8
A9: 3 | B9: Aggregate | C9: =SUMIF('Builder Estimate'!$B$6:$B$645,B9,'Builder Estimate'!$C$6:$C$645) -> 86.8723 | D9: =VLOOKUP(B9,'Builder Estimate'!$B:$H,4,FALSE) -> Sud | E9: =VLOOKUP(B9,'Price '!B:D,3,FALSE) -> 130000 | F9: =VLOOKUP(B9,'Price '!$B:$D,2,FALSE) -> Suds | G9: =E9*C9 -> 11293399
A10: 4 | B10: 6" x 9" Stone | C10: =SUMIF('Builder Estimate'!$B$6:$B$645,B10,'Builder Estimate'!$C$6:$C$645) -> 10.541059 | D10: =VLOOKUP(B10,'Builder Estimate'!$B:$H,4,FALSE) -> Sud | E10: =VLOOKUP(B10,'Price '!B:D,3,FALSE) -> 220000 | F10: =VLOOKUP(B10,'Price '!$B:$D,2,FALSE) -> Suds | G10: =E10*C10 -> 2319033.1
A11: 5 | B11: Jungle Wood | C11: =SUMIF('Builder Estimate'!$B$6:$B$645,B11,'Builder Estimate'!$C$6:$C$645) -> 18.356988 | D11: =VLOOKUP(B11,'Builder Estimate'!$B:$H,4,FALSE) -> Ton | E11: =VLOOKUP(B11,'Price '!B:D,3,FALSE) -> 2500000 | F11: =VLOOKUP(B11,'Price '!$B:$D,2,FALSE) -> Ton | G11: =E11*C11 -> 45892471
A12: 6 | B12: 5-plywood | C12: =SUMIF('Builder Estimate'!$B$6:$B$645,B12,'Builder Estimate'!$C$6:$C$645) -> 157.44246 | D12: =VLOOKUP(B12,'Builder Estimate'!$B:$H,4,FALSE) -> Nos | E12: =VLOOKUP(B12,'Price '!B:D,3,FALSE) -> 75000 | F12: =VLOOKUP(B12,'Price '!$B:$D,2,FALSE) -> Sht | G12: =E12*C12 -> 11808184
A13: 7 | B13: Wire Nail | C13: =SUMIF('Builder Estimate'!$B$6:$B$645,B13,'Builder Estimate'!$C$6:$C$645) -> 261.63189 | D13: =VLOOKUP(B13,'Builder Estimate'!$B:$H,4,FALSE) -> Viss | E13: =VLOOKUP(B13,'Price '!B:D,3,FALSE) -> 12000 | F13: =VLOOKUP(B13,'Price '!$B:$D,2,FALSE) -> Viss | G13: =E13*C13 -> 3139582.7
A14: 8 | B14: Fuel | C14: =SUMIF('Builder Estimate'!$B$6:$B$645,B14,'Builder Estimate'!$C$6:$C$645) -> 136.53557 | D14: =VLOOKUP(B14,'Builder Estimate'!$B:$H,4,FALSE) -> Gal | E14: =VLOOKUP(B14,'Price '!B:D,3,FALSE) -> 20000 | F14: =VLOOKUP(B14,'Price '!$B:$D,2,FALSE) -> Gal | G14: =E14*C14 -> 2730711.4
A15: 9 | B15: Impermo | C15: =SUMIF('Builder Estimate'!$B$6:$B$645,B15,'Builder Estimate'!$C$6:$C$645) -> 66 | D15: =VLOOKUP(B15,'Builder Estimate'!$B:$H,4,FALSE) -> Bag | E15: =VLOOKUP(B15,'Price '!B:D,3,FALSE) -> 7500 | F15: =VLOOKUP(B15,'Price '!$B:$D,2,FALSE) -> Bag | G15: =E15*C15 -> 495000
A16: 10 | B16: Sikament-9 | C16: =SUMIF('Builder Estimate'!$B$6:$B$645,B16,'Builder Estimate'!$C$6:$C$645) -> 166.87408 | D16: =VLOOKUP(B16,'Builder Estimate'!$B:$H,4,FALSE) -> Lit | E16: =VLOOKUP(B16,'Price '!B:D,3,FALSE) -> 14700 | F16: =VLOOKUP(B16,'Price '!$B:$D,2,FALSE) -> Lit | G16: =E16*C16 -> 2453048.9
A17: 11 | B17: Bonding Agent | C17: =SUMIF('Builder Estimate'!$B$6:$B$645,B17,'Builder Estimate'!$C$6:$C$645) -> 165.88269 | D17: =VLOOKUP(B17,'Builder Estimate'!$B:$H,4,FALSE) -> Lit | E17: =VLOOKUP(B17,'Price '!B:D,3,FALSE) -> 14950 | F17: =VLOOKUP(B17,'Price '!$B:$D,2,FALSE) -> Lit | G17: =E17*C17 -> 2479946.2
A18: 12 | B18: Sikadur 31CF | C18: =SUMIF('Builder Estimate'!$B$6:$B$645,B18,'Builder Estimate'!$C$6:$C$645) -> 4.4 | D18: =VLOOKUP(B18,'Builder Estimate'!$B:$H,4,FALSE) -> Set | E18: =VLOOKUP(B18,'Price '!B:D,3,FALSE) -> 120000 | F18: =VLOOKUP(B18,'Price '!$B:$D,2,FALSE) -> Set | G18: =E18*C18 -> 528000
A19: 13 | B19: Ø 16mm Deform Bar | C19: ='Bill of Quantity'!C19+'Bill of Quantity'!C22+'Bill of Quantity'!C25+'Bill of Quantity'!C28 -> 19.788707 | D19: Ton | E19: =VLOOKUP(B19,'Price '!B:D,3,FALSE) -> 2420000 | F19: =D19 -> Ton | G19: =E19*C19 -> 47888671 | H19: =SUM(C19:C22) -> 37.835366
A20: 14 | B20: Ø 12mm Deform Bar | C20: ='Bill of Quantity'!C29+'Bill of Quantity'!C26+'Bill of Quantity'!C20 -> 2.1865999 | D20: Ton | E20: =VLOOKUP(B20,'Price '!B:D,3,FALSE) -> 2060000 | F20: =D20 -> Ton | G20: =E20*C20 -> 4504395.9
A21: 15 | B21: Ø 10mm Deform Bar | C21: ='Bill of Quantity'!C21+'Bill of Quantity'!C23+'Bill of Quantity'!C27+'Bill of Quantity'!C30+'Bill of Quantity'!C31 -> 14.623494 | D21: Ton | E21: =VLOOKUP(B21,'Price '!B:D,3,FALSE) -> 2450000 | F21: =D21 -> Ton | G21: =E21*C21 -> 35827561
A22: 16 | B22: Ø 6.5mm Deform Bar | C22: ='Bill of Quantity'!C32+'Bill of Quantity'!C24 -> 1.2365646 | D22: Ton | E22: =VLOOKUP(B22,'Price '!B:D,3,FALSE) -> 3430000 | F22: =D22 -> Ton | G22: =E22*C22 -> 4241416.6
A23: 17 | B23: Binding Wire | C23: =SUMIF('Builder Estimate'!$B$6:$B$645,B23,'Builder Estimate'!$C$6:$C$645) -> 720.67364 | D23: =VLOOKUP(B23,'Builder Estimate'!$B:$H,4,FALSE) -> lbs | E23: =VLOOKUP(B23,'Price '!B:D,3,FALSE) -> 12000 | F23: =VLOOKUP(B23,'Price '!$B:$D,2,FALSE) -> Lbs | G23: =E23*C23 -> 8648083.7
A24: 18 | B24: Plastic Sheet | C24: =SUMIF('Builder Estimate'!$B$6:$B$645,B24,'Builder Estimate'!$C$6:$C$645) -> 247.5 | D24: =VLOOKUP(B24,'Builder Estimate'!$B:$H,4,FALSE) -> Rft | E24: =VLOOKUP(B24,'Price '!B:D,3,FALSE) -> 1500 | F24: =VLOOKUP(B24,'Price '!$B:$D,2,FALSE) -> Rft | G24: =E24*C24 -> 371250
A25: 19 | B25: Brick( 3 Hole Brick ) | C25: =SUMIF('Builder Estimate'!$B$6:$B$645,B25,'Builder Estimate'!$C$6:$C$645) -> 50723.635 | D25: =VLOOKUP(B25,'Builder Estimate'!$B:$H,4,FALSE) -> Nos | E25: =VLOOKUP(B25,'Price '!B:D,3,FALSE) -> 285 | F25: =VLOOKUP(B25,'Price '!$B:$D,2,FALSE) -> Nos | G25: =E25*C25 -> 14456236
A26: 20 | B26: X-met (2-1/2" Wide) | C26: =SUMIF('Builder Estimate'!$B$6:$B$645,B26,'Builder Estimate'!$C$6:$C$645) -> 9096.1389 | D26: =VLOOKUP(B26,'Builder Estimate'!$B:$H,4,FALSE) -> Rft | E26: =VLOOKUP(B26,'Price '!B:D,3,FALSE) -> 170 | F26: =VLOOKUP(B26,'Price '!$B:$D,2,FALSE) -> Rft | G26: =E26*C26 -> 1546343.6
A27: 21 | B27: 5"x3" Chowket | C27: =SUMIF('Builder Estimate'!$B$6:$B$645,B27,'Builder Estimate'!$C$6:$C$645) -> 25.41 | D27: =VLOOKUP(B27,'Builder Estimate'!$B:$H,4,FALSE) -> Rft | E27: =VLOOKUP(B27,'Price '!B:D,3,FALSE) -> 14000 | F27: =VLOOKUP(B27,'Price '!$B:$D,2,FALSE) -> Rft | G27: =E27*C27 -> 355740
A28: 22 | B28: 5"x2" Chowket | C28: =SUMIF('Builder Estimate'!$B$6:$B$645,B28,'Builder Estimate'!$C$6:$C$645) -> 284.3225 | D28: =VLOOKUP(B28,'Builder Estimate'!$B:$H,4,FALSE) -> Rft | E28: =VLOOKUP(B28,'Price '!B:D,3,FALSE) -> 9500 | F28: =VLOOKUP(B28,'Price '!$B:$D,2,FALSE) -> Rft | G28: =E28*C28 -> 2701063.8
A29: 23 | B29: Chowket Bracket | C29: =SUMIF('Builder Estimate'!$B$6:$B$645,B29,'Builder Estimate'!$C$6:$C$645) -> 165 | D29: =VLOOKUP(B29,'Builder Estimate'!$B:$H,4,FALSE) -> Nos. | E29: =VLOOKUP(B29,'Price '!B:D,3,FALSE) -> 450 | F29: =VLOOKUP(B29,'Price '!$B:$D,2,FALSE) -> Nos. | G29: =E29*C29 -> 74250
A30: 24 | B30: Coal Tar | C30: =SUMIF('Builder Estimate'!$B$6:$B$645,B30,'Builder Estimate'!$C$6:$C$645) -> 11 | D30: =VLOOKUP(B30,'Builder Estimate'!$B:$H,4,FALSE) -> Bottle | E30: =VLOOKUP(B30,'Price '!B:D,3,FALSE) -> 12000 | F30: =VLOOKUP(B30,'Price '!$B:$D,2,FALSE) -> Bottle | G30: =E30*C30 -> 132000
A31: 33 | B31: Ready Made Teak Door Leaf | C31: =SUMIF('Builder Estimate'!$B$7:$B$622,$B$6:$B$67,'Builder Estimate'!$D$7:$D$622) -> 374.08333 | D31: =VLOOKUP(B31,'Builder Estimate'!$B:$H,4,FALSE) -> Sqft | E31: =VLOOKUP(B31,'Price '!B:D,3,FALSE) -> 0 | F31: =VLOOKUP(B31,'Price '!$B:$D,2,FALSE) -> Sft | G31: =E31*C31 -> 0
A32: 34 | B32: Door Lock | C32: =SUMIF('Builder Estimate'!$B$7:$B$622,$B$6:$B$67,'Builder Estimate'!$D$7:$D$622) -> 15 | D32: =VLOOKUP(B32,'Builder Estimate'!$B:$H,4,FALSE) -> Nos | E32: =VLOOKUP(B32,'Price '!B:D,3,FALSE) -> 0 | F32: =VLOOKUP(B32,'Price '!$B:$D,2,FALSE) -> Nos | G32: =E32*C32 -> 0
A33: 35 | B33: 4" Butt Hinge | C33: =SUMIF('Builder Estimate'!$B$7:$B$622,$B$6:$B$67,'Builder Estimate'!$D$7:$D$622) -> 45 | D33: =VLOOKUP(B33,'Builder Estimate'!$B:$H,4,FALSE) -> Nos | E33: =VLOOKUP(B33,'Price '!B:D,3,FALSE) -> 0 | F33: =VLOOKUP(B33,'Price '!$B:$D,2,FALSE) -> Nos | G33: =E33*C33 -> 0
A34: 36 | B34: 6" Hand Rail | C34: =SUMIF('Builder Estimate'!$B$7:$B$622,$B$6:$B$67,'Builder Estimate'!$D$7:$D$622) -> 15 | D34: =VLOOKUP(B34,'Builder Estimate'!$B:$H,4,FALSE) -> Nos | E34: =VLOOKUP(B34,'Price '!B:D,3,FALSE) -> 0 | F34: =VLOOKUP(B34,'Price '!$B:$D,2,FALSE) -> Nos | G34: =E34*C34 -> 0
A35: 37 | B35: Hook & Eye | C35: =SUMIF('Builder Estimate'!$B$7:$B$622,$B$6:$B$67,'Builder Estimate'!$D$7:$D$622) -> 15 | D35: =VLOOKUP(B35,'Builder Estimate'!$B:$H,4,FALSE) -> Nos | E35: =VLOOKUP(B35,'Price '!B:D,3,FALSE) -> 0 | F35: =VLOOKUP(B35,'Price '!$B:$D,2,FALSE) -> Nos | G35: =E35*C35 -> 0
A36: 38 | B36: Wood Screw | C36: =SUMIF('Builder Estimate'!$B$7:$B$622,$B$6:$B$67,'Builder Estimate'!$D$7:$D$622) -> 0 | D36: =VLOOKUP(B36,'Builder Estimate'!$B:$H,4,FALSE) -> Lbs | E36: =VLOOKUP(B36,'Price '!B:D,3,FALSE) -> 0 | F36: =VLOOKUP(B36,'Price '!$B:$D,2,FALSE) -> Lbs | G36: =E36*C36 -> 0
A37: 39 | B37: Aluminium & Glass | C37: =SUMIF('Builder Estimate'!$B$7:$B$622,$B$6:$B$67,'Builder Estimate'!$D$7:$D$622) -> 0 | D37: =VLOOKUP(B37,'Builder Estimate'!$B:$H,4,FALSE) -> Sft | E37: =VLOOKUP(B37,'Price '!B:D,3,FALSE) -> 0 | F37: =VLOOKUP(B37,'Price '!$B:$D,2,FALSE) -> 0 | G37: =E37*C37 -> 0
A38: 40 | B38: Emulsion Paint | C38: =SUMIF('Builder Estimate'!$B$7:$B$622,$B$6:$B$67,'Builder Estimate'!$D$7:$D$622) -> 0 | D38: =VLOOKUP(B38,'Builder Estimate'!$B:$H,4,FALSE) -> Gal | E38: =VLOOKUP(B38,'Price '!B:D,3,FALSE) -> 0 | F38: =VLOOKUP(B38,'Price '!$B:$D,2,FALSE) -> Gal | G38: =E38*C38 -> 0
A39: 41 | B39: Roller | C39: =SUMIF('Builder Estimate'!$B$7:$B$622,$B$6:$B$67,'Builder Estimate'!$D$7:$D$622) -> 0 | D39: =VLOOKUP(B39,'Builder Estimate'!$B:$H,4,FALSE) -> Nos | E39: =VLOOKUP(B39,'Price '!B:D,3,FALSE) -> 0 | F39: =VLOOKUP(B39,'Price '!$B:$D,2,FALSE) -> Nos | G39: =E39*C39 -> 0
A40: 42 | B40: Putty (Walling) | C40: =SUMIF('Builder Estimate'!$B$7:$B$622,$B$6:$B$67,'Builder Estimate'!$D$7:$D$622) -> 0 | D40: =VLOOKUP(B40,'Builder Estimate'!$B:$H,4,FALSE) -> Gal | E40: =VLOOKUP(B40,'Price '!B:D,3,FALSE) -> 0 | F40: =VLOOKUP(B40,'Price '!$B:$D,2,FALSE) -> Gal | G40: =E40*C40 -> 0
A41: 43 | B41: Sand Paper | C41: =SUMIF('Builder Estimate'!$B$7:$B$622,$B$6:$B$67,'Builder Estimate'!$D$7:$D$622) -> 0 | D41: =VLOOKUP(B41,'Builder Estimate'!$B:$H,4,FALSE) -> Dz | E41: =VLOOKUP(B41,'Price '!B:D,3,FALSE) -> 0 | F41: =VLOOKUP(B41,'Price '!$B:$D,2,FALSE) -> Doz | G41: =E41*C41 -> 0
...

Sheet Bill of Quantity
A1: Project : Three Storeyed RCC Residential Building, Magway
A2: Work Item : Main Building ( Civil Work )
A3: Bill Of Quantity
A4: No | B4: Particular | C4: Quantity | D4: Unit | E4: Rate | F4: Per | G4: Amount
B6: Materials
A7: 1 | B7: Cement | C7: =SUMIF('Builder Estimate'!$B$6:$B$645,'Bill of Quantity'!B7,'Builder Estimate'!$C$6:$C$645) -> 2291.2145 | D7: =VLOOKUP(B7,'Builder Estimate'!$B:$H,4,FALSE) -> Bag | E7: =VLOOKUP(B7,'Price '!B:D,3,FALSE) -> 18400 | F7: =VLOOKUP(B7,'Price '!$B:$D,2,FALSE) -> Bags | G7: =E7*C7 -> 42158346
A8: 2 | B8: Sand | C8: =SUMIF('Builder Estimate'!$B$6:$B$645,'Bill of Quantity'!B8,'Builder Estimate'!$C$6:$C$645) -> 99.348876 | D8: =VLOOKUP(B8,'Builder Estimate'!$B:$H,4,FALSE) -> Sud | E8: =VLOOKUP(B8,'Price '!B:D,3,FALSE) -> 50000 | F8: =VLOOKUP(B8,'Price '!$B:$D,2,FALSE) -> Suds | G8: =E8*C8 -> 4967443.8
A9: 3 | B9: Aggregate | C9: =SUMIF('Builder Estimate'!$B$6:$B$645,'Bill of Quantity'!B9,'Builder Estimate'!$C$6:$C$645) -> 86.8723 | D9: =VLOOKUP(B9,'Builder Estimate'!$B:$H,4,FALSE) -> Sud | E9: =VLOOKUP(B9,'Price '!B:D,3,FALSE) -> 130000 | F9: =VLOOKUP(B9,'Price '!$B:$D,2,FALSE) -> Suds | G9: =E9*C9 -> 11293399
A10: 4 | B10: 6" x 9" Stone | C10: =SUMIF('Builder Estimate'!$B$6:$B$645,'Bill of Quantity'!B10,'Builder Estimate'!$C$6:$C$645) -> 10.541059 | D10: =VLOOKUP(B10,'Builder Estimate'!$B:$H,4,FALSE) -> Sud | E10: =VLOOKUP(B10,'Price '!B:D,3,FALSE) -> 220000 | F10: =VLOOKUP(B10,'Price '!$B:$D,2,FALSE) -> Suds | G10: =E10*C10 -> 2319033.1
A11: 5 | B11: Jungle Wood | C11: =SUMIF('Builder Estimate'!$B$6:$B$645,'Bill of Quantity'!B11,'Builder Estimate'!$C$6:$C$645) -> 18.356988 | D11: =VLOOKUP(B11,'Builder Estimate'!$B:$H,4,FALSE) -> Ton | E11: =VLOOKUP(B11,'Price '!B:D,3,FALSE) -> 2500000 | F11: =VLOOKUP(B11,'Price '!$B:$D,2,FALSE) -> Ton | G11: =E11*C11 -> 45892471
A12: 6 | B12: 5-plywood | C12: =SUMIF('Builder Estimate'!$B$6:$B$645,'Bill of Quantity'!B12,'Builder Estimate'!$C$6:$C$645) -> 157.44246 | D12: =VLOOKUP(B12,'Builder Estimate'!$B:$H,4,FALSE) -> Nos | E12: =VLOOKUP(B12,'Price '!B:D,3,FALSE) -> 75000 | F12: =VLOOKUP(B12,'Price '!$B:$D,2,FALSE) -> Sht | G12: =E12*C12 -> 11808184
A13: 7 | B13: Wire Nail | C13: =SUMIF('Builder Estimate'!$B$6:$B$645,'Bill of Quantity'!B13,'Builder Estimate'!$C$6:$C$645) -> 261.63189 | D13: =VLOOKUP(B13,'Builder Estimate'!$B:$H,4,FALSE) -> Viss | E13: =VLOOKUP(B13,'Price '!B:D,3,FALSE) -> 12000 | F13: =VLOOKUP(B13,'Price '!$B:$D,2,FALSE) -> Viss | G13: =E13*C13 -> 3139582.7
A14: 8 | B14: Fuel | C14: =SUMIF('Builder Estimate'!$B$6:$B$645,'Bill of Quantity'!B14,'Builder Estimate'!$C$6:$C$645) -> 136.53557 | D14: =VLOOKUP(B14,'Builder Estimate'!$B:$H,4,FALSE) -> Gal | E14: =VLOOKUP(B14,'Price '!B:D,3,FALSE) -> 20000 | F14: =VLOOKUP(B14,'Price '!$B:$D,2,FALSE) -> Gal | G14: =E14*C14 -> 2730711.4
A15: 9 | B15: Impermo | C15: =SUMIF('Builder Estimate'!$B$6:$B$645,'Bill of Quantity'!B15,'Builder Estimate'!$C$6:$C$645) -> 66 | D15: =VLOOKUP(B15,'Builder Estimate'!$B:$H,4,FALSE) -> Bag | E15: =VLOOKUP(B15,'Price '!B:D,3,FALSE) -> 7500 | F15: =VLOOKUP(B15,'Price '!$B:$D,2,FALSE) -> Bag | G15: =E15*C15 -> 495000
A16: 10 | B16: Sikament-9 | C16: =SUMIF('Builder Estimate'!$B$6:$B$645,'Bill of Quantity'!B16,'Builder Estimate'!$C$6:$C$645) -> 166.87408 | D16: =VLOOKUP(B16,'Builder Estimate'!$B:$H,4,FALSE) -> Lit | E16: =VLOOKUP(B16,'Price '!B:D,3,FALSE) -> 14700 | F16: =VLOOKUP(B16,'Price '!$B:$D,2,FALSE) -> Lit | G16: =E16*C16 -> 2453048.9
A17: 11 | B17: Bonding Agent | C17: =SUMIF('Builder Estimate'!$B$6:$B$645,'Bill of Quantity'!B17,'Builder Estimate'!$C$6:$C$645) -> 165.88269 | D17: =VLOOKUP(B17,'Builder Estimate'!$B:$H,4,FALSE) -> Lit | E17: =VLOOKUP(B17,'Price '!B:D,3,FALSE) -> 14950 | F17: =VLOOKUP(B17,'Price '!$B:$D,2,FALSE) -> Lit | G17: =E17*C17 -> 2479946.2
A18: 12 | B18: Sikadur 31CF | C18: =SUMIF('Builder Estimate'!$B$6:$B$645,'Bill of Quantity'!B18,'Builder Estimate'!$C$6:$C$645) -> 4.4 | D18: =VLOOKUP(B18,'Builder Estimate'!$B:$H,4,FALSE) -> Set | E18: =VLOOKUP(B18,'Price '!B:D,3,FALSE) -> 120000 | F18: =VLOOKUP(B18,'Price '!$B:$D,2,FALSE) -> Set | G18: =E18*C18 -> 528000
A19: 13 | B19: Ø 16mm Deform Bar (Footing) | C19: =SUMIF('Builder Estimate'!$B$6:$B$645,'Bill of Quantity'!B19,'Builder Estimate'!$C$6:$C$645) -> 10.603257 | D19: =VLOOKUP(B19,'Builder Estimate'!$B:$H,4,FALSE) -> Ton | E19: =VLOOKUP(B19,'Price '!B:D,3,FALSE) -> 2420000 | F19: =D19 -> Ton | G19: =E19*C19 -> 25659881 | H19: =SUM(C19:C32) -> 37.835366
A20: 14 | B20: Ø 12mm Deform Bar (BW) | C20: =SUMIF('Builder Estimate'!$B$6:$B$645,'Bill of Quantity'!B20,'Builder Estimate'!$C$6:$C$645) -> 1.0587582 | D20: =VLOOKUP(B20,'Builder Estimate'!$B:$H,4,FALSE) -> Ton | E20: =VLOOKUP(B20,'Price '!B:D,3,FALSE) -> 2060000 | F20: =D20 -> Ton | G20: =E20*C20 -> 2181041.9
A21: 15 | B21: Ø 10mm Deform Bar (BW) | C21: =SUMIF('Builder Estimate'!$B$6:$B$645,'Bill of Quantity'!B21,'Builder Estimate'!$C$6:$C$645) -> 0.53924847 | D21: =VLOOKUP(B21,'Builder Estimate'!$B:$H,4,FALSE) -> Ton | E21: =VLOOKUP(B21,'Price '!B:D,3,FALSE) -> 2450000 | F21: =D21 -> Ton | G21: =E21*C21 -> 1321158.8
A22: 16 | B22: Ø 16mm Deform Bar (Column) | C22: =SUMIF('Builder Estimate'!$B$6:$B$645,'Bill of Quantity'!B22,'Builder Estimate'!$C$6:$C$645) -> 2.9625193 | D22: =VLOOKUP(B22,'Builder Estimate'!$B:$H,4,FALSE) -> Ton | E22: =VLOOKUP(B22,'Price '!B:D,3,FALSE) -> 2420000 | F22: =D22 -> Ton | G22: =E22*C22 -> 7169296.6
A23: 17 | B23: Ø 10mm Deform Bar (Column) | C23: =SUMIF('Builder Estimate'!$B$6:$B$645,'Bill of Quantity'!B23,'Builder Estimate'!$C$6:$C$645) -> 1.3904766 | D23: =VLOOKUP(B23,'Builder Estimate'!$B:$H,4,FALSE) -> Ton | E23: =VLOOKUP(B23,'Price '!B:D,3,FALSE) -> 2450000 | F23: =D23 -> Ton | G23: =E23*C23 -> 3406667.7
A24: 18 | B24: Ø 6.5mm Deform Bar (Column) | C24: =SUMIF('Builder Estimate'!$B$6:$B$645,'Bill of Quantity'!B24,'Builder Estimate'!$C$6:$C$645) -> 0.24636245 | D24: =VLOOKUP(B24,'Builder Estimate'!$B:$H,4,FALSE) -> Ton | E24: =VLOOKUP(B24,'Price '!B:D,3,FALSE) -> 3430000 | F24: =D24 -> Ton | G24: =E24*C24 -> 845023.21
A25: 19 | B25: Ø 16mm DF(Beam) | C25: =SUMIF('Builder Estimate'!$B$6:$B$645,'Bill of Quantity'!B25,'Builder Estimate'!$C$6:$C$645) -> 6.1093733 | D25: =VLOOKUP(B25,'Builder Estimate'!$B:$H,4,FALSE) -> Ton | E25: =VLOOKUP(B25,'Price '!B:D,3,FALSE) -> 2420000 | F25: =D25 -> Ton | G25: =E25*C25 -> 14784683
A26: 20 | B26: Ø 12mm DF(Beam) | C26: =SUMIF('Builder Estimate'!$B$6:$B$645,'Bill of Quantity'!B26,'Builder Estimate'!$C$6:$C$645) -> 0.080153574 | D26: =VLOOKUP(B26,'Builder Estimate'!$B:$H,4,FALSE) -> Ton | E26: =VLOOKUP(B26,'Price '!B:D,3,FALSE) -> 2060000 | F26: =D26 -> Ton | G26: =E26*C26 -> 165116.36
A27: 21 | B27: Ø 10mm DF(Beam) | C27: =SUMIF('Builder Estimate'!$B$6:$B$645,'Bill of Quantity'!B27,'Builder Estimate'!$C$6:$C$645) -> 2.5239924 | D27: =VLOOKUP(B27,'Builder Estimate'!$B:$H,4,FALSE) -> Ton | E27: =VLOOKUP(B27,'Price '!B:D,3,FALSE) -> 2450000 | F27: =D27 -> Ton | G27: =E27*C27 -> 6183781.4
A28: 22 | B28: Ø 16mm DF(Slab) | C28: =SUMIF('Builder Estimate'!$B$6:$B$645,'Bill of Quantity'!B28,'Builder Estimate'!$C$6:$C$645) -> 0.11355799 | D28: =VLOOKUP(B28,'Builder Estimate'!$B:$H,4,FALSE) -> Ton | E28: =VLOOKUP(B28,'Price '!B:D,3,FALSE) -> 2420000 | F28: =D28 -> Ton | G28: =E28*C28 -> 274810.32
A29: 23 | B29: Ø 12mm DF(Slab) | C29: =SUMIF('Builder Estimate'!$B$6:$B$645,'Bill of Quantity'!B29,'Builder Estimate'!$C$6:$C$645) -> 1.0476881 | D29: =VLOOKUP(B29,'Builder Estimate'!$B:$H,4,FALSE) -> Ton | E29: =VLOOKUP(B29,'Price '!B:D,3,FALSE) -> 2060000 | F29: =D29 -> Ton | G29: =E29*C29 -> 2158237.6
A30: 24 | B30: Ø 10mm DF(Slab) | C30: =SUMIF('Builder Estimate'!$B$6:$B$645,'Bill of Quantity'!B30,'Builder Estimate'!$C$6:$C$645) -> 9.0330962 | D30: =VLOOKUP(B30,'Builder Estimate'!$B:$H,4,FALSE) -> Ton | E30: =VLOOKUP(B30,'Price '!B:D,3,FALSE) -> 2450000 | F30: =D30 -> Ton | G30: =E30*C30 -> 22131086
A31: 25 | B31: Ø 10mm DF(Stiffner) | C31: =SUMIF('Builder Estimate'!$B$6:$B$645,'Bill of Quantity'!B31,'Builder Estimate'!$C$6:$C$645) -> 1.1366805 | D31: =VLOOKUP(B31,'Builder Estimate'!$B:$H,4,FALSE) -> Ton | E31: =VLOOKUP(B31,'Price '!B:D,3,FALSE) -> 2450000 | F31: =D31 -> Ton | G31: =E31*C31 -> 2784867.3
A32: 26 | B32: Ø 6.5mm DF(Stiffner) | C32: =SUMIF('Builder Estimate'!$B$6:$B$645,'Bill of Quantity'!B32,'Builder Estimate'!$C$6:$C$645) -> 0.99020216 | D32: =VLOOKUP(B32,'Builder Estimate'!$B:$H,4,FALSE) -> Ton | E32: =VLOOKUP(B32,'Price '!B:D,3,FALSE) -> 3430000 | F32: =D32 -> Ton | G32: =E32*C32 -> 3396393.4
A33: 27 | B33: Binding Wire | C33: =SUMIF('Builder Estimate'!$B$6:$B$645,'Bill of Quantity'!B33,'Builder Estimate'!$C$6:$C$645) -> 720.67364 | D33: =VLOOKUP(B33,'Builder Estimate'!$B:$H,4,FALSE) -> lbs | E33: =VLOOKUP(B33,'Price '!B:D,3,FALSE) -> 12000 | F33: =VLOOKUP(B33,'Price '!$B:$D,2,FALSE) -> Lbs | G33: =E33*C33 -> 8648083.7
A34: 28 | B34: Plastic Sheet | C34: =SUMIF('Builder Estimate'!$B$6:$B$645,'Bill of Quantity'!B34,'Builder Estimate'!$C$6:$C$645) -> 247.5 | D34: =VLOOKUP(B34,'Builder Estimate'!$B:$H,4,FALSE) -> Rft | E34: =VLOOKUP(B34,'Price '!B:D,3,FALSE) -> 1500 | F34: =VLOOKUP(B34,'Price '!$B:$D,2,FALSE) -> Rft | G34: =E34*C34 -> 371250
A35: 29 | B35: Brick( 3 Hole Brick ) | C35: =SUMIF('Builder Estimate'!$B$6:$B$645,'Bill of Quantity'!B35,'Builder Estimate'!$C$6:$C$645) -> 50723.635 | D35: =VLOOKUP(B35,'Builder Estimate'!$B:$H,4,FALSE) -> Nos | E35: =VLOOKUP(B35,'Price '!B:D,3,FALSE) -> 285 | F35: =VLOOKUP(B35,'Price '!$B:$D,2,FALSE) -> Nos | G35: =E35*C35 -> 14456236
A36: 30 | B36: X-met (2-1/2" Wide) | C36: =SUMIF('Builder Estimate'!$B$6:$B$645,'Bill of Quantity'!B36,'Builder Estimate'!$C$6:$C$645) -> 9096.1389 | D36: =VLOOKUP(B36,'Builder Estimate'!$B:$H,4,FALSE) -> Rft | E36: =VLOOKUP(B36,'Price '!B:D,3,FALSE) -> 170 | F36: =VLOOKUP(B36,'Price '!$B:$D,2,FALSE) -> Rft | G36: =E36*C36 -> 1546343.6
A37: 31 | B37: 5"x3" Chowket | C37: =SUMIF('Builder Estimate'!$B$6:$B$645,'Bill of Quantity'!B37,'Builder Estimate'!$C$6:$C$645) -> 25.41 | D37: =VLOOKUP(B37,'Builder Estimate'!$B:$H,4,FALSE) -> Rft | E37: =VLOOKUP(B37,'Price '!B:D,3,FALSE) -> 14000 | F37: =VLOOKUP(B37,'Price '!$B:$D,2,FALSE) -> Rft | G37: =E37*C37 -> 355740
A38: 32 | B38: 5"x2" Chowket | C38: =SUMIF('Builder Estimate'!$B$6:$B$645,'Bill of Quantity'!B38,'Builder Estimate'!$C$6:$C$645) -> 284.3225 | D38: =VLOOKUP(B38,'Builder Estimate'!$B:$H,4,FALSE) -> Rft | E38: =VLOOKUP(B38,'Price '!B:D,3,FALSE) -> 9500 | F38: =VLOOKUP(B38,'Price '!$B:$D,2,FALSE) -> Rft | G38: =E38*C38 -> 2701063.8
A39: 33 | B39: Chowket Bracket | C39: =SUMIF('Builder Estimate'!$B$6:$B$645,'Bill of Quantity'!B39,'Builder Estimate'!$C$6:$C$645) -> 165 | D39: =VLOOKUP(B39,'Builder Estimate'!$B:$H,4,FALSE) -> Nos. | E39: =VLOOKUP(B39,'Price '!B:D,3,FALSE) -> 450 | F39: =VLOOKUP(B39,'Price '!$B:$D,2,FALSE) -> Nos. | G39: =E39*C39 -> 74250
A40: 34 | B40: Coal Tar | C40: =SUMIF('Builder Estimate'!$B$6:$B$645,'Bill of Quantity'!B40,'Builder Estimate'!$C$6:$C$645) -> 11 | D40: =VLOOKUP(B40,'Builder Estimate'!$B:$H,4,FALSE) -> Bottle | E40: =VLOOKUP(B40,'Price '!B:D,3,FALSE) -> 12000 | F40: =VLOOKUP(B40,'Price '!$B:$D,2,FALSE) -> Bottle | G40: =E40*C40 -> 132000
A41: 33 | B41: Ready Made Teak Door Leaf | D41: =VLOOKUP(B41,'Builder Estimate'!$B:$H,4,FALSE) -> Sqft | E41: =VLOOKUP(B41,'Price '!B:D,3,FALSE) -> 0 | F41: =VLOOKUP(B41,'Price '!$B:$D,2,FALSE) -> Sft | G41: =E41*C41 -> 0
...

Sheet Builder Estimate
A1: Project : Three Storeyed RCC Residential Building, Magway
A2: Work Item : Main Building ( Civil Work )
A3: Builder's Estimate
A4: No | B4: Particular | C4: Quantity | D4: Quantity | E4: Unit | F4: Rate | G4: Per | H4: Amount
A6: 1 | B6: =VLOOKUP(A6,'Details of Measurement'!$A:$O,2,FALSE) -> Site Clearing Work | C6: =D6 -> 3246.75 | D6: =VLOOKUP(B6,'Details of Measurement'!B:N,13,FALSE) -> 3246.75 | E6: =VLOOKUP(B6,'Details of Measurement'!$B$6:$O$2333,14,FALSE) -> Sft | H6: =H10 -> 707142.15
B7: Labours
B8: Worker | C8: =D8*1.1 -> 35.71425 | D8: =D6*1/100 -> 32.4675 | E8: Nos | F8: =VLOOKUP(B8,'Price '!B:D,3,FALSE) -> 19800 | G8: =E8 -> Nos | H8: =C8*F8 -> 707142.15
G9: L | H9: =SUM(H8) -> 707142.15
G10: M+L | H10: =H9 -> 707142.15
A12: 2 | B12: =VLOOKUP(A12,'Details of Measurement'!$A:$O,2,FALSE) -> Surveying & Leveling Work | C12: =D12 -> 2206.75 | D12: =VLOOKUP(B12,'Details of Measurement'!B:N,13,FALSE) -> 2206.75 | E12: =VLOOKUP(B12,'Details of Measurement'!$B$6:$O$2333,14,FALSE) -> Sft | H12: =H23 -> 185212.53
B13: Materials
B14: Jungle Wood | C14: =D14*1.1 -> 0.036411375 | D14: =(D12/10000)*(30/(50*4)) -> 0.03310125 | E14: Ton | F14: =VLOOKUP(B14,'Price '!B:D,3,FALSE) -> 2500000 | G14: =E14 -> Ton | H14: =C14*F14 -> 91028.438
B15: Wire Nail | C15: =D15*1.1 -> 0.50571354 | D15: =(D12/10000)*7.5/3.6 -> 0.45973958 | E15: Viss | F15: =VLOOKUP(B15,'Price '!B:D,3,FALSE) -> 12000 | G15: =E15 -> Viss | H15: =C15*F15 -> 6068.5625
G17: M | H17: =SUM(H14:H15) -> 97097
B18: Labours
B19: Surveyor | C19: =D19*1.1 -> 0.2427425 | D19: =D12*1/10000 -> 0.220675 | E19: Nos | F19: =VLOOKUP(B19,'Price '!B:D,3,FALSE) -> 27500 | G19: =E19 -> Nos | H19: =C19*F19 -> 6675.4188
B20: Carpenter | C20: =D20*1.1 -> 1.2137125 | D20: =D12*5/10000 -> 1.103375 | E20: Nos | F20: =VLOOKUP(B20,'Price '!B:D,3,FALSE) -> 27500 | G20: =E20 -> Nos | H20: =C20*F20 -> 33377.094
B21: Worker | C21: =D21*1.1 -> 2.427425 | D21: =D12*10/10000 -> 2.20675 | E21: Nos | F21: =VLOOKUP(B21,'Price '!B:D,3,FALSE) -> 19800 | G21: =E21 -> Nos | H21: =C21*F21 -> 48063.015
G22: L | H22: =SUM(H19:H21) -> 88115.528
G23: M+L | H23: =H17+H22 -> 185212.53
A24: 3 | B24: =VLOOKUP(A24,'Details of Measurement'!$A:$O,2,FALSE) -> Earth Work Excavating Foundation in Ordinary Soil to a depth of 5Ft. | C24: =D24 -> 11624.031 | D24: =VLOOKUP(B24,'Details of Measurement'!B:N,13,FALSE) -> 11624.031 | E24: =VLOOKUP(B24,'Details of Measurement'!$B$6:$O$2333,14,FALSE) -> Cft | H24: =H27 -> 5063428
B25: Labours
B26: Worker | C26: =D26*1.1 -> 255.72869 | D26: =D24*2/100 -> 232.48063 | E26: Nos | F26: =VLOOKUP(B26,'Price '!B:D,3,FALSE) -> 19800 | G26: =E26 -> Nos | H26: =C26*F26 -> 5063428
G27: L | H27: =SUM(H26) -> 5063428
G28: M+L | H28: =H27 -> 5063428
A30: 4 | B30: =VLOOKUP(A30,'Details of Measurement'!$A:$O,2,FALSE) -> Plumb Concrete with (6"x9") Stone and (1:3:6)Lean Concrete | C30: =D30 -> 1375.625 | D30: =VLOOKUP(B30,'Details of Measurement'!B:N,13,FALSE) -> 1375.625 | E30: =VLOOKUP(B30,'Details of Measurement'!$B$6:$O$2333,14,FALSE) -> Cft | H30: =H39+H51 -> 7285265.3
B31: Hardcore | C31: =C30*1/3 -> 458.54167 | D31: =D30*1/3 -> 458.54167 | E31: Cft
B32: Materials
B33: 6" x 9" Stone | C33: =D33*1.1 -> 5.2961563 | D33: =D31*100/100/100*1.05 -> 4.8146875 | E33: Sud | F33: =VLOOKUP(B33,'Price '!B:D,3,FALSE) -> 220000 | G33: =E33 -> Sud | H33: =C33*F33 -> 1165154.4
G34: M | H34: =SUM(H33:H33) -> 1165154.4
B35: Labours
B36: Mason | C36: =D36*1.1 -> 7.5659375 | D36: =D30*0.5/100 -> 6.878125 | E36: Nos | F36: =VLOOKUP(B36,'Price '!B:D,3,FALSE) -> 27500 | G36: =E36 -> Nos | H36: =C36*F36 -> 208063.28
B37: Worker | C37: =D37*1.1 -> 7.5659375 | D37: =D30*0.5/100 -> 6.878125 | E37: Nos | F37: =VLOOKUP(B37,'Price '!B:D,3,FALSE) -> 19800 | G37: =E37 -> Nos | H37: =C37*F37 -> 149805.56
G38: L | H38: =SUM(H36:H37) -> 357868.84
G39: M+L | H39: =H34+H38 -> 1523023.2
B41: (1:3:6) Concrete | C41: =C30*2/3 -> 917.08333 | D41: =D30*2/3 -> 917.08333 | E41: Cft | H41: =H51 -> 5762242.1 | K41: 275.125 | L41: =D30*2/3 -> 917.08333
B42: Materials
B43: Cement | C43: =D43*1.1 -> 129.701 | D43: =ROUND(D41*1440/112/100,2) -> 117.91 | E43: Bag | F43: =VLOOKUP(B43,'Price '!B:D,3,FALSE) -> 18400 | G43: =E43 -> Bag | H43: =C43*F43 -> 2386498.4
B44: Sand | C44: =D44*1.1 -> 4.84 | D44: =ROUND(D41*48/100/100,2) -> 4.4 | E44: Sud | F44: =VLOOKUP(B44,'Price '!B:D,3,FALSE) -> 50000 | G44: =E44 -> Sud | H44: =C44*F44 -> 242000 | K44: =ROUND(K41*1440/112/100,2) -> 35.37 | L44: =ROUND(L41*1440/112/100,2) -> 117.91
B45: Aggregate | C45: =D45*1.1 -> 9.68 | D45: =ROUND(D41*96/100/100,2) -> 8.8 | E45: Sud | F45: =VLOOKUP(B45,'Price '!B:D,3,FALSE) -> 130000 | G45: =E45 -> Sud | H45: =C45*F45 -> 1258400 | K45: =ROUND(K41*48/100/100,2) -> 1.32 | L45: =ROUND(L41*48/100/100,2) -> 4.4
...

Sheet Details of Measurement
A1: Project : Three Storeyed RCC Residential Building, Magway
A2: Work Item : Main Building ( Civil Work )
A3: Detail Of Measurement
A4: No | B4: Particular | C4: Nos | F4: Measurement | L4: Deduc- | M4: Content | N4: Total | O4: Unit
F5: L(Ft-in) | H5: B(Ft) | J5: H(Ft) | L5: tion | N5: Of Each
A6: 1 | B6: Site Clearing Work | N6: =SUM(M7) -> 3246.75 | O6: Sft
B7: (a)Site Clearing | C7: 1 | D7: x | E7: 1 | F7: =35+2*10 -> 55 | G7: 6 | H7: =38+2*10 -> 58 | I7: 6 | M7: =IF(C7=0,1,C7)*IF(E7=0,1,E7)*IF((F7+G7/12)=0,1,(F7+G7/12))*IF((H7+I7/12)=0,1,(H7+I7/12))*IF((J7+K7/12)=0,1,(J7+K7/12)) -> 3246.75
A9: 2 | B9: Surveying & Leveling Work | N9: =SUM(M10) -> 2206.75 | O9: Sft
B10: (a)Surveying & Leveling | C10: 1 | D10: x | E10: 1 | F10: =35+2*5 -> 45 | G10: 6 | H10: =38+2*5 -> 48 | I10: 6 | M10: =IF(C10=0,1,C10)*IF(E10=0,1,E10)*IF((F10+G10/12)=0,1,(F10+G10/12))*IF((H10+I10/12)=0,1,(H10+I10/12))*IF((J10+K10/12)=0,1,(J10+K10/12)) -> 2206.75
A12: 3 | B12: Earth Work Excavating Foundation in Ordinary Soil to a depth of 5Ft. | N12: =SUM(N13:N22) -> 11624.031 | O12: Cft
B13: Mat Footing
B14: MF (35'-6" x 38'-6") GL 1~3 | C14: 1 | D14: x | E14: 1 | F14: 35 | G14: =6 -> 6 | H14: 25 | I14: 7 | J14: 7 | K14: 9 | M14: =IF(C14=0,1,C14)*IF(E14=0,1,E14)*IF((F14+G14/12)=0,1,(F14+G14/12))*IF((H14+I14/12)=0,1,(H14+I14/12))*IF((J14+K14/12)=0,1,(J14+K14/12)) -> 7038.6146
B15: MF (35'-6" x 38'-6") GL 3~4 | C15: 1 | D15: x | E15: 1 | F15: =F14 -> 35 | G15: =G14 -> 6 | H15: 12 | I15: 11 | J15: 10 | K15: 0 | M15: =IF(C15=0,1,C15)*IF(E15=0,1,E15)*IF((F15+G15/12)=0,1,(F15+G15/12))*IF((H15+I15/12)=0,1,(H15+I15/12))*IF((J15+K15/12)=0,1,(J15+K15/12)) -> 4585.4167
N16: =SUM(M14:M15) -> 11624.031 | O16: Cft
B17: (b) Retaining Wall
B18: X-Direction
B19: 17'-6" Span at GL- 1 | C19: 1 | D19: x | E19: 1 | F19: =17-1 -> 16 | G19: 6 | H19: 1 | I19: 8 | J19: 3 | K19: 0
B20: 16'-0" Span at GL- 1 | C20: 1 | D20: x | E20: 1 | F20: =8 -> 8 | G20: 6 | H20: =H19 -> 1 | I20: =I19 -> 8 | J20: =J19 -> 3 | K20: =K19 -> 0
N21: =SUM(M18:M20) -> 0 | O21: Cft
A23: 4 | B23: Plumb Concrete with (6"x9") Stone and (1:3:6)Lean Concrete | N23: =SUM(N24:N27) -> 1375.625 | O23: Cft
B24: Mat Footing
B25: MF (35'-6" x 38'-6") GL 3~4 | C25: =C15 -> 1 | D25: x | E25: =E15 -> 1 | F25: =F15 -> 35 | G25: =G15 -> 6 | H25: =H15 -> 12 | I25: =I15 -> 11 | J25: 3 | K25: 0 | M25: =IF(C25=0,1,C25)*IF(E25=0,1,E25)*IF((F25+G25/12)=0,1,(F25+G25/12))*IF((H25+I25/12)=0,1,(H25+I25/12))*IF((J25+K25/12)=0,1,(J25+K25/12)) -> 1375.625
E26: =SUM(E25:E25) -> 1 | N26: =SUM(M25:M25) -> 1375.625 | O26: Cft
A28: 5 | B28: Hardcore Filling Work | N28: =SUM(N29:N32) -> 454.10417 | O28: Cft
B29: Mat Footing
B30: MF (35'-6" x 38'-6") GL 1~3 | C30: =C14 -> 1 | D30: x | E30: =E14 -> 1 | F30: =F14 -> 35 | G30: =G14 -> 6 | H30: =H14 -> 25 | I30: =I14 -> 7 | J30: 0 | K30: 6 | M30: =IF(C30=0,1,C30)*IF(E30=0,1,E30)*IF((F30+G30/12)=0,1,(F30+G30/12))*IF((H30+I30/12)=0,1,(H30+I30/12))*IF((J30+K30/12)=0,1,(J30+K30/12)) -> 454.10417
E31: =SUM(E30:E30) -> 1 | N31: =SUM(M30:M30) -> 454.10417 | O31: Cft
A33: 6 | B33: 1:3:6 Lean Concrete Laying Work | N33: =SUM(N34:N64) -> 779.45833 | O33: Cft
B34: (a)Footing (3" Thk Lean)
B35: MF (35'-6" x 38'-6") GL 1~3 | C35: =C14 -> 1 | D35: x | E35: =E14 -> 1 | F35: =F14 -> 35 | G35: =G14 -> 6 | H35: =H14 -> 25 | I35: =I14 -> 7 | J35: 0 | K35: 3 | M35: =IF(C35=0,1,C35)*IF(E35=0,1,E35)*IF((F35+G35/12)=0,1,(F35+G35/12))*IF((H35+I35/12)=0,1,(H35+I35/12))*IF((J35+K35/12)=0,1,(J35+K35/12)) -> 227.05208
N36: =SUM(M35:M35) -> 227.05208 | O36: Cft
B37: (b) Retaining Wall (6" Thk Lean)
B38: X-Direction
B39: 17'-6" Span at GL- 1&4 | C39: 1 | D39: x | E39: 2 | F39: =17-1 -> 16 | G39: 0 | H39: =H19 -> 1 | I39: =I19 -> 8 | J39: =0 -> 0 | K39: 6 | M39: =IF(C39=0,1,C39)*IF(E39=0,1,E39)*IF((F39+G39/12)=0,1,(F39+G39/12))*IF((H39+I39/12)=0,1,(H39+I39/12))*IF((J39+K39/12)=0,1,(J39+K39/12)) -> 26.666667 | P39: =17.5-1.5*1 -> 16
B40: 16'-0" Span at GL- 1&4 | C40: 1 | D40: x | E40: 2 | F40: 14 | G40: 6 | H40: =H39 -> 1 | I40: =I39 -> 8 | J40: =J39 -> 0 | K40: =K39 -> 6 | M40: =IF(C40=0,1,C40)*IF(E40=0,1,E40)*IF((F40+G40/12)=0,1,(F40+G40/12))*IF((H40+I40/12)=0,1,(H40+I40/12))*IF((J40+K40/12)=0,1,(J40+K40/12)) -> 24.166667 | P40: =16-1.5 -> 14.5
B41: 11'-0" Span betw; GL- 1&2 | C41: =1 -> 1 | D41: x | E41: 1 | F41: 11 | G41: 0 | H41: =H40 -> 1 | I41: =I40 -> 8 | J41: =J40 -> 0 | K41: =K40 -> 6 | M41: =IF(C41=0,1,C41)*IF(E41=0,1,E41)*IF((F41+G41/12)=0,1,(F41+G41/12))*IF((H41+I41/12)=0,1,(H41+I41/12))*IF((J41+K41/12)=0,1,(J41+K41/12)) -> 9.1666667
B42: 17'-6" Span at GL- 2&3 | C42: 1 | D42: x | E42: 2 | F42: 15 | G42: 9 | H42: =H41 -> 1 | I42: =I41 -> 8 | J42: =J41 -> 0 | K42: =K41 -> 6 | M42: =IF(C42=0,1,C42)*IF(E42=0,1,E42)*IF((F42+G42/12)=0,1,(F42+G42/12))*IF((H42+I42/12)=0,1,(H42+I42/12))*IF((J42+K42/12)=0,1,(J42+K42/12)) -> 26.25 | P42: =17.5-1*1.17-0.5*1.17 -> 15.745
B43: 16'-0" Span at GL- 2&3 | C43: 1 | D43: x | E43: 2 | F43: 14 | G43: 5 | H43: =H42 -> 1 | I43: =I42 -> 8 | J43: =J42 -> 0 | K43: =K42 -> 6 | M43: =IF(C43=0,1,C43)*IF(E43=0,1,E43)*IF((F43+G43/12)=0,1,(F43+G43/12))*IF((H43+I43/12)=0,1,(H43+I43/12))*IF((J43+K43/12)=0,1,(J43+K43/12)) -> 24.027778 | P43: =16-1*1-0.5*1.17 -> 14.415
B44: 7'-11" Span betw; GL- 2&3 | C44: 1 | D44: x | E44: 1 | F44: 7 | G44: 11 | H44: =H43 -> 1 | I44: =I43 -> 8 | J44: =J43 -> 0 | K44: =K43 -> 6 | M44: =IF(C44=0,1,C44)*IF(E44=0,1,E44)*IF((F44+G44/12)=0,1,(F44+G44/12))*IF((H44+I44/12)=0,1,(H44+I44/12))*IF((J44+K44/12)=0,1,(J44+K44/12)) -> 6.5972222
E45: =C39*E39+C41*E41+C42*E42+C43*E43+C44*E44+C40*E40 -> 10
...

Sheet Price 
A2: 1 | B2: Cement | C2: Bags | D2: 18400
A3: 2 | B3: Sand | C3: Suds | D3: 50000 | H3: 12000
A4: 3 | B4: Aggregate | C4: Suds | D4: 130000 | H4: 70000
A5: 4 | B5: 6" x 9" Stone | C5: Suds | D5: 220000
A6: 5 | B6: Fuel | C6: Gal | D6: 20000
A7: 6 | B7: Impermo | C7: Bag | D7: 7500
A8: 7 | B8: Sikament-9 | C8: Lit | D8: 14700
A9: 8 | B9: Bonding Agent | C9: Lit | D9: 14950
A10: 9 | B10: Sikadur 31CF | C10: Set | D10: 120000
A11: 10 | B11: Jungle Wood | C11: Ton | D11: 2500000 | H11: 650000
B12: T-Post (3"x 2") Jungle Wood | C12: Ton | D12: 1500000
A13: 11 | B13: 5-plywood | C13: Sht | D13: 75000
A14: 12 | B14: Wire Nail | C14: Viss | D14: 12000
A15: 13 | B15: Ø 16mm Deform Bar | C15: Ton | D15: 2420000 | H15: =460000*1.05 -> 483000
A16: 14 | B16: Ø 12mm Deform Bar | C16: Ton | D16: 2060000 | H16: =480000*1.05 -> 504000
A17: 15 | B17: Ø 10mm Deform Bar | C17: Ton | D17: 2450000
A18: 16 | B18: Ø 6.5mm Deform Bar | C18: Ton | D18: 3430000
A19: 17 | B19: Binding Wire | C19: Lbs | D19: 12000
A20: 18 | B20: Brick( 3 Hole Brick ) | C20: Nos | D20: 285
A21: 19 | B21: X-met (2-1/2" Wide) | C21: Rft | D21: 170
A22: 20 | B22: Pyingadoo Wood | C22: Ton | D22: =D12 -> 1500000
A23: 21 | B23: 5"x3" Chowket | C23: Rft | D23: 14000
A24: 22 | B24: 5"x2" Chowket | C24: Rft | D24: 9500
A25: 23 | B25: Chowket Bracket | C25: Nos. | D25: 450
A26: 24 | B26: Coal Tar | C26: Bottle | D26: 12000 | I26: Labour
A27: 25 | B27: Ready Made Teak Door Leaf (1½" Thk) | C27: Sft | I27: 1976
A28: 26 | B28: Ready Made Teak Door Leaf | C28: Sft | I28: 1271
A29: 27 | B29: Door Lock | C29: Nos
A30: 28 | B30: 4" Butt Hinge | C30: Nos | K30: =5000/6.24 -> 801.28205 | M30: =12*12*8 -> 1152
A31: 29 | B31: 6" Hand Rail | C31: Nos | M31: =12*12*6 -> 864
A32: 30 | B32: 6" Towel Bolt | C32: Nos
A33: 31 | B33: Hook & Eye | C33: Nos
A34: 32 | B34: Wood Screw | C34: Lbs
A35: 33 | B35: Fully Glass Panel | C35: Sft
A36: 34 | B36: PVC Window (Thailand) | C36: Sft
A37: 35 | B37: Emulsion Paint | C37: Gal | I37: =25700/5 -> 5140
A38: 36 | B38: Roller | C38: Nos
A39: 37 | B39: Putty (Walling) | C39: Gal
A40: 37 | B40: Sand Paper | C40: Doz
A41: 38 | B41: Putty Trowel | C41: Nos
...

Sheet Summary(Apron)
A1: Project : ရန္ကုန္တိုင္းေဒသႀကီးအစိုးရအဖြဲ႔၊ ရန္ကုန္ၿမိဳ႕ေတာ္စည္ပင္သာယာေရးေကာ္မတီ။
A2: Subject : ဒလၿမိဳ႕နယ္တြင္ (၁၅၀'-၀" x ၇၄'-၀") ၂ထပ္ RCC ၿမိဳ႕နယ္ခန္းမ (၁) ေဆာင္ တည္ေဆာက္ျခင္းလုပ္ငန္း။
A3: Tender No. : Lot (1)
A4: Work Item : Apron & Drain
A5: Summary of Cost
A6: Item | B6: Particular | C6: Material Cost (Kyats) | D6: Labour Cost (Kyats) | E6: Total (Kyats)
A8: 1 | B8: Apron & Drain Work | C8: ='BQ-Apron & Drain'!$G$16 -> #N/A | D8: ='BQ-Apron & Drain'!$G$25 -> 8927135 | E8: =C8+D8 -> #N/A
B11: Grand Total (M+L) | E11: =SUM(E8:E10) -> #N/A
B14: Scope Of Work
B15: Earthwork Excavation
B16: 3" Thk; Sand Filling Work
B17: 3" Thk; (1:3:6) Lean Concrete Work
B18: Brick Work with (1:3) Cement Mortar
B19: Plastering Work with (1:3) Cement Mortar

Sheet AC-Apron & Drain
A1: Project : ရန္ကုန္တိုင္းေဒသႀကီးအစိုးရအဖြဲ႔၊ ရန္ကုန္ၿမိဳ႕ေတာ္စည္ပင္သာယာေရးေကာ္မတီ။
A2: Subject : ဒလၿမိဳ႕နယ္တြင္ (၁၅၀'-၀" x ၇၄'-၀") ၂ထပ္ RCC ၿမိဳ႕နယ္ခန္းမ (၁) ေဆာင္ တည္ေဆာက္ျခင္းလုပ္ငန္း။
A3: Tender No. : Lot (1)
A4: Work Item : Apron & Drain
A5: Abstract of Cost
A6: Sr No | B6: Particular | C6: Quantity | D6: Unit | E6: Rate | F6: Per | G6: Amount
C7: Total | G7: Kyats
A8: 1 | B8: =VLOOKUP(A8,'BE-Apron & Drain'!A:G,2,FALSE) -> Earth Work in Excavation for foundation in Ordinary soil to a depth of (5)ft . | C8: =VLOOKUP(A8,'BE-Apron & Drain'!A:G,3,FALSE) -> 1713.75 | D8: =VLOOKUP(A8,'BE-Apron & Drain'!A:G,4,FALSE) -> Cft | E8: =G8/C8 -> 297 | F8: =D8 -> Cft | G8: =VLOOKUP(A8,'BE-Apron & Drain'!A:G,7,FALSE) -> 508983.75
A10: 2 | B10: =VLOOKUP(A10,'BE-Apron & Drain'!A:G,2,FALSE) -> Sand Filling Work | C10: =VLOOKUP(A10,'BE-Apron & Drain'!A:G,3,FALSE) -> 214.21875 | D10: =VLOOKUP(A10,'BE-Apron & Drain'!A:G,4,FALSE) -> Cft | E10: =G10/C10 -> 823 | F10: =D10 -> Cft | G10: =VLOOKUP(A10,'BE-Apron & Drain'!A:G,7,FALSE) -> 176302.03
A12: 3 | B12: =VLOOKUP(A12,'BE-Apron & Drain'!A:G,2,FALSE) -> 1:3:6 Lean Concrete Work | C12: =VLOOKUP(A12,'BE-Apron & Drain'!A:G,3,FALSE) -> 620.91146 | D12: =VLOOKUP(A12,'BE-Apron & Drain'!A:G,4,FALSE) -> Cft | E12: =G12/C12 -> 5712.7143 | F12: =D12 -> Cft | G12: =VLOOKUP(A12,'BE-Apron & Drain'!A:G,7,FALSE) -> 3547089.8
A14: 4 | B14: =VLOOKUP(A14,'BE-Apron & Drain'!A:G,2,FALSE) -> 4-1/2" Thk; Brick Walling In Cement Mortar (1:3) Reinforced At Every 4th Course . | C14: =VLOOKUP(A14,'BE-Apron & Drain'!A:G,3,FALSE) -> 2285 | D14: =VLOOKUP(A14,'BE-Apron & Drain'!A:G,4,FALSE) -> Sft | E14: =G14/C14 -> #N/A | F14: =D14 -> Sft | G14: =VLOOKUP(A14,'BE-Apron & Drain'!A:G,7,FALSE) -> #N/A
A16: 5 | B16: =VLOOKUP(A16,'BE-Apron & Drain'!A:G,2,FALSE) -> 1/2" tk: Plastering Work with (1:3) Cement Mortar . | C16: =VLOOKUP(A16,'BE-Apron & Drain'!A:G,3,FALSE) -> 6866.5 | D16: =VLOOKUP(A16,'BE-Apron & Drain'!A:G,4,FALSE) -> Sft | E16: =G16/C16 -> 942.42857 | F16: =D16 -> Sft | G16: =VLOOKUP(A16,'BE-Apron & Drain'!A:G,7,FALSE) -> 6471185.8
B19: Total Material + Labour Cost | G19: =SUM(G8:G18) -> #N/A

Sheet BQ-Apron & Drain
A1: Project : ရန္ကုန္တိုင္းေဒသႀကီးအစိုးရအဖြဲ႔၊ ရန္ကုန္ၿမိဳ႕ေတာ္စည္ပင္သာယာေရးေကာ္မတီ။
A2: Subject : ဒလၿမိဳ႕နယ္တြင္ (၁၅၀'-၀" x ၇၄'-၀") ၂ထပ္ RCC ၿမိဳ႕နယ္ခန္းမ (၁) ေဆာင္ တည္ေဆာက္ျခင္းလုပ္ငန္း။
A3: Tender No. : Lot (1)
A4: Work Item : Apron & Drain
A5: Bill of Quantity
A6: Sr No | B6: Particular | C6: Quantity | D6: Unit | E6: Rate | F6: Per | G6: Amount
G7: Kyats
B8: Material Cost
A9: 1 | B9: Cement | C9: =SUMIFS('BE-Apron & Drain'!C:C,'BE-Apron & Drain'!B:B,'BQ-Apron & Drain'!B9) -> 243.19978 | D9: =VLOOKUP(B9,'BE-Apron & Drain'!B:G,3,FALSE) -> Bag | E9: =VLOOKUP(B9,'Price '!$B:$E,3,FALSE) -> 18400 | F9: =D9 -> Bag | G9: =C9*E9 -> 4474875.9
A10: 2 | B10: Sand | C10: =SUMIFS('BE-Apron & Drain'!C:C,'BE-Apron & Drain'!B:B,'BQ-Apron & Drain'!B10) -> 11.376359 | D10: =VLOOKUP(B10,'BE-Apron & Drain'!B:G,3,FALSE) -> Sud | E10: =VLOOKUP(B10,'Price '!$B:$E,3,FALSE) -> 50000 | F10: =D10 -> Sud | G10: =C10*E10 -> 568817.97
A11: 3 | B11: Aggregate | C11: =SUMIFS('BE-Apron & Drain'!C:C,'BE-Apron & Drain'!B:B,'BQ-Apron & Drain'!B11) -> 5.96075 | D11: =VLOOKUP(B11,'BE-Apron & Drain'!B:G,3,FALSE) -> Sud | E11: =VLOOKUP(B11,'Price '!$B:$E,3,FALSE) -> 130000 | F11: =D11 -> Sud | G11: =C11*E11 -> 774897.5
A12: 4 | B12: Brick( 10 Hole Brick ) | C12: =SUMIFS('BE-Apron & Drain'!C:C,'BE-Apron & Drain'!B:B,'BQ-Apron & Drain'!B12) -> 12567.5 | D12: =VLOOKUP(B12,'BE-Apron & Drain'!B:G,3,FALSE) -> Nos | E12: =VLOOKUP(B12,'Price '!$B:$E,3,FALSE) -> #N/A | F12: =D12 -> Nos | G12: =C12*E12 -> #N/A
A13: 5 | B13: X-met (2-1/2" Wide) | C13: =SUMIFS('BE-Apron & Drain'!C:C,'BE-Apron & Drain'!B:B,'BQ-Apron & Drain'!B13) -> 2627.75 | D13: =VLOOKUP(B13,'BE-Apron & Drain'!B:G,3,FALSE) -> Rft | E13: =VLOOKUP(B13,'Price '!$B:$E,3,FALSE) -> 170 | F13: =D13 -> Rft | G13: =C13*E13 -> 446717.5
C16: Total Material Cost | G16: =SUM(G9:G15) -> #N/A
H18: =G16+G25 -> #N/A
H19: ='BE-Apron & Drain'!G47 -> #N/A
B20: Labour Cost
A21: 1 | B21: Mason | C21: =SUMIFS('BE-Apron & Drain'!C:C,'BE-Apron & Drain'!B:B,'BQ-Apron & Drain'!B21) -> 120.57411 | D21: =VLOOKUP(B21,'BE-Apron & Drain'!B:G,3,FALSE) -> Nos | E21: =VLOOKUP(B21,'Price '!$B:$E,3,FALSE) -> 27500 | F21: =D21 -> Nos | G21: =C21*E21 -> 3315788.2
A22: 2 | B22: Worker | C22: =SUMIFS('BE-Apron & Drain'!C:C,'BE-Apron & Drain'!B:B,'BQ-Apron & Drain'!B22) -> 283.40135 | D22: =VLOOKUP(B22,'BE-Apron & Drain'!B:G,3,FALSE) -> Nos | E22: =VLOOKUP(B22,'Price '!$B:$E,3,FALSE) -> 19800 | F22: =D22 -> Nos | G22: =C22*E22 -> 5611346.8
C25: Total Labour Cost | G25: =SUM(G20:G24) -> 8927135

Sheet BE-Apron & Drain
A1: Project : ရန္ကုန္တိုင္းေဒသႀကီးအစိုးရအဖြဲ႔၊ ရန္ကုန္ၿမိဳ႕ေတာ္စည္ပင္သာယာေရးေကာ္မတီ။
A2: Subject : ဒလၿမိဳ႕နယ္တြင္ (၁၅၀'-၀" x ၇၄'-၀") ၂ထပ္ RCC ၿမိဳ႕နယ္ခန္းမ (၁) ေဆာင္ တည္ေဆာက္ျခင္းလုပ္ငန္း။
A3: Tender No. : Lot (1)
A4: Work Item : Apron & Drain
A5: Builder's Estimate
A6: Sr No | B6: Particular | C6: Quantity | D6: Unit | E6: Rate | F6: Per | G6: Amount
G7: ( Kyats )
A8: 1 | B8: =VLOOKUP(A8,'Measurement-Apron & Drain'!A:O,2,FALSE) -> Earth Work in Excavation for foundation in Ordinary soil to a depth of (5)ft . | C8: =VLOOKUP(A8,'Measurement-Apron & Drain'!A:O,14,FALSE) -> 1713.75 | D8: =VLOOKUP(B8,'Measurement-Apron & Drain'!B:P,14,FALSE) -> Cft | G8: =SUM(G10) -> 508983.75 | I8: =G8 -> 508983.75
B9: Labour
B10: Worker | C10: =C8*1.5/100 -> 25.70625 | D10: Nos | E10: =VLOOKUP(B10,'Price '!$B:$F,3,FALSE) -> 19800 | F10: =D10 -> Nos | G10: =C10*E10 -> 508983.75
A12: 2 | B12: =VLOOKUP(A12,'Measurement-Apron & Drain'!A:O,2,FALSE) -> Sand Filling Work | C12: =VLOOKUP(A12,'Measurement-Apron & Drain'!A:O,14,FALSE) -> 214.21875 | D12: =VLOOKUP(B12,'Measurement-Apron & Drain'!B:P,14,FALSE) -> Cft | G12: =SUM(G14:G16) -> 176302.03 | H12: =SUM(G14:G14) -> 133886.72 | I12: =SUM(G16:G16) -> 42415.312
B13: Material
B14: Sand | C14: =C12*125/100/100 -> 2.6777344 | D14: Sud | E14: =VLOOKUP(B14,'Price '!$B:$F,3,FALSE) -> 50000 | F14: =D14 -> Sud | G14: =C14*E14 -> 133886.72
B15: Labour
B16: Worker | C16: =C12*1/100 -> 2.1421875 | D16: Nos | E16: =VLOOKUP(B16,'Price '!$B:$F,3,FALSE) -> 19800 | F16: =D16 -> Nos | G16: =C16*E16 -> 42415.312
A19: 3 | B19: =VLOOKUP(A19,'Measurement-Apron & Drain'!A:O,2,FALSE) -> 1:3:6 Lean Concrete Work | C19: =VLOOKUP(A19,'Measurement-Apron & Drain'!A:O,14,FALSE) -> 620.91146 | D19: =VLOOKUP(B19,'Measurement-Apron & Drain'!B:P,14,FALSE) -> Cft | G19: =SUM(G21:G26) -> 3547089.8 | H19: =SUM(G21:G23) -> 2392815.4 | I19: =SUM(G25:G26) -> 1154274.4
B20: Material
B21: Cement | C21: =1440*C19/100/112 -> 79.831473 | D21: Bag | E21: =VLOOKUP(B21,'Price '!$B:$F,3,FALSE) -> 18400 | F21: =D21 -> Bag | G21: =C21*E21 -> 1468899.1
B22: Sand | C22: =48*C19/100/100 -> 2.980375 | D22: Sud | E22: =VLOOKUP(B22,'Price '!$B:$F,3,FALSE) -> 50000 | F22: =D22 -> Sud | G22: =C22*E22 -> 149018.75
B23: Aggregate | C23: =96*C19/100/100 -> 5.96075 | D23: Sud | E23: =VLOOKUP(B23,'Price '!$B:$F,3,FALSE) -> 130000 | F23: =D23 -> Sud | G23: =C23*E23 -> 774897.5
B24: Labour
B25: Mason | C25: =1*C19/100 -> 6.2091146 | D25: Nos | E25: =VLOOKUP(B25,'Price '!$B:$F,3,FALSE) -> 27500 | F25: =D25 -> Nos | G25: =C25*E25 -> 170750.65
B26: Worker | C26: =8*C19/100 -> 49.672917 | D26: Nos | E26: =VLOOKUP(B26,'Price '!$B:$F,3,FALSE) -> 19800 | F26: =D26 -> Nos | G26: =C26*E26 -> 983523.75
A29: 4 | B29: =VLOOKUP(A29,'Measurement-Apron & Drain'!A:O,2,FALSE) -> 4-1/2" Thk; Brick Walling In Cement Mortar (1:3) Reinforced At Every 4th Course . | C29: =VLOOKUP(A29,'Measurement-Apron & Drain'!A:O,14,FALSE) -> 2285 | D29: =VLOOKUP(B29,'Measurement-Apron & Drain'!B:P,14,FALSE) -> Sft | G29: =SUM(G31:G37) -> #N/A | H29: =SUM(G31:G34) -> #N/A | I29: =SUM(G36:G37) -> 2614040
B30: Material
B31: Cement | C31: =350*C29/100/112 -> 71.40625 | D31: Bag | E31: =VLOOKUP(B31,'Price '!$B:$F,3,FALSE) -> 18400 | F31: =D31 -> Bag | G31: =C31*E31 -> 1313875
B32: Sand | C32: =10*C29/100/100 -> 2.285 | D32: Sud | E32: =VLOOKUP(B32,'Price '!$B:$F,3,FALSE) -> 50000 | F32: =D32 -> Sud | G32: =C32*E32 -> 114250
B33: Brick( 10 Hole Brick ) | C33: =550*C29/100 -> 12567.5 | D33: Nos | E33: =VLOOKUP(B33,'Price '!$B:$F,3,FALSE) -> #N/A | F33: =D33 -> Nos | G33: =C33*E33 -> #N/A
B34: X-met (2-1/2" Wide) | C34: =115*C29/100 -> 2627.75 | D34: Rft | E34: =VLOOKUP(B34,'Price '!$B:$F,3,FALSE) -> 170 | F34: =D34 -> Rft | G34: =C34*E34 -> 446717.5
B35: Labour
B36: Mason | C36: =2*C29/100 -> 45.7 | D36: Nos | E36: =VLOOKUP(B36,'Price '!$B:$F,3,FALSE) -> 27500 | F36: =D36 -> Nos | G36: =C36*E36 -> 1256750
B37: Worker | C37: =3*C29/100 -> 68.55 | D37: Nos | E37: =VLOOKUP(B37,'Price '!$B:$F,3,FALSE) -> 19800 | F37: =D37 -> Nos | G37: =C37*E37 -> 1357290
A39: 5 | B39: =VLOOKUP(A39,'Measurement-Apron & Drain'!A:O,2,FALSE) -> 1/2" tk: Plastering Work with (1:3) Cement Mortar . | C39: =VLOOKUP(A39,'Measurement-Apron & Drain'!A:O,14,FALSE) -> 6866.5 | D39: =VLOOKUP(B39,'Measurement-Apron & Drain'!B:P,14,FALSE) -> Sft | G39: =SUM(G41:G45) -> 6471185.8 | H39: =SUM(G41:G42) -> 1863764.3 | I39: =SUM(G44:G45) -> 4607421.5
B40: Material
B41: Cement | C41: =C39*150/100/112 -> 91.962054 | D41: Bag | E41: =VLOOKUP(B41,'Price '!$B:$F,3,FALSE) -> 18400 | F41: =D41 -> Bag | G41: =C41*E41 -> 1692101.8
