Workbook

Sheet Rate
A1: Material | B1: Unit | C1: Rate
A2: Cement | B2: Bag | C2: 25000
A3: R/Sand | B3: Sud | C3: 50000
A4: R/Sand for Backfill | B4: Sud | C4: 50000
A5: Brick | B5: No | C5: 500
A6: R/Shingle | B6: Sud | C6: 130000
A7: Hard Core | B7: Sud | C7: 220000
A8: Fuel | B8: Gal | C8: 20000
A9: Bonding Agent | B9: Lit | C9: 25000
A10: Sikament-9 | B10: Lit | C10: 7000
A11: T-Rental Charges | B11: No | C11: =(14+14+7)*250 -> 8750
A12: 5 Ply Wood (8' x 4') | B12: Sht | C12: 75000
A13: Jungle Wood | B13: Ton | C13: 1500000
A14: Concrete Nail | B14: Box | C14: 10000
A15: Wire Nail | B15: Lb | C15: =12000/3.6 -> 3333
A16: M.S Rod
A17: 6.5 mm Ø M.S Rod | B17: Ton | C17: 2800000
A18: 8 mm Ø M.S Rod | B18: Ton | C18: 2700000
A19: 10 mm Ø Re bar | B19: Ton | C19: 3100000
A20: 12 mm Ø Re bar | B20: Ton | C20: 2550000
A21: 16 mm Ø Re bar | B21: Ton | C21: 2980000
B22: Ton
A23: Binding Wire | B23: Lb | C23: =12000/3.6 -> 3333
A24: 5"x2" Chowket | B24: Ft | C24: 12000
A25: Coal Tar | B25: Gal | C25: 12000
A26: X-Met | B26: Fr | C26: 170
A27: Plastic Sheet (3' wide) | B27: Yard | C27: 5000
A28: Bamboo | B28: No | C28: 2000
A29: Coin Yarn | B29: Viss | C29: 15000
A30: Broken Brick | B30: Sud | C30: 40000
A31: GI (1' 6" x 1' 6") Manhole Cover | B31: No | C31: 30000
A32: 4" Ø GI Vent Pipe | B32: No | C32: 12000
A33: 4" Ø PVC Outlet Pipe (T) | B33: No | C33: 15000
A34: 4" Ø PVC Inlet Pipe (T) | B34: No | C34: 15000
A37: Mason | B37: No | C37: 27000
A38: Operator | B38: No | C38: =C37 -> 27000
A39: Worker | B39: No | C39: 20000
A40: Worker (Dismantling) | B40: No | C40: =C39 -> 20000
A41: Steel Fixer | B41: No | C41: =C37 -> 27000
A42: Carpenter | B42: No | C42: =C37 -> 27000
...

Sheet Floor Area
A1: =SUM!A1 -> U MYO MIN AUNG (KAN NAR LANN, MAGWAY)
A2: =SUM!A2 -> 27'x40' - 2.5 STOREYED RCC BUILDING
A3: Item | B3: Particular | C3: Qty | D3: L | E3: B | G3: Content | H3: Unit
A4: 1 | B4: Ground Floor | C4: 1 | D4: 27 | E4: 40 | G4: =C4*D4*E4 -> 1080 | H4: Fs
A5: 2 | B5: 1st Floor | C5: 1 | D5: 27 | E5: 40 | G5: =C5*D5*E5 -> 1080 | H5: Fs
C6: 1 | D6: 27 | E6: 3 | G6: =C6*D6*E6 -> 81 | H6: Fs
C7: 1 | D7: 3 | E7: 11.5 | G7: =C7*D7*E7 -> 34.5 | H7: Fs
A8: 3 | B8: Roof Floor | C8: 1 | D8: 27 | E8: 43 | G8: =C8*D8*E8 -> 1161 | H8: Fs
C9: 1 | D9: 3 | E9: 14.5 | G9: =C9*D9*E9 -> 43.5 | H9: Fs
A10: 4 | B10: Top Roof | C10: 1 | D10: 17.5 | E10: 28.5 | F10: 0.5 | G10: =ROUND(C10*D10*E10*F10,1) -> 249.4 | H10: Fs
B11: Total Floor Area | G11: =SUM(G4:G10) -> 3729.4 | H11: Fs
B14: SUM YB | C14: ='BQ-YB'!G63 -> 356040000
B15: PAE | C15: =C14/G11 -> 95468.44

Sheet SUM
A1: =Detail!A1 -> U MYO MIN AUNG (KAN NAR LANN, MAGWAY)
A2: 27'x40' - 2.5 STOREYED RCC BUILDING
A3: Summary
A4: Item | B4: Description | C4: Amount | D4: Remark
A5: 1 | B5: - Material Cost | C5: ='BQ-YB'!G36 -> 2.0804477e+08 | D5: အုတ္စီ၊ ေခ်ာ၊ က်ည္းေဘာင္ေထာင္ျခင္း
A6: 2 | B6: - Labour Cost | C6: ='BQ-YB'!G47 -> 84491740 | D6: အထပ္သား၊ သစ္-3 Times used
A7: 3 | B7: - Mechinary Charges For Excavation & Earth Removal | C7: ='BQ-YB'!G52 -> 4382400 | D7: April, 2026 ေစ်းႏႈန္းအရျဖစ္ပါသည္
A8: 4 | B8: - Mechinary Charges For RC Conc; Work | C8: ='BQ-YB'!G57 -> 5400000 | D8: တည္ေဆာက္မည့္အခ်ိန္ကာလေစ်းႏႈန္းေပၚမူတည္ၿပီး
D9: ေငြ Amount အေျပာင္းအလဲရွိႏိုင္ပါသည္
B10: Total | C10: =SUM(C5:C8) -> 3.0231891e+08
A11: 5 | B11: - Transportation Cost (3% of Material) | C11: =C5*0.03 -> 6241343
A12: 6 | B12: - Preliminary Cost (2% of Total) | C12: =C10*0.05 -> 15115945
A13: 8 | B13: - Supervision Charges (10% of Toal) | C13: =C10*0.1 -> 30231891
B15: Total Amount | C15: =SUM(C10:C14) -> 3.5390808e+08
A16: Say | C16: =ROUND(C15,-4) -> 353910000
B18: Floor Area | C18: ='Floor Area'!G11 -> 3729.4
B19: PAE | C19: =C16/C18 -> 94897

Sheet Summary
A1: ='BQ-YB'!A1:G1 -> U MYO MIN AUNG (KAN NAR LANN, MAGWAY)
A2: ='BQ-YB'!A2:G2 -> 27' X 40' 2.5 STOREYED BUILDING (Structure Work)
A3: Total Summary
A4: No | B4: Particular | C4: Amount | D4: Remark
A5: 1 | B5: Material Cost | C5: ='BQ-YB'!G36 -> 2.0804477e+08 | D5: အုတ္စီ၊ ေခ်ာ၊ က်ည္းေဘာင္ေထာင္ျခင္း
A6: 2 | B6: Labour Charges | C6: ='BQ-YB'!G47 -> 84491740 | D6: April, 2026 ေစ်းႏႈန္းအရျဖစ္ပါသည္
A7: 3 | B7: Mechinary Charges | C7: ='BQ-YB'!G52+'BQ-YB'!G57 -> 9782400 | D7: တည္ေဆာက္မည့္အခ်ိန္ကာလေစ်းႏႈန္းေပၚမူတည္ၿပီး
B8: Total | C8: =SUM(C5:C7) -> 3.0231891e+08 | D8: ေငြ Amount အေျပာင္းအလဲရွိႏိုင္ပါသည္
B9: Transportation Charges (3% of Material) | C9: =C5*0.03 -> 6241343
B10: Preliminary Cost (5%) | C10: =C8*0.05 -> 15115945
B11: Supervision (10%) | C11: =ROUND((C8+C9+C10)*0.1,-3) -> 32368000
B12: Grand Total Cost | C12: =SUM(C8:C11) -> 3.5604419e+08
B13: Say (For 1 No) | C13: =ROUND(C12,-4) -> 356040000
B15: Floor Area | C15: ='Floor Area'!G11 -> 3729.4
B16: PAE | C16: =C13/C15 -> 95468.44

Sheet BQ-YB
A1: =Detail!A1 -> U MYO MIN AUNG (KAN NAR LANN, MAGWAY)
A2: =Detail!A2 -> 27' X 40' 2.5 STOREYED BUILDING (Structure Work)
A3: BILL OF QUANTITY
A4: No. | B4: Particular | C4: Unit | D4: Quantity | E4: Rate | F4: Per | G4: Amount
B6: Material
A7: 1 | B7: Cement | C7: Bag | D7: =SUMIF(BE!$B$6:$B$386,B7,BE!$D$6:$D$386) -> 1501.97 | E7: =VLOOKUP(B7,Rate!$A$2:$C$29,3,FALSE) -> 25000 | F7: =C7 -> Bag | G7: =D7*E7 -> 37549250
A8: 2 | B8: R/Sand | C8: Sud | D8: =SUMIF(BE!$B$6:$B$386,B8,BE!$D$6:$D$386) -> 73.68 | E8: =VLOOKUP(B8,Rate!$A$2:$C$29,3,FALSE) -> 50000 | F8: =C8 -> Sud | G8: =D8*E8 -> 3684000
A9: 3 | B9: R/Sand for Backfill | C9: Sud | D9: =SUMIF(BE!$B$6:$B$386,B9,BE!$D$6:$D$386) -> 122.81 | E9: =VLOOKUP(B9,Rate!$A$2:$C$29,3,FALSE) -> 50000 | F9: =C9 -> Sud | G9: =D9*E9 -> 6140500
A10: 4 | B10: Brick | C10: No | D10: =SUMIF(BE!$B$6:$B$386,B10,BE!$D$6:$D$386) -> 41691 | E10: =VLOOKUP(B10,Rate!$A$2:$C$29,3,FALSE) -> 500 | F10: =C10 -> No | G10: =D10*E10 -> 20845500
A11: 5 | B11: R/Shingle | C11: Sud | D11: =SUMIF(BE!$B$6:$B$386,B11,BE!$D$6:$D$386) -> 54.72 | E11: =VLOOKUP(B11,Rate!$A$2:$C$29,3,FALSE) -> 130000 | F11: =C11 -> Sud | G11: =D11*E11 -> 7113600
A12: 6 | B12: Hard Core | C12: Sud | D12: =SUMIF(BE!$B$6:$B$386,B12,BE!$D$6:$D$386) -> 5.33 | E12: =VLOOKUP(B12,Rate!$A$2:$C$29,3,FALSE) -> 220000 | F12: =C12 -> Sud | G12: =D12*E12 -> 1172600
A13: 7 | B13: Fuel | C13: Gal | D13: =SUMIF(BE!$B$6:$B$386,B13,BE!$D$6:$D$386) -> 108.92 | E13: =VLOOKUP(B13,Rate!$A$2:$C$29,3,FALSE) -> 20000 | F13: =C13 -> Gal | G13: =D13*E13 -> 2178400
A14: 8 | B14: Bonding Agent | C14: Lit | D14: =SUMIF(BE!$B$6:$B$386,B14,BE!$D$6:$D$386) -> 59 | E14: =VLOOKUP(B14,Rate!$A$2:$C$29,3,FALSE) -> 25000 | F14: =C14 -> Lit | G14: =D14*E14 -> 1475000
A15: 9 | B15: Sikament-9 | C15: Lit | D15: =SUMIF(BE!$B$6:$B$386,B15,BE!$D$6:$D$386) -> 220.59 | E15: =VLOOKUP(B15,Rate!$A$2:$C$29,3,FALSE) -> 7000 | F15: =C15 -> Lit | G15: =D15*E15 -> 1544130
A16: 10 | B16: T-Rental Charges | C16: No | D16: =SUMIF(BE!$B$6:$B$386,B16,BE!$D$6:$D$386) -> 1167 | E16: =VLOOKUP(B16,Rate!$A$2:$C$29,3,FALSE) -> 8750 | F16: =C16 -> No | G16: =D16*E16 -> 10211250
A17: 11 | B17: 5 Ply Wood (8' x 4') | C17: Sht | D17: =SUMIF(BE!$B$6:$B$386,B17,BE!$D$6:$D$386) -> 125.61 | E17: =VLOOKUP(B17,Rate!$A$2:$C$29,3,FALSE) -> 75000 | F17: =C17 -> Sht | G17: =D17*E17 -> 9420750
A18: 12 | B18: Jungle Wood | C18: Ton | D18: =SUMIF(BE!$B$6:$B$386,B18,BE!$D$6:$D$386) -> 14.02 | E18: =VLOOKUP(B18,Rate!$A$2:$C$29,3,FALSE) -> 1500000 | F18: =C18 -> Ton | G18: =D18*E18 -> 21030000
... A20: 14 | B20: Wire Nail | C20: Lb | D20: =SUMIF(BE!$B$6:$B$386,B20,BE!$D$6:$D$386) -> 605.29 | E20: =VLOOKUP(B20,Rate!$A$2:$C$29,3,FALSE) -> 3333 | F20: =C20 -> Lb | G20: =D20*E20 -> 2017431.6
A21: 15 | B21: M.S Rod
B22: 6.5 mm Ø M.S Rod | C22: Ton | D22: =SUMIF(BE!$B$6:$B$386,B22,BE!$D$6:$D$386) -> 0.32 | E22: =VLOOKUP(B22,Rate!$A$2:$C$29,3,FALSE) -> 2800000 | F22: =C22 -> Ton | G22: =D22*E22 -> 896000
B23: 8 mm Ø M.S Rod | C23: Ton | D23: =SUMIF(BE!$B$6:$B$386,B23,BE!$D$6:$D$386) -> 0.24 | E23: =VLOOKUP(B23,Rate!$A$2:$C$29,3,FALSE) -> 2700000 | F23: =C23 -> Ton | G23: =D23*E23 -> 648000
B24: 10 mm Ø Re bar | C24: Ton | D24: =SUMIF(BE!$B$6:$B$386,B24,BE!$D$6:$D$386) -> 9.59 | E24: =VLOOKUP(B24,Rate!$A$2:$C$29,3,FALSE) -> 3100000 | F24: =C24 -> Ton | G24: =D24*E24 -> 29729000
B25: 12 mm Ø Re bar | C25: Ton | D25: =SUMIF(BE!$B$6:$B$386,B25,BE!$D$6:$D$386) -> 2.45 | E25: =VLOOKUP(B25,Rate!$A$2:$C$29,3,FALSE) -> 2550000 | F25: =C25 -> Ton | G25: =D25*E25 -> 6247500
B26: 16 mm Ø Re bar | C26: Ton | D26: =SUMIF(BE!$B$6:$B$386,B26,BE!$D$6:$D$386) -> 12.5 | E26: =VLOOKUP(B26,Rate!$A$2:$C$29,3,FALSE) -> 2980000 | F26: =C26 -> Ton | G26: =D26*E26 -> 37250000
C27: Ton | D27: =SUM(D22:D26) -> 25.1
A28: 16 | B28: Binding Wire | C28: Lb | D28: =SUMIF(BE!$B$6:$B$386,B28,BE!$D$6:$D$386) -> 827.22 | E28: =VLOOKUP(B28,Rate!$A$2:$C$29,3,FALSE) -> 3333 | F28: =C28 -> Lb | G28: =D28*E28 -> 2757124.3
A29: 17 | B29: 5"x2" Chowket | C29: =BE!C324 -> Rft | D29: =SUMIF(BE!$B$6:$B$386,B29,BE!$D$6:$D$386) -> 310.76 | E29: =VLOOKUP(B29,Rate!$A$2:$C$29,3,FALSE) -> 12000 | F29: =C29 -> Rft | G29: =D29*E29 -> 3729120
A30: 18 | B30: Coal Tar | C30: Gal | D30: =SUMIF(BE!$B$6:$B$386,B30,BE!$D$6:$D$386) -> 3 | E30: =VLOOKUP(B30,Rate!$A$2:$C$29,3,FALSE) -> 12000 | F30: =C30 -> Gal | G30: =D30*E30 -> 36000
A31: 19 | B31: X-Met | C31: Fr | D31: =SUMIF(BE!$B$6:$B$386,B31,BE!$D$6:$D$386) -> 5773 | E31: =VLOOKUP(B31,Rate!$A$2:$C$29,3,FALSE) -> 170 | F31: =C31 -> Fr | G31: =D31*E31 -> 981410
A32: 20 | B32: Plastic Sheet (3' wide) | C32: =BE!C364 -> Yds | D32: =SUMIF(BE!$B$6:$B$386,B32,BE!$D$6:$D$386) -> 101.97 | E32: =VLOOKUP(B32,Rate!$A$2:$C$29,3,FALSE) -> 5000 | F32: =C32 -> Yds | G32: =D32*E32 -> 509850
A33: 21 | B33: Bamboo | C33: No | D33: =SUMIF(BE!$B$6:$B$386,B33,BE!$D$6:$D$386) -> 173.4 | E33: =VLOOKUP(B33,Rate!$A$2:$C$29,3,FALSE) -> 2000 | F33: =C33 -> No | G33: =D33*E33 -> 346800
A34: 22 | B34: Coin Yarn | C34: Viss | D34: =SUMIF(BE!$B$6:$B$386,B34,BE!$D$6:$D$386) -> 24.77 | E34: =VLOOKUP(B34,Rate!$A$2:$C$29,3,FALSE) -> 15000 | F34: =C34 -> Viss | G34: =D34*E34 -> 371550
B36: Total Material Cost | G36: =SUM(G7:G35) -> 2.0804477e+08
B37: Labour
A38: 1 | B38: Mason | C38: No | D38: =SUMIF(BE!$B$6:$B$386,B38,BE!$D$6:$D$386) -> 476.34 | E38: =VLOOKUP(B38,Rate!$A$37:$C$44,3,FALSE) -> 27000 | F38: =C38 -> No | G38: =D38*E38 -> 12861180
A39: 2 | B39: Operator | C39: No | D39: =SUMIF(BE!$B$6:$B$386,B39,BE!$D$6:$D$386) -> 27.24 | E39: =VLOOKUP(B39,Rate!$A$37:$C$44,3,FALSE) -> 27000 | F39: =C39 -> No | G39: =D39*E39 -> 735480
A40: 3 | B40: Worker | C40: No | D40: =SUMIF(BE!$B$6:$B$386,B40,BE!$D$6:$D$386) -> 2060.86 | E40: =VLOOKUP(B40,Rate!$A$37:$C$44,3,FALSE) -> 20000 | F40: =C40 -> No | G40: =D40*E40 -> 41217200
A41: 4 | B41: Worker (Dismantling) | C41: No | D41: =SUMIF(BE!$B$6:$B$386,B41,BE!$D$6:$D$386) -> 66.88 | E41: =VLOOKUP(B41,Rate!$A$37:$C$44,3,FALSE) -> 20000 | F41: No | G41: =D41*E41 -> 1337600
A42: 5 | B42: Steel Fixer | C42: No | D42: =SUMIF(BE!$B$6:$B$386,B42,BE!$D$6:$D$386) -> 476.65 | E42: =VLOOKUP(B42,Rate!$A$37:$C$44,3,FALSE) -> 27000 | F42: =C42 -> No | G42: =D42*E42 -> 12869550
A43: 6 | B43: Carpenter | C43: No | D43: =SUMIF(BE!$B$6:$B$386,B43,BE!$D$6:$D$386) -> 439.02 | E43: =VLOOKUP(B43,Rate!$A$37:$C$44,3,FALSE) -> 27000 | F43: =C43 -> No | G43: =D43*E43 -> 11853540
...

Sheet AC
A1: =Detail!A1 -> U MYO MIN AUNG (KAN NAR LANN, MAGWAY)
A2: =Detail!A2 -> 27' X 40' 2.5 STOREYED BUILDING (Structure Work)
A3: Abstract Of Costs
A4: Sr | B4: Quantity | C4: Unit | D4: Particulars | E4: Rate | F4: Per | G4: Material | H4: Labour | I4: Mechine | J4: Amount
A6: =BE!A6 -> 1 | B6: =BE!D6 -> 24 | C6: =BE!C6 -> %Fs | D6: =BE!B6 -> Site Clearing Work | E6: =J6/B6 -> 5000 | F6: =C6 -> %Fs | G6: =BE!G9 -> 0 | H6: =BE!H9 -> 120000 | J6: =SUM(G6:H6) -> 120000
A7: =BE!A11 -> 2 | B7: =BE!D11 -> 1850 | C7: =BE!C11 -> Fs | D7: =BE!B11 -> Staking Works For Preparation of Foundation | E7: =J7/B7 -> 71.28 | F7: =C7 -> Fs | G7: =BE!G19 -> 64632.87 | H7: =BE!H19 -> 67240 | J7: =SUM(G7:I7) -> 131872.87
B8: =BE!D21 -> 129.12 | C8: =BE!C21 -> %Fc | D8: =BE!B21 -> Excavation & Earth Removal | I8: =BE!I25 -> 4382400 | J8: =SUM(G8:I8) -> 4382400
A9: =BE!A28 -> 4 | B9: =BE!D28 -> 5.33 | C9: =BE!C28 -> %Fc | D9: =BE!B28 -> Hard Core Laying with sand Work | E9: =J9/B9 -> 286001.88 | F9: =C9 -> %Fc | G9: =BE!G35 -> 1239100 | H9: =BE!H35 -> 285290 | J9: =SUM(G9:I9) -> 1524390
A10: =BE!A37 -> 5 | B10: =BE!D37 -> 9.55 | C10: =BE!C37 -> %Fc | D10: =BE!B37 -> (1:3:6) Lean Conc; Work | E10: =J10/B10 -> 670760.21 | F10: =C10 -> %Fc | G10: =BE!G47 -> 4872850 | H10: =BE!H47 -> 1532910 | J10: =SUM(G10:I10) -> 6405760
A11: =BE!A49 -> 6 | B11: =BE!D49 -> 10.43 | C11: =BE!C49 -> %Fc | D11: =BE!B49 -> Retaining Wall Brick Work with (1:3) Cement Mortor | E11: =J11/B11 -> 1090128.5 | F11: =C11 -> %Fc | G11: =BE!G57 -> 8992000 | H11: =BE!H57 -> 2378040 | J11: =SUM(G11:I11) -> 11370040
A12: =BE!A59 -> 7 | D12: =BE!B59 -> Concrete Casting Work for Footing | J12: =SUM(G12:I12) -> 0
B13: =BE!D60 -> 9.84 | C13: =BE!C60 -> %Fc | D13: =BE!B60 -> ( a ) (1:2:4) R.C Conc; Work | E13: =J13/B13 -> 892123.98 | F13: =C13 -> %Fc | G13: =BE!G70 -> 6343100 | H13: =BE!H70 -> 2435400 | J13: =SUM(G13:I13) -> 8778500
B14: =BE!D72 -> 4.53 | C14: =BE!C72 -> %Fs | D14: =BE!B72 -> ( b ) Formwork | E14: =J14/B14 -> 453572.25 | F14: =C14 -> %Fs | G14: =BE!G80 -> 1384242.3 | H14: =BE!H80 -> 670440 | J14: =SUM(G14:I14) -> 2054682.3
B15: =BE!D81 -> 3.18 | C15: =BE!C81 -> Ton | D15: =BE!B81 -> ( c ) Rebar Work | E15: =J15/B15 -> 3804894.3 | F15: =C15 -> Ton | G15: =BE!G91 -> 9881164 | H15: =BE!H91 -> 2218400 | J15: =SUM(G15:I15) -> 12099564
A16: =BE!A93 -> 8 | D16: =BE!B93 -> Concrete Casting Work For Column | J16: =SUM(G16:I16) -> 0
B17: =BE!D94 -> 5.9 | C17: =BE!C94 -> %Fc | D17: =BE!B94 -> ( a ) (1:2:4) R.C Conc; Work | E17: =J17/B17 -> 1202144.1 | F17: =C17 -> %Fc | G17: =BE!G105 -> 5278400 | H17: =BE!H105 -> 1814250 | J17: =SUM(G17:I17) -> 7092650
B18: =BE!D107 -> 23.61 | C18: =BE!C107 -> %Fs | D18: =BE!B107 -> ( b ) Formwork | E18: =J18/B18 -> 504293.37 | F18: =C18 -> %Fs | G18: =BE!G117 -> 7247326.5 | H18: =BE!H117 -> 4659040 | J18: =SUM(G18:I18) -> 11906367
B19: =BE!D119 -> 5.85 | C19: =BE!C119 -> Ton | D19: =BE!B119 -> ( c ) Rebar Work | E19: =J19/B19 -> 4206091.2 | F19: =C19 -> Ton | G19: =BE!G131 -> 18265334 | H19: =BE!H131 -> 6340300 | J19: =SUM(G19:I19) -> 24605634
A20: =BE!A132 -> 9 | D20: =BE!B132 -> R.C Concrete Casting Work Beam | J20: =SUM(G20:I20) -> 0
B21: =BE!D133 -> 13.14 | C21: =BE!C133 -> %Fc | D21: =BE!B133 -> ( a ) (1:2:4) R.C Conc; Casting Work | E21: =J21/B21 -> 1016846.3 | F21: =C21 -> %Fc | G21: =BE!G144 -> 9320810 | H21: =BE!H144 -> 4040550 | J21: =SUM(G21:I21) -> 13361360
B22: =BE!D145 -> 29.84 | C22: =BE!C145 -> %Fs | D22: =BE!B145 -> ( b ) Formwork | E22: =J22/B22 -> 504253.22 | F22: =C22 -> %Fs | G22: =BE!G155 -> 9158465.9 | H22: =BE!H155 -> 5888450 | J22: =SUM(G22:I22) -> 15046916
B23: =BE!D156 -> 8.26 | C23: =BE!C156 -> Ton | D23: =BE!B156 -> ( c ) Rebar Work | E23: =J23/B23 -> 4050870.4 | F23: =C23 -> Ton | G23: =BE!G166 -> 27094040 | H23: =BE!H166 -> 6366150 | J23: =SUM(G23:I23) -> 33460190
A24: =BE!A168 -> 10 | D24: =BE!B168 -> RC Floor Slab Work | J24: =SUM(G24:I24) -> 0
B25: =BE!D169 -> 8.44 | C25: =BE!C169 -> %Fc | D25: =BE!B169 -> ( a ) (1:2:4) RC Concrete Work | E25: =J25/B25 -> 956759.48 | F25: =C25 -> %Fc | G25: =BE!G181 -> 5986150 | H25: =BE!H181 -> 2088900 | J25: =SUM(G25:I25) -> 8075050
B26: =BE!D183 -> 31.09 | C26: =BE!C183 -> %Fs | D26: =BE!B183 -> ( b ) Formwork | G26: =BE!G194 -> 9706480.5 | H26: =BE!H194 -> 6135070 | J26: =SUM(G26:I26) -> 15841550
B27: =BE!D198 -> 3.58 | D27: =BE!B196 -> ( c ) Re bar Work | G27: =BE!G206 -> 17536804 | H27: =BE!H206 -> 5207600 | J27: =SUM(G27:I27) -> 22744404
A28: =BE!A209 -> 11 | B28: 1 | C28: Lot | D28: =BE!B209 -> T-Rental Charges | J28: =BE!G210 -> 10211250
A29: =BE!A211 -> 12 | D29: =BE!B211 -> RC Stair Work | J29: =SUM(G29:I29) -> 0
B30: =BE!D212 -> 2.29 | C30: =BE!C212 -> %Fc | D30: =BE!B212 -> ( a ) RC Concrete Work | G30: =BE!G223 -> 1624520 | H30: =BE!H223 -> 566910 | J30: =SUM(G30:I30) -> 2191430
B31: =BE!D224 -> 5.36 | C31: =BE!C224 -> %Fs | D31: =BE!B224 -> ( b ) Formwork | G31: =BE!G234 -> 1637624.2 | H31: =BE!H234 -> 1057730 | J31: =SUM(G31:I31) -> 2695354.2
B32: =BE!D235 -> 0.69 | C32: =BE!C235 -> Ton | D32: =BE!B235 -> ( c ) Re bar Work | G32: =BE!G249 -> 2088492.2 | H32: =BE!H249 -> 987000 | J32: =SUM(G32:I32) -> 3075492.2
A33: =BE!A251 -> 13 | D33: =BE!B251 -> Mechinary Charges for RC Concrete Casting Work | J33: =SUM(G33:I33) -> 0
B34: =BE!D253 -> 21.78 | C34: =BE!C253 -> M3 | D34: =BE!B252 -> 1st Floor Beam,Slab & Stair | I34: =BE!I253 -> 1600000 | J34: =SUM(G34:I34) -> 1600000
D35: Pump Charges
B36: =BE!D256 -> 21.82 | C36: =C34 -> M3 | D36: =BE!B255 -> 2nd Floor Beam, Slab & Stair | I36: =BE!I256 -> 1800000 | J36: =SUM(G36:I36) -> 1800000
D37: Pump Charges
B38: =BE!D259 -> 15.37 | C38: =C36 -> M3 | D38: =BE!B258 -> Roof Beam & Slab | I38: =BE!I259 -> 2000000 | J38: =SUM(G38:I38) -> 2000000
D39: Pump Charges
J40: =SUM(G40:I40) -> 0
A41: =BE!A262 -> 14 | B41: =BE!D262 -> 50.2 | C41: =BE!C262 -> %Fs | D41: =BE!B262 -> ( a ) 4½" Thk; Brick Walling Work | E41: =J41/B41 -> 479844.82 | F41: =C41 -> %Fs | G41: =BE!G271 -> 18365410 | H41: =BE!H271 -> 5722800 | J41: =SUM(G41:I41) -> 24088210
...

Sheet BE
A1: =Detail!A1 -> U MYO MIN AUNG (KAN NAR LANN, MAGWAY)
A2: =Detail!A2 -> 27' X 40' 2.5 STOREYED BUILDING (Structure Work)
A3: BUILDER'S ESTIMATE
A4: Item | B4: Particular | C4: Unit | D4: Quantity | E4: Rate | F4: Per | G4: Amount
G5: Material | H5: Labour
A6: =Detail!A6 -> 1 | B6: =Detail!B6 -> Site Clearing Work | C6: =Detail!K7 -> %Fs | D6: =Detail!J7 -> 24
B7: Labour
B8: Worker | C8: No | D8: =D6*0.25 -> 6 | E8: ='BQ-YB'!E40 -> 20000 | F8: =C8 -> No | H8: =D8*E8 -> 120000
G9: =SUM(G8) -> 0 | H9: =SUM(H8) -> 120000
A11: =Detail!A9 -> 2 | B11: =Detail!B9 -> Staking Works For Preparation of Foundation | C11: =Detail!K9 -> Fs | D11: =Detail!J9 -> 1850
B12: Material
B13: Jungle Wood | C13: Ton | D13: =D11/(100*100)*30/50/3 -> 0.04 | E13: ='BQ-YB'!E18 -> 1500000 | F13: =C13 -> Ton | G13: =E13*D13 -> 60000
B14: Wire Nail | C14: Lb | D14: =D11/(100*100)*7.5 -> 1.39 | E14: ='BQ-YB'!E20 -> 3333 | F14: =C14 -> Lb | G14: =E14*D14 -> 4632.87
B15: Labour
B16: Surveyor | C16: No | D16: =D11/(100*100)*1 -> 0.19 | E16: ='BQ-YB'!E45 -> 27000 | F16: =C16 -> No | H16: =D16*E16 -> 5130
B17: Carpenter | C17: No | D17: =D11/(100*100)*5 -> 0.93 | E17: ='BQ-YB'!E43 -> 27000 | F17: =C17 -> No | H17: =D17*E17 -> 25110
B18: Worker | C18: No | D18: =D11/(100*100)*10 -> 1.85 | E18: ='BQ-YB'!E40 -> 20000 | F18: =C18 -> No | H18: =D18*E18 -> 37000
G19: =SUM(G13:G18) -> 64632.87 | H19: =SUM(H13:H18) -> 67240
A21: 3 | B21: =Detail!B12 -> Excavation & Earth Removal | C21: =Detail!K13 -> %Fc | D21: =Detail!J13 -> 129.12
B22: Excavator (8 Ton) | C22: Juty | D22: 2 | E22: ='BQ-YB'!E49 -> 800000 | F22: =C22 -> Juty | I22: =D22*E22 -> 1600000
B23: Transportation (Excavator သြား/ျပန္) | C23: Trip | D23: 2 | E23: ='BQ-YB'!E50 -> 100000 | F23: =C23 -> Trip | I23: =D23*E23 -> 200000
B24: Faw Car (3 Sud) For Earth Removal | C24: Trip | D24: =D21*1.5/3 -> 64.56 | E24: ='BQ-YB'!E51 -> 40000 | F24: =C24 -> Trip | I24: =D24*E24 -> 2582400
I25: =SUM(I22:I24) -> 4382400
A28: =Detail!A16 -> 4 | B28: =Detail!B16 -> Hard Core Laying with sand Work | C28: =Detail!K24 -> %Fc | D28: =Detail!J24 -> 5.33
B29: Material
B30: Hard Core | C30: Sud | D30: =D28 -> 5.33 | E30: ='BQ-YB'!E12 -> 220000 | F30: =C30 -> Sud | G30: =D30*E30 -> 1172600
B31: R/Sand | C31: Sud | D31: =D28*0.25 -> 1.33 | E31: ='BQ-YB'!E8 -> 50000 | F31: =C31 -> Sud | G31: =D31*E31 -> 66500
B32: Labour
B33: Mason | C33: No | D33: =D28*0.5 -> 2.67 | E33: ='BQ-YB'!E38 -> 27000 | F33: =C33 -> No | H33: =D33*E33 -> 72090
B34: Worker | C34: No | D34: =D28*2 -> 10.66 | E34: ='BQ-YB'!E40 -> 20000 | F34: =C34 -> No | H34: =D34*E34 -> 213200
G35: =SUM(G30:G34) -> 1239100 | H35: =SUM(H30:H34) -> 285290
A37: =Detail!A26 -> 5 | B37: =Detail!B26 -> (1:3:6) Lean Conc; Work | C37: =Detail!K52 -> %Fc | D37: =Detail!J52 -> 9.55
B38: Material
B39: Cement | C39: Bag | D39: =D37*1440/112 -> 122.79 | E39: ='BQ-YB'!E7 -> 25000 | F39: =C39 -> Bag | G39: =E39*D39 -> 3069750
B40: R/Sand | C40: Sud | D40: =D37*0.48 -> 4.58 | E40: ='BQ-YB'!E8 -> 50000 | F40: =C40 -> Sud | G40: =E40*D40 -> 229000
B41: R/Shingle | C41: Sud | D41: =D37*0.96 -> 9.17 | E41: ='BQ-YB'!E11 -> 130000 | F41: =C41 -> Sud | G41: =E41*D41 -> 1192100
B42: Fuel | C42: Gal | D42: =D37*2 -> 19.1 | E42: ='BQ-YB'!E13 -> 20000 | F42: =C42 -> Gal | G42: =E42*D42 -> 382000
B43: Labour
B44: Mason | C44: No | D44: =D37*1 -> 9.55 | E44: ='BQ-YB'!E38 -> 27000 | F44: =C44 -> No | H44: =D44*E44 -> 257850
B45: Operator | C45: No | D45: =D37*0.5 -> 4.78 | E45: ='BQ-YB'!E39 -> 27000 | F45: =C45 -> No | H45: =D45*E45 -> 129060
...

Sheet Detail
A1: U MYO MIN AUNG (KAN NAR LANN, MAGWAY)
A2: 27' X 40' 2.5 STOREYED BUILDING (Structure Work)
A3: DETAILS OF MEASUREMENT
A4: Item | B4: Particular | D4: No. | E4: Measurement | H4: Deduction | I4: Contents | J4: Total of Each | K4: Unit
E5: L | F5: B | G5: H
A6: 1 | B6: Site Clearing Work | D6: 1 | E6: =40+20 -> 60 | F6: =27+13 -> 40 | I6: =F6*E6*D6 -> 2400 | J6: =SUM(I6) -> 2400 | K6: Fs
J7: =J6/100 -> 24 | K7: %Fs
A9: 2 | B9: Staking Works For Preparation of Foundation | D9: =D6 -> 1 | E9: =40+10 -> 50 | F9: =27+10 -> 37 | I9: =F9*E9*D9 -> 1850 | J9: =SUM(I9) -> 1850 | K9: Fs
A11: 3 | B11: Earth Work in Medium Soil
B12: Excavation & Earth Removal
B13: Using Mechaniary | D13: 1 | E13: 34 | F13: 49 | G13: =7.75 -> 7.75 | I13: =D13*E13*F13*G13 -> 12911.5 | J13: =I13/100 -> 129.12 | K13: %Fc | M13: =J13*35000 -> 4519200
A16: 4 | B16: Hard Core Laying with sand Work
B17: Footing
B18: F1 (6' 0" x 6' 0" x 0'-10") | D18: 2 | E18: =6+1 -> 7 | F18: =E18 -> 7 | G18: =0.5 -> 0.5 | I18: =D18*E18*F18*G18 -> 49 | K18: Fc
B19: F2 (7' 0" x 7' 0" x 1'-0") | D19: 1 | E19: =7+1 -> 8 | F19: =E19 -> 8 | G19: =0.5 -> 0.5 | I19: =D19*E19*F19*G19 -> 32 | K19: Fc
B20: F3 (8' 0" x 8' 0" x 1'-0") | D20: 3 | E20: =8+1 -> 9 | F20: =E20 -> 9 | G20: =0.5 -> 0.5 | I20: =D20*E20*F20*G20 -> 121.5 | K20: Fc
B21: SF1 (10' 6" x 33' 6" x 1'-2") | D21: 1 | E21: =10.5+1 -> 11.5 | F21: =33.5+1 -> 34.5 | G21: =0.5 -> 0.5 | I21: =D21*E21*F21*G21 -> 198.4 | K21: Fc
B22: SF2 (4' 6" x 47' 0" x 1'-0") | D22: 1 | E22: =4.5+1 -> 5.5 | F22: =47+1 -> 48 | G22: =0.5 -> 0.5 | I22: =D22*E22*F22*G22 -> 132 | K22: Fc
J23: =SUM(I18:I23) -> 532.9 | K23: Fc
J24: =J23/100 -> 5.33 | K24: %Fc
A26: 5 | B26: (1:3:6) Lean Conc; Work
B27: Footing
B28: =B18 -> F1 (6' 0" x 6' 0" x 0'-10") | D28: =D18 -> 2 | E28: 6 | F28: 6 | G28: =0.25 -> 0.25 | I28: =D28*E28*F28*G28 -> 18 | K28: Fc
B29: =B19 -> F2 (7' 0" x 7' 0" x 1'-0") | D29: =D19 -> 1 | E29: 7 | F29: 7 | G29: =0.25 -> 0.25 | I29: =D29*E29*F29*G29 -> 12.3 | K29: Fc
B30: =B20 -> F3 (8' 0" x 8' 0" x 1'-0") | D30: =D20 -> 3 | E30: 8 | F30: 8 | G30: =0.25 -> 0.25 | I30: =D30*E30*F30*G30 -> 48 | K30: Fc
B31: =B21 -> SF1 (10' 6" x 33' 6" x 1'-2") | D31: =D21 -> 1 | E31: 10.5 | F31: 33.5 | G31: =1.17 -> 1.17 | I31: =D31*E31*F31*G31 -> 411.5 | K31: Fc
B32: =B22 -> SF2 (4' 6" x 47' 0" x 1'-0") | D32: =D22 -> 1 | E32: =4.5 -> 4.5 | F32: 47 | G32: 1 | I32: =D32*E32*F32*G32 -> 211.5 | K32: Fc
D33: =SUM(D28:D32) -> 8 | J33: =SUM(I28:I33) -> 701.3 | K33: Fc
B34: Retaining Wall
B35: Line A, 40' L | D35: 1 | E35: =40-5*1 -> 35 | F35: =1.67 -> 1.67 | G35: 0.5 | I35: =D35*E35*F35*G35 -> 29.23 | K35: Fc
B36: Line B, 40' L | D36: 1 | E36: =40-5*1 -> 35 | F36: =F35 -> 1.67 | G36: =G35 -> 0.5 | I36: =D36*E36*F36*G36 -> 29.23 | K36: Fc
B37: Line C, 40' L | D37: 1 | E37: =40-1*5 -> 35 | F37: =F36 -> 1.67 | G37: =G36 -> 0.5 | I37: =D37*E37*F37*G37 -> 29.23 | K37: Fc
B38: Line 1, 27' L | D38: 1 | E38: =27-3 -> 24 | F38: =F37 -> 1.67 | G38: =G37 -> 0.5 | I38: =D38*E38*F38*G38 -> 20.04 | K38: Fc
B39: Line 2, 3, 27' L | D39: 2 | E39: =27-3 -> 24 | F39: =F38 -> 1.67 | G39: =G38 -> 0.5 | I39: =D39*E39*F39*G39 -> 40.08 | K39: Fc
B40: Line 4, 27' L | D40: 1 | E40: =27-3 -> 24 | F40: =F39 -> 1.67 | G40: =G39 -> 0.5 | I40: =D40*E40*F40*G40 -> 20.04 | K40: Fc
B41: Line 5, 27' L | D41: 1 | E41: =27-3 -> 24 | F41: =F40 -> 1.67 | G41: =G40 -> 0.5 | I41: =D41*E41*F41*G41 -> 20.04 | K41: Fc
B42: Y-Dir Bet; A & B, 9' L | D42: 1 | E42: =9-1.67 -> 7.33 | F42: =F41 -> 1.67 | G42: =G41 -> 0.5 | I42: =D42*E42*F42*G42 -> 6.12 | K42: Fc
B43: Y-Dir Bet; B & C, 28' L | D43: 1 | E43: =28-1.67*4 -> 21.32 | F43: =F42 -> 1.67 | G43: =G42 -> 0.5 | I43: =D43*E43*F43*G43 -> 17.8 | K43: Fc
B44: X-Dir Bet; 2&3, 8' L | D44: 1 | E44: =8-1.67 -> 6.33 | F44: =F43 -> 1.67 | G44: =G43 -> 0.5 | I44: =D44*E44*F44*G44 -> 5.29 | K44: Fc
B45: X-Dir Bet; 3&4, 4' L | D45: 1 | E45: =4-1.67 -> 2.33 | F45: =F44 -> 1.67 | G45: =G44 -> 0.5 | I45: =D45*E45*F45*G45 -> 1.95 | K45: Fc
...

Sheet Cement
A2: Item | B2: Particular | C2: Work Volume | D2: Unit | E2: Cement | F2: Brick | G2: Sand | H2: Shingle
E3: Bag | F3: No | G3: Sud | H3: Sud
B4: Footing Lean | C4: =Detail!J33/100 -> 7.01 | D4: %Fc | E4: =ROUND(C4*12.5,0) -> 88 | G4: =ROUND(C4*0.48,2) -> 3.36 | H4: =ROUND(C4*0.96,2) -> 6.73
B5: Footing Concrete | C5: =Detail!J140 -> 9.84 | D5: %Fc | E5: =ROUND(C5*18,0) -> 177 | G5: =ROUND(C5*0.46,2) -> 4.53 | H5: =ROUND(C5*0.92,2) -> 9.05
B6: Short Column Concrete | C6: =Detail!J193/100 -> 1.32 | D6: %Fc | E6: =ROUND(C6*18,0) -> 24 | G6: =ROUND(C6*0.46,2) -> 0.61 | H6: =ROUND(C6*0.92,2) -> 1.21
B7: R/Wall Lean | C7: =Detail!J47/100 -> 2.24 | D7: %Fc | E7: =ROUND(C7*12.5,0) -> 28 | G7: =ROUND(C7*0.48,2) -> 1.08 | H7: =ROUND(C7*0.96,2) -> 2.15
B8: R/Wall Brick Work | C8: =Detail!J116/100 -> 9.34 | D8: %Fc | E8: =ROUND(C8*630/112,0) -> 53 | F8: =ROUND(C8*1300,0) -> 12142 | G8: =ROUND(C8*0.26,2) -> 2.43
B9: PB | C9: =Detail!J304/100 -> 3.04 | D9: %Fc | E9: =ROUND(C9*18,0) -> 55 | G9: =ROUND(C9*0.46,2) -> 1.4 | H9: =ROUND(C9*0.92,2) -> 2.8
B10: Brick Step Lean | C10: =Detail!J50/100 -> 0.3 | D10: %Fc | E10: =ROUND(C10*12.5,0) -> 4 | G10: =ROUND(C10*0.48,2) -> 0.14 | H10: =ROUND(C10*0.96,2) -> 0.29
B11: Brick Step Brick Work | C11: =Detail!J126/100 -> 1.19 | D11: %Fc | E11: =ROUND(C11*630/112,0) -> 7 | F11: =ROUND(C11*1300,0) -> 1547 | G11: =ROUND(C11*0.26,2) -> 0.31
B12: Total Sub Structure | E12: =SUM(E4:E11) -> 436 | F12: =SUM(F4:F11) -> 13689 | G12: =SUM(G4:G11) -> 13.86 | H12: =SUM(H4:H11) -> 22.23
B14: G.F Column Concrete | C14: =Detail!J198/100 -> 1.77 | D14: %Fc | E14: =ROUND(C14*18,0) -> 32 | G14: =ROUND(C14*0.46,2) -> 0.81 | H14: =ROUND(C14*0.92,2) -> 1.63
B16: 1st Floor Beam | C16: =Detail!J317/100 -> 3.59 | D16: %Fc | E16: =ROUND(C16*18,0) -> 65 | G16: =ROUND(C16*0.46,2) -> 1.65 | H16: =ROUND(C16*0.92,2) -> 3.3
B17: 1st Flloor Slab | C17: =Detail!J679/100 -> 2.96 | D17: %Fc | E17: =ROUND(C17*18,0) -> 53 | G17: =ROUND(C17*0.46,2) -> 1.36 | H17: =ROUND(C17*0.92,2) -> 2.72
B18: Stair (G to 1st F) | C18: =Detail!J894/2 -> 1.15 | D18: %Fc | E18: =ROUND(C18*18,0) -> 21 | G18: =ROUND(C18*0.46,2) -> 0.53 | H18: =ROUND(C18*0.92,2) -> 1.06
B19: 1st Fl Beam & Slab | C19: =SUM(C16:C18) -> 7.7 | D19: %Fc | E19: =SUM(E16:E18) -> 139 | G19: =SUM(G16:G18) -> 4 | H19: =SUM(H16:H18) -> 7
B21: 1st Floor Column | C21: =Detail!J203/100 -> 1.62 | D21: %Fc | E21: =ROUND(C21*18,0) -> 29 | G21: =ROUND(C21*0.46,2) -> 0.75 | H21: =ROUND(C21*0.92,2) -> 1.49
B23: 2nd Floor Beam | C23: =Detail!J331/100 -> 3.62 | D23: %Fc | E23: =ROUND(C23*18,0) -> 65 | G23: =ROUND(C23*0.46,2) -> 1.67 | H23: =ROUND(C23*0.92,2) -> 3.33
B24: 2nd Floor Slab | C24: =Detail!J689/100 -> 2.95 | D24: %Fc | E24: =ROUND(C24*18,0) -> 53 | G24: =ROUND(C24*0.46,2) -> 1.36 | H24: =ROUND(C24*0.92,2) -> 2.71
B25: Stair (1st to 2nd Floor) | C25: =C18 -> 1.15 | D25: %Fc | E25: =ROUND(C25*18,0) -> 21 | G25: =ROUND(C25*0.46,2) -> 0.53 | H25: =ROUND(C25*0.92,2) -> 1.06
B26: 2nd Fl Beam & Slab | C26: =SUM(C23:C25) -> 7.72 | D26: %Fc | E26: =SUM(E23:E25) -> 139 | G26: =SUM(G23:G25) -> 4 | H26: =SUM(H23:H25) -> 7
B28: 2nd Floor Column | C28: =Detail!J206/100 -> 1.18 | D28: %Fc | E28: =ROUND(C28*18,0) -> 21 | G28: =ROUND(C28*0.46,2) -> 0.54 | H28: =ROUND(C28*0.92,2) -> 1.09
B30: Roof Beam | C30: =Detail!J347/100 -> 2.89 | D30: %Fc | E30: =ROUND(C30*18,0) -> 52 | G30: =ROUND(C30*0.46,2) -> 1.33 | H30: =ROUND(C30*0.92,2) -> 2.66
B31: Roof Slab | C31: =Detail!J697/100 -> 2.53 | D31: %Fc | E31: =ROUND(C31*18,0) -> 46 | G31: =ROUND(C31*0.46,2) -> 1.16 | H31: =ROUND(C31*0.92,2) -> 2.33
B32: Roof Beam & Slab | C32: =SUM(C30:C31) -> 5.42 | D32: %Fc | E32: =SUM(E30:E31) -> 98 | G32: =SUM(G30:G31) -> 2 | H32: =SUM(H30:H31) -> 5
B34: 4.5" Thk; G.F Brick Wall | C34: =(Detail!J947+Detail!J1013)/100 -> 18.88 | D34: %Fs | E34: =ROUND(C34*2.65,0) -> 50
B35: 4.5" Thk; 1st F Brick Wall | C35: =(Detail!J966+Detail!J1030)/100 -> 16.61 | D35: %Fs
B36: 4.5" Thk; Roof F Brick Wall | C36: =(Detail!J985+Detail!J1040)/100 -> 10.79 | D36: %Fs
B37: 4.5" Thk; Roof Top Brick Wall | C37: =(Detail!J991+Detail!J1046)/100 -> 3.93 | D37: %Fs
B39: Lintel & Stiffener | C39: =Detail!J1078 -> 1.98 | D39: %Fc
