Workbook

Sheet Summary (2)
A1: =BQ!A1 -> One Storeyed RCC Building, Myat Lay Street
A2: 19'-5"~26'-3"x42'-7"x44'-0" Ht; (Foundation Work)
A3: Summary | E3: Date : | F3: =TODAY() -> 46197
A4: No. | B4: Particular | C4: Amount | D4: Remark
A6: 1 | B6: Foundation Work with Bored Pile | C6: =Summary!C15 -> 307900000 | F6: =C6+C11+C12 -> 311120000
A7: 2 | B7: Foundation Work without Bored Pile | C7: =[3]Summary!$C$13 -> 48300000 | F7: =[2]Summary!$C$7+[1]Summary!$C$7 -> 11754110
B9: Difference | C9: =C6-C7 -> 259600000
B10: မြေပြန်ဖြည့်ခ | C10: 800000 | D10: Backhoe 1 duty
B11: Mobilization | C11: 3000000
B12: Pile Design Fee | C12: 220000
B13: Supervision Charges
B14: Total Extra Charges for Bored Pile | C14: =SUM(C9:C13) -> 263620000
B15: Say (For 1 No.) | C15: =ROUNDDOWN(C14,-5) -> 263600000
B17: Area | D17: Sq-ft
B18: PAE Rate | C18: =C15/C17 -> #DIV/0! | D18: per Sq-ft

Sheet Total Summary
A1: =BQ!A1 -> One Storeyed RCC Building, Myat Lay Street
A2: =BQ!A2 -> 35'-0"x45'-0"x13'-0" Ht;
A3: Total Summary | E3: Date : | F3: =TODAY() -> 46197
A4: No. | B4: Particular | C4: Amount | D4: Remark
A6: 1 | B6: Main Building | C6: =Summary!C15 -> 307900000 | F6: =[2]Summary!$C$6+[1]Summary!$C$6 -> 32096652
A7: 2 | B7: Ground Tank | C7: =[6]Summary!$C$13 -> 4600000 | F7: =[2]Summary!$C$7+[1]Summary!$C$7 -> 11754110
A8: 3 | B8: Septic Tank | C8: =[7]Summary!$C$12 -> 3500000
B10: Total Cost | C10: =SUM(C6:C9) -> 316000000
B11: မြေပြန်ဖြည့်ခ | D11: Backhoe 1 duty
B12: Say (For 1 No.) | C12: =ROUNDDOWN(C10,-4) -> 316000000 | F12: =C12-[4]Summary!$C$14 -> 58700000
B14: Area | D14: Sq-ft
B15: PAE Rate | C15: =C12/C14 -> #DIV/0! | D15: per Sq-ft
B16: Area | C16: =(35*45+9.5*5+6*5+5*5) -> 1677.5 | D16: (For 1 Storeyed)
B17: PAE Rate | C17: =C12/C16 -> 188375.56

Sheet Summary
A1: =BQ!A1 -> One Storeyed RCC Building, Myat Lay Street
A2: =BQ!A2 -> 35'-0"x45'-0"x13'-0" Ht;
A3: Summary | E3: Date : | F3: =TODAY() -> 46197
A4: No. | B4: Particular | C4: Amount | D4: Remark
A6: 1 | B6: Material Cost | C6: =BQ!G102 -> 1.7070056e+08 | F6: =[2]Summary!$C$6+[1]Summary!$C$6 -> 32096652
A7: 2 | B7: Labour Cost | C7: =BQ!G121 -> 88147568 | F7: =[2]Summary!$C$7+[1]Summary!$C$7 -> 11754110
B9: Total Cost | C9: =SUM(C6:C7) -> 2.5884813e+08
B10: မြေပြန်ဖြည့်ခ | D10: Backhoe 1 duty
B11: Transportation Charges | C11: =BQ!G123 -> 7765443.8
B12: Preliminary Charges | C12: =BQ!G124 -> 13330679
B13: Supervision Charges | C13: =BQ!G125 -> 27994425
B14: Grand Total Cost | C14: =SUM(C9:C13) -> 3.0793867e+08
B15: Say (For 1 No.) | C15: =ROUNDDOWN(C14,-5) -> 307900000 | D15: Main Building | F15: =C15-[4]Summary!$C$14 -> 50600000
B17: Area | D17: Sq-ft
B18: PAE Rate | C18: =C15/C17 -> #DIV/0! | D18: per Sq-ft
B19: Area | C19: =(35*45+9.5*5+6*5+5*5) -> 1677.5 | E19: =45*34 -> 1530
B20: PAE Rate | C20: =C15/C19 -> 183546.94 | D20: Main Builing

Sheet AC
A1: =Detail!A1 -> One Storeyed RCC Building, Myat Lay Street
A2: =BQ!A2 -> 35'-0"x45'-0"x13'-0" Ht;
A3: Abstract of Cost (Main Building)
A4: Sr. No | B4: Particular | C4: Quantity | D4: Unit | E4: Rate( Kyats ) | F4: Per | G4: Amount(Ks) | H4: 0.3 | I4: Amount(Ks) | J4: Old | K4: Structure Wall | L4: Extra Charges | M4: Reduced Charges
A5: 1 | B5: Site Clearing | C5: =VLOOKUP(B5,BE!$B$5:$C$459,2,FALSE) -> 24.75 | D5: =VLOOKUP(B5,BE!$B$5:$E$810,4,FALSE) -> %Fs | E5: =G5/C5 -> 5447.2 | F5: =D5 -> %Fs | G5: =VLOOKUP(B5,BE!$B$5:$H$810,7,FALSE) -> 134818.2 | H5: =G5*1.3 -> 175263.66 | I5: =ROUNDUP(H5,-4) -> 180000 | J5: =[4]AC!$L$5 -> 110000 | K5: =I5 -> 180000 | N5: =BE!H8 -> 134818.2 | O5: =G5-N5 -> 0 | P5: =G5/$G$71 -> 0.000520839 | Q5: =P5+P6+P7+P9+P10+P11+P19+P20+P23+P24+P26+P13+P32+P33+P35+P42 -> 0.21181894 | R5: 15 | S5: =#REF!+#REF!+#REF!+#REF!+#REF!+#REF! -> #REF! | T5: 20
A6: 2 | B6: Surveying & Levelling Work | C6: =VLOOKUP(B6,BE!$B$5:$C$459,2,FALSE) -> 15.75 | D6: =VLOOKUP(B6,BE!$B$5:$E$810,4,FALSE) -> %Fs | E6: =G6/C6 -> 6157.327 | F6: =D6 -> %Fs | G6: =VLOOKUP(B6,BE!$B$5:$H$810,7,FALSE) -> 96977.9 | H6: =G6*1.3 -> 126071.27 | I6: =ROUNDUP(H6,-4) -> 130000 | J6: =[4]AC!$L$6 -> 80000 | K6: =I6 -> 130000 | N6: =BE!H20 -> 96977.9 | O6: =G6-N6 -> 0 | P6: =G6/$G$71 -> 0.00037465174 | Q6: =P12+P25+P34 -> 0.050920357 | R6: 5 | T6: 6
A7: 3 | B7: Earthwork Excavation for foundation in medium soil | C7: =VLOOKUP(B7,BE!$B$5:$C$459,2,FALSE) -> 56.07 | D7: =VLOOKUP(B7,BE!$B$5:$E$810,4,FALSE) -> %Fc | E7: =G7/C7 -> 43560 | F7: =D7 -> %Fc | G7: =VLOOKUP(B7,BE!$B$5:$H$810,7,FALSE) -> 2442409.2 | H7: =G7*1.3 -> 3175132 | I7: =ROUNDUP(H7,-4) -> 3180000 | J7: =[4]AC!$K$7 -> 1530000 | K7: =I7 -> 3180000 | L7: =K7-J7 -> 1650000 | N7: =BE!H25 -> 2442409.2 | O7: =G7-N7 -> 0 | P7: =G7/$G$71 -> 0.0094356843 | Q7: =P14+#REF!+P27+P28+P36+P37 -> #REF! | R7: 10 | T7: 15
A8: 4 | B8: Timber shuttering Formwork (3 Times) | C8: =VLOOKUP(B8,BE!$B$5:$C$459,2,FALSE) -> 71.27 | D8: =VLOOKUP(B8,BE!$B$5:$E$810,4,FALSE) -> %Fs | H8: =G8*1.3 -> 0 | I8: =ROUNDUP(H8,-4) -> 0 | K8: =I8 -> 0 | L8: =K8-J8 -> 0 | N8: =BE!H37 -> 0 | O8: =G8-N8 -> 0 | P8: =G8/$G$71 -> 0 | Q8: =P44+#REF!+P16+P29+P38 -> #REF! | R8: 5 | T8: 8
B9: =BE!B39 -> Footing Formwork | C9: =VLOOKUP(B9,BE!$B$5:$C$459,2,FALSE) -> 4.4 | D9: =VLOOKUP(B9,BE!$B$5:$E$810,4,FALSE) -> %Fs | E9: =G9/C9 -> 491810.11 | F9: =D9 -> %Fs | G9: =VLOOKUP(B9,BE!$B$5:$H$810,7,FALSE) -> 2163964.5 | H9: =G9*1.3 -> 2813153.9 | I9: =ROUNDUP(H9,-4) -> 2820000 | J9: =[4]AC!$L$11 -> 3310000 | K9: =I9 -> 2820000 | L9: =K9-J9 -> -490000 | P9: =G9/$G$71 -> 0.0083599775 | Q9: =P46+#REF!+P51 -> #REF! | R9: 10 | T9: 15
B10: =BE!B51 -> Retaining Wall Formwork | C10: =VLOOKUP(B10,BE!$B$5:$C$459,2,FALSE) -> 3.86 | D10: =VLOOKUP(B10,BE!$B$5:$E$810,4,FALSE) -> %Fs | E10: =G10/C10 -> 489160.91 | F10: =D10 -> %Fs | G10: =VLOOKUP(B10,BE!$B$5:$H$810,7,FALSE) -> 1888161.1 | H10: =G10*1.3 -> 2454609.4 | I10: =ROUNDUP(H10,-4) -> 2460000 | J10: =[4]AC!$L$12 -> 970000 | K10: =I10 -> 2460000 | M10: =J10-K10 -> -1490000 | P10: =G10/$G$71 -> 0.0072944747 | Q10: =P41 -> 0.008684922 | R10: 5 | T10: 5
B11: =BE!B63 -> Short Column Formwork | C11: =VLOOKUP(B11,BE!$B$5:$C$459,2,FALSE) -> 4.93 | D11: =VLOOKUP(B11,BE!$B$5:$E$810,4,FALSE) -> %Fs | E11: =G11/C11 -> 491235.5 | F11: =D11 -> %Fs | G11: =VLOOKUP(B11,BE!$B$5:$H$810,7,FALSE) -> 2421791 | H11: =G11*1.3 -> 3148328.3 | I11: =ROUNDUP(H11,-4) -> 3150000 | J11: =[4]AC!$L$13 -> 1530000 | K11: =I11 -> 3150000 | L11: =K11-J11 -> 1620000 | P11: =G11/$G$71 -> 0.0093560306 | Q11: =SUM(Q5:Q9) -> #REF! | R11: 5 | T11: 5
B12: =BE!B75 -> Ground Floor Column Formwork | C12: =VLOOKUP(B12,BE!$B$5:$C$459,2,FALSE) -> 12.91 | D12: =VLOOKUP(B12,BE!$B$5:$E$810,4,FALSE) -> %Fs | E12: =G12/C12 -> 490810.22 | F12: =D12 -> %Fs | G12: =VLOOKUP(B12,BE!$B$5:$H$810,7,FALSE) -> 6336359.9 | H12: =G12*1.3 -> 8237267.9 | I12: =ROUNDUP(H12,-4) -> 8240000 | J12: =[4]AC!$L$14 -> 3730000 | K12: =I12 -> 8240000 | L12: =K12-J12 -> 4510000 | P12: =G12/$G$71 -> 0.024479064 | R12: =SUM(R5:R11) -> 55 | T12: =SUM(T5:T11) -> 74
B13: =BE!B87 -> Ground Beam Formwork | C13: =VLOOKUP(B13,BE!$B$5:$C$459,2,FALSE) -> 7.92 | D13: =VLOOKUP(B13,BE!$B$5:$E$810,4,FALSE) -> %Fs | E13: =G13/C13 -> 491507.54 | F13: =D13 -> %Fs | G13: =VLOOKUP(B13,BE!$B$5:$H$810,7,FALSE) -> 3892739.7 | H13: =G13*1.3 -> 5060561.6 | I13: =ROUNDUP(H13,-4) -> 5070000 | J13: =[4]AC!$L$16 -> 2810000 | K13: =I13 -> 5070000 | L13: =K13-J13 -> 2260000 | P13: =G13/$G$71 -> 0.015038701
B14: =BE!B99 -> Roof Beam Formwork | C14: =VLOOKUP(B14,BE!$B$5:$C$459,2,FALSE) -> 12.41 | D14: =VLOOKUP(B14,BE!$B$5:$E$810,4,FALSE) -> %Fs | E14: =G14/C14 -> 491449.75 | F14: =D14 -> %Fs | G14: =VLOOKUP(B14,BE!$B$5:$H$810,7,FALSE) -> 6098891.4 | H14: =G14*1.3 -> 7928558.8 | I14: =ROUNDUP(H14,-4) -> 7930000 | J14: =[4]AC!$L$17 -> 4220000 | K14: =I14 -> 7930000 | L14: =K14-J14 -> 3710000 | P14: =G14/$G$71 -> 0.023561659
B15: =BE!B111 -> Slab Formwork | C15: =VLOOKUP(B15,BE!$B$5:$C$459,2,FALSE) -> 14.27 | D15: =VLOOKUP(B15,BE!$B$5:$E$810,4,FALSE) -> %Fs | E15: =G15/C15 -> 490536.07 | F15: =D15 -> %Fs | G15: =VLOOKUP(B15,BE!$B$5:$H$810,7,FALSE) -> 6999949.7 | H15: =G15*1.3 -> 9099934.6 | I15: =ROUNDUP(H15,-4) -> 9100000 | J15: =[4]AC!$L$22 -> 6470000 | K15: =I15 -> 9100000 | L15: =K15-J15 -> 2630000 | P15: =G15/$G$71 -> 0.02704269
B16: =BE!B123 -> Lintel & Stiffener Formwork | C16: =VLOOKUP(B16,BE!$B$5:$C$459,2,FALSE) -> 8.72 | D16: =VLOOKUP(B16,BE!$B$5:$E$810,4,FALSE) -> %Fs | E16: =G16/C16 -> 490462.52 | F16: =D16 -> %Fs | G16: =VLOOKUP(B16,BE!$B$5:$H$810,7,FALSE) -> 4276833.2 | P16: =G16/$G$71 -> 0.016522558
B17: =BE!B135 -> Sunshade Formwork | C17: =VLOOKUP(B17,BE!$B$5:$C$459,2,FALSE) -> 1.85 | D17: =VLOOKUP(B17,BE!$B$5:$E$810,4,FALSE) -> %Fs | E17: =G17/C17 -> 492163.08 | F17: =D17 -> %Fs | G17: =VLOOKUP(B17,BE!$B$5:$H$810,7,FALSE) -> 910501.7 | P17: =G17/$G$71 -> 0.0035175132
A18: 5 | B18: =BE!B147 -> 9" thk; Hardcore Stone Work with Sand Filling | C18: =VLOOKUP(B18,BE!$B$5:$C$459,2,FALSE) -> 2.34 | D18: =VLOOKUP(B18,BE!$B$5:$E$810,4,FALSE) -> %Fc | E18: =G18/C18 -> 259344.1 | F18: =D18 -> %Fc | G18: =VLOOKUP(B18,BE!$B$5:$H$810,7,FALSE) -> 606865.2 | H18: =G18*1.3 -> 788924.76 | I18: =ROUNDUP(H18,-4) -> 790000 | J18: =[4]AC!$L$23 -> 1230000 | K18: =I18 -> 790000 | L18: =K18-J18 -> -440000 | N18: =BE!H168 -> 1907044.7 | O18: =G18-N18 -> -1300179.5 | P18: =G18/$G$71 -> 0.0023444836
A19: 6 | B19: ( 1:3:6 ) Cement Concrete Work with River Shingle | C19: =VLOOKUP(B19,BE!$B$5:$C$459,2,FALSE) -> 10.83 | D19: =VLOOKUP(B19,BE!$B$5:$E$810,4,FALSE) -> %Fc | E19: =G19/C19 -> 572898.31 | F19: =D19 -> %Fc | G19: =VLOOKUP(B19,BE!$B$5:$H$810,7,FALSE) -> 6204488.7 | H19: =G19*1.3 -> 8065835.3 | I19: =ROUNDUP(H19,-4) -> 8070000 | J19: =[4]AC!$L$23 -> 1230000 | K19: =I19 -> 8070000 | L19: =K19-J19 -> 6840000 | N19: =BE!H169 -> 6204488.7 | O19: =G19-N19 -> 0 | P19: =G19/$G$71 -> 0.02396961
A20: 7 | B20: =BE!B171 -> Sand Filling Work, watering & Ramming | C20: =VLOOKUP(B20,BE!$B$5:$C$459,2,FALSE) -> 41.77 | D20: =VLOOKUP(B20,BE!$B$5:$E$810,4,FALSE) -> %Fc | E20: =G20/C20 -> 59285.387 | F20: =D20 -> %Fc | G20: =VLOOKUP(B20,BE!$B$5:$H$810,7,FALSE) -> 2476350.6 | H20: =G20*1.3 -> 3219255.8 | I20: =ROUNDUP(H20,-4) -> 3220000 | J20: =[4]AC!$L$24 -> 1880000 | K20: =I20 -> 3220000 | L20: =K20-J20 -> 1340000 | N20: =BE!H178 -> 2476350.6 | O20: =G20-N20 -> 0 | P20: =G20/$G$71 -> 0.0095668091
A21: 8 | B21: =BE!B180 -> Back Filling Work | C21: =VLOOKUP(B21,BE!$B$5:$C$459,2,FALSE) -> 34.96 | D21: =VLOOKUP(B21,BE!$B$5:$E$810,4,FALSE) -> %Fc | E21: =G21/C21 -> 21780 | F21: =D21 -> %Fc | G21: =VLOOKUP(B21,BE!$B$5:$H$810,7,FALSE) -> 761428.8 | H21: =G21*1.3 -> 989857.44 | I21: =ROUNDUP(H21,-4) -> 990000 | J21: =[4]AC!$L$24 -> 1880000 | K21: =I21 -> 990000 | L21: =K21-J21 -> -890000 | N21: =BE!H179 -> 0 | O21: =G21-N21 -> 761428.8 | P21: =G21/$G$71 -> 0.0029416044
A22: 9 | B22: (1:2:4) RC Concrete Work | C22: =VLOOKUP(B22,BE!$B$5:$C$459,2,FALSE) -> 20.39 | D22: =VLOOKUP(B22,BE!$B$5:$E$810,4,FALSE) -> %Fc | H22: =G22*1.3 -> 0 | I22: =ROUNDUP(H22,-4) -> 0 | K22: =I22 -> 0 | L22: =K22-J22 -> 0 | O22: =G22-N22 -> 0 | P22: =G22/$G$71 -> 0
B23: =BE!B186 -> Footing Concrete | C23: =VLOOKUP(B23,BE!$B$5:$C$459,2,FALSE) -> 3.96 | D23: =VLOOKUP(B23,BE!$B$5:$E$810,4,FALSE) -> %Fc | E23: =G23/C23 -> 767148.61 | F23: =D23 -> %Fc | G23: =VLOOKUP(B23,BE!$B$5:$H$810,7,FALSE) -> 3037908.5 | H23: =G23*1.3 -> 3949281.1 | I23: =ROUNDUP(H23,-4) -> 3950000 | J23: =[4]AC!$L$27 -> 5140000 | K23: =[5]AC!$L$33 -> 5140000 | L23: =K23-J23 -> 0 | N23: =BE!H198 -> 3037908.5 | O23: =G23-N23 -> 0 | P23: =G23/$G$71 -> 0.011736258
B24: =BE!B200 -> Short Column Concrete | C24: =VLOOKUP(B24,BE!$B$5:$C$459,2,FALSE) -> 1.07 | D24: =VLOOKUP(B24,BE!$B$5:$E$810,4,FALSE) -> %Fc | E24: =G24/C24 -> 771229.07 | F24: =D24 -> %Fc | G24: =VLOOKUP(B24,BE!$B$5:$H$810,7,FALSE) -> 825215.1 | H24: =G24*1.3 -> 1072779.6 | I24: =ROUNDUP(H24,-4) -> 1080000 | J24: =[4]AC!$L$28 -> 820000 | K24: =[5]AC!$L$35 -> 1050000 | L24: =K24-J24 -> 230000 | N24: =BE!H212 -> 825215.1 | O24: =G24-N24 -> 0 | P24: =G24/$G$71 -> 0.0031880281
B25: =BE!B214 -> Ground Floor Column Concrete | C25: =VLOOKUP(B25,BE!$B$5:$C$459,2,FALSE) -> 2.68 | D25: =VLOOKUP(B25,BE!$B$5:$E$810,4,FALSE) -> %Fc | E25: =G25/C25 -> 787177.09 | F25: =D25 -> %Fc | G25: =VLOOKUP(B25,BE!$B$5:$H$810,7,FALSE) -> 2109634.6 | H25: =G25*1.3 -> 2742525 | I25: =ROUNDUP(H25,-4) -> 2750000 | J25: =[4]AC!$L$29 -> 2020000 | K25: =[5]AC!$L$36 -> 2020000 | L25: =K25-J25 -> 0 | N25: =BE!H227 -> 2109634.6 | O25: =G25-N25 -> 0 | P25: =G25/$G$71 -> 0.0081500864
B26: =BE!B229 -> Ground Beam Concrete | C26: =VLOOKUP(B26,BE!$B$5:$C$459,2,FALSE) -> 3.35 | D26: =VLOOKUP(B26,BE!$B$5:$E$810,4,FALSE) -> %Fc | E26: =G26/C26 -> 769189.16 | F26: =D26 -> %Fc | G26: =VLOOKUP(B26,BE!$B$5:$H$810,7,FALSE) -> 2576783.7 | H26: =G26*1.3 -> 3349818.8 | I26: =ROUNDUP(H26,-4) -> 3350000 | J26: =[4]AC!$L$31 -> 2240000 | K26: =[5]AC!$L$38 -> 2240000 | L26: =K26-J26 -> 0 | N26: =BE!H241 -> 2576783.7 | O26: =G26-N26 -> 0 | P26: =G26/$G$71 -> 0.0099548092
B27: =BE!B243 -> Roof Beam Concrete | C27: =VLOOKUP(B27,BE!$B$5:$C$459,2,FALSE) -> 3.61 | D27: =VLOOKUP(B27,BE!$B$5:$E$810,4,FALSE) -> %Fc | E27: =G27/C27 -> 846797.37 | F27: =D27 -> %Fc | G27: =VLOOKUP(B27,BE!$B$5:$H$810,7,FALSE) -> 3056938.5 | H27: =G27*1.3 -> 3974020.1 | I27: =ROUNDUP(H27,-4) -> 3980000 | J27: =[4]AC!$L$32 -> 3140000 | K27: =[5]AC!$L$39 -> 3140000 | L27: =K27-J27 -> 0 | N27: =BE!H256 -> 3056938.5 | O27: =G27-N27 -> 0 | P27: =G27/$G$71 -> 0.011809776
B28: =BE!B258 -> Slab Concrete | C28: =VLOOKUP(B28,BE!$B$5:$C$459,2,FALSE) -> 3.26 | D28: =VLOOKUP(B28,BE!$B$5:$E$810,4,FALSE) -> %Fc | E28: =G28/C28 -> 846981.07 | F28: =D28 -> %Fc | G28: =VLOOKUP(B28,BE!$B$5:$H$810,7,FALSE) -> 2761158.3 | H28: =G28*1.3 -> 3589505.8 | I28: =ROUNDUP(H28,-4) -> 3590000 | J28: =[4]AC!$L$36 -> 2780000 | K28: =[5]AC!$L$47 -> 2780000 | L28: =K28-J28 -> 0 | N28: =BE!H271 -> 2761158.3 | O28: =G28-N28 -> 0 | P28: =G28/$G$71 -> 0.010667098
B29: =BE!B273 -> Lintel & Stiffener Concrete | C29: =VLOOKUP(B29,BE!$B$5:$C$459,2,FALSE) -> 2.15 | D29: =VLOOKUP(B29,BE!$B$5:$E$810,4,FALSE) -> %Fc | E29: =G29/C29 -> 768228.84 | F29: =D29 -> %Fc | G29: =VLOOKUP(B29,BE!$B$5:$H$810,7,FALSE) -> 1651692 | P29: =G29/$G$71 -> 0.0063809309
B30: =BE!B287 -> Sunshade Concrete | C30: =VLOOKUP(B30,BE!$B$5:$C$459,2,FALSE) -> 0.3 | D30: =VLOOKUP(B30,BE!$B$5:$E$810,4,FALSE) -> %Fc | E30: =G30/C30 -> 779510.67 | F30: =D30 -> %Fc | G30: =VLOOKUP(B30,BE!$B$5:$H$810,7,FALSE) -> 233853.2 | P30: =G30/$G$71 -> 0.00090343787
A31: 10 | B31: M.S reinforcement work including cutting, binding and fixing ( Assorted Size ) | C31: =VLOOKUP(B31,BE!$B$5:$C$459,2,FALSE) -> 11.427551 | D31: =VLOOKUP(B31,BE!$B$5:$E$810,4,FALSE) -> Ton | H31: =G31*1.3 -> 0 | I31: =ROUNDUP(H31,-4) -> 0 | K31: =I31 -> 0 | L31: =K31-J31 -> 0 | O31: =G31-N31 -> 0 | P31: =G31/$G$71 -> 0
B32: =BE!B317 -> Footing Rebar | C32: =VLOOKUP(B32,BE!$B$5:$C$459,2,FALSE) -> 1.1310672 | D32: =VLOOKUP(B32,BE!$B$5:$E$810,4,FALSE) -> Ton | E32: =G32/C32 -> 3070800.3 | F32: =D32 -> Ton | G32: =VLOOKUP(B32,BE!$B$5:$H$810,7,FALSE) -> 3473281.5 | H32: =G32*1.3 -> 4515265.9 | I32: =ROUNDUP(H32,-4) -> 4520000 | J32: =[4]AC!$L$42 -> 7590000 | K32: =I32 -> 4520000 | L32: =K32-J32 -> -3070000 | N32: =BE!H329 -> 3473281.5 | O32: =G32-N32 -> 0 | P32: =G32/$G$71 -> 0.013418221
B33: =BE!B331 -> Short Column Rebar | C33: =VLOOKUP(B33,BE!$B$5:$C$459,2,FALSE) -> 1.3135707 | D33: =VLOOKUP(B33,BE!$B$5:$E$810,4,FALSE) -> Ton | E33: =G33/C33 -> 3039977 | F33: =D33 -> Ton | G33: =VLOOKUP(B33,BE!$B$5:$H$810,7,FALSE) -> 3993224.6 | H33: =G33*1.3 -> 5191192 | I33: =ROUNDUP(H33,-4) -> 5200000 | J33: =[4]AC!$L$43 -> 4700000 | K33: =I33 -> 5200000 | L33: =K33-J33 -> 500000 | N33: =BE!H343 -> 3993224.6 | O33: =G33-N33 -> 0 | P33: =G33/$G$71 -> 0.015426902
B34: =BE!B345 -> Ground Floor Column Rebar | C34: =VLOOKUP(B34,BE!$B$5:$C$459,2,FALSE) -> 1.579814 | D34: =VLOOKUP(B34,BE!$B$5:$E$810,4,FALSE) -> Ton | E34: =G34/C34 -> 2996963.1 | F34: =D34 -> Ton | G34: =VLOOKUP(B34,BE!$B$5:$H$810,7,FALSE) -> 4734644.4 | H34: =G34*1.3 -> 6155037.8 | I34: =ROUNDUP(H34,-4) -> 6160000 | J34: =[4]AC!$L$44 -> 4360000 | K34: =I34 -> 6160000 | L34: =K34-J34 -> 1800000 | N34: =BE!H357 -> 4734644.4 | O34: =G34-N34 -> 0 | P34: =G34/$G$71 -> 0.018291206
B35: =BE!B359 -> Plinth Beam Rebar | C35: =VLOOKUP(B35,BE!$B$5:$C$459,2,FALSE) -> 2.1829889 | D35: =VLOOKUP(B35,BE!$B$5:$E$810,4,FALSE) -> Ton | E35: =G35/C35 -> 2907691.4 | F35: =D35 -> Ton | G35: =VLOOKUP(B35,BE!$B$5:$H$810,7,FALSE) -> 6347458.1 | H35: =G35*1.3 -> 8251695.5 | I35: =ROUNDUP(H35,-4) -> 8260000 | J35: =[4]AC!$L$46 -> 6580000 | K35: =I35 -> 8260000 | L35: =K35-J35 -> 1680000 | N35: =BE!H371 -> 6347458.1 | O35: =G35-N35 -> 0 | P35: =G35/$G$71 -> 0.024521939
B36: =BE!B373 -> Roof Beam Rebar | C36: =VLOOKUP(B36,BE!$B$5:$C$459,2,FALSE) -> 2.32908 | D36: =VLOOKUP(B36,BE!$B$5:$E$810,4,FALSE) -> Ton | E36: =G36/C36 -> 2911922.5 | F36: =D36 -> Ton | G36: =VLOOKUP(B36,BE!$B$5:$H$810,7,FALSE) -> 6782100.5 | H36: =G36*1.3 -> 8816730.6 | I36: =ROUNDUP(H36,-4) -> 8820000 | J36: =[4]AC!$L$47 -> 7000000 | K36: =I36 -> 8820000 | L36: =K36-J36 -> 1820000 | N36: =BE!H385 -> 6782100.5 | O36: =G36-N36 -> 0 | P36: =G36/$G$71 -> 0.02620108
B37: =BE!B387 -> Slab Rebar | C37: =VLOOKUP(B37,BE!$B$5:$C$459,2,FALSE) -> 2.3148202 | D37: =VLOOKUP(B37,BE!$B$5:$E$810,4,FALSE) -> Ton | E37: =G37/C37 -> 2577235.5 | F37: =D37 -> Ton | G37: =VLOOKUP(B37,BE!$B$5:$H$810,7,FALSE) -> 5965836.8 | H37: =G37*1.3 -> 7755587.8 | I37: =ROUNDUP(H37,-4) -> 7760000 | J37: =[4]AC!$L$51 -> 4360000 | K37: =I37 -> 7760000 | L37: =K37-J37 -> 3400000 | N37: =BE!H399 -> 5965836.8 | O37: =G37-N37 -> 0 | P37: =G37/$G$71 -> 0.023047634
B38: =BE!B401 -> Lintel & Stiffener Rebar | C38: =VLOOKUP(B38,BE!$B$5:$C$459,2,FALSE) -> 0.38549572 | D38: =VLOOKUP(B38,BE!$B$5:$E$810,4,FALSE) -> Ton | E38: =G38/C38 -> 2962117.2 | F38: =D38 -> Ton | G38: =VLOOKUP(B38,BE!$B$5:$H$810,7,FALSE) -> 1141883.5 | P38: =G38/$G$71 -> 0.0044114034
B39: =BE!B415 -> Sunshade Rebar | C39: =VLOOKUP(B39,BE!$B$5:$C$459,2,FALSE) -> 0.19071435 | D39: =VLOOKUP(B39,BE!$B$5:$E$810,4,FALSE) -> Ton | E39: =G39/C39 -> 2853945.3 | F39: =D39 -> Ton | G39: =VLOOKUP(B39,BE!$B$5:$H$810,7,FALSE) -> 544288.31 | P39: =G39/$G$71 -> 0.0021027323
A40: 11 | B40: =BE!B429 -> Curing Work for 14 Days | C40: =VLOOKUP(B40,BE!$B$5:$C$459,2,FALSE) -> 9.73 | D40: =VLOOKUP(B40,BE!$B$5:$E$810,4,FALSE) -> %Fs | E40: =G40/C40 -> 21780 | F40: =D40 -> %Fs | G40: =VLOOKUP(B40,BE!$B$5:$H$810,7,FALSE) -> 211919.4 | H40: =G40*1.3 -> 275495.22 | I40: =ROUNDUP(H40,-4) -> 280000 | J40: =[4]AC!$L$39 -> 2650000 | K40: =I40 -> 280000 | L40: =K40-J40 -> -2370000 | N40: =BE!H445 -> 928529.8 | O40: =G40-N40 -> -716610.4 | P40: =G40/$G$71 -> 0.0008187017
...

Sheet BQ
A1: =Detail!A1 -> One Storeyed RCC Building, Myat Lay Street
A2: =Detail!A2 -> 35'-0"x45'-0"x13'-0" Ht;
A3: Bill Of Quantities (Main Building)
A4: Sr. No. | B4: Particular | C4: Quantity | D4: Unit | E4: Rate | F4: Per | G4: Amount | H4: Remark
B5: Material Cost | I5: =G6-I6 -> #REF!
A6: 1 | B6: Cement | C6: =SUMIF(BE!$B$5:$B$810,B6,BE!$C$5:$C$810) -> 953.34 | D6: =VLOOKUP(B6,BE!$B$5:$E$810,4,FALSE) -> Bags | E6: =VLOOKUP(B6,'M&L Rate'!$B$7:$J$159,4,FALSE) -> 18600 | F6: =D6 -> Bags | G6: =E6*C6 -> 17732124 | H6: P-18, No.18 | I6: =BE!H159+BE!#REF!+BE!H188+BE!H202+BE!H231+BE!H245+BE!#REF!+BE!#REF!+BE!#REF!+BE!#REF!+BE!#REF!+BE!H260+BE!#REF!+BE!#REF!+BE!#REF!+BE!#REF!+BE!H437+BE!H450+BE!H462+BE!H489 -> #REF!
A7: 2 | B7: Sand | C7: =SUMIF(BE!$B$5:$B$810,B7,BE!$C$5:$C$810) -> 82.43 | D7: =VLOOKUP(B7,BE!$B$5:$E$810,4,FALSE) -> Sud | E7: =VLOOKUP(B7,'M&L Rate'!$B$7:$J$159,4,FALSE) -> 30000 | F7: =D7 -> Sud | G7: =E7*C7 -> 2472900 | H7: P-18, No.19
A8: 3 | B8: River Shingle | C8: =SUMIF(BE!$B$5:$B$810,B8,BE!$C$5:$C$810) -> 31.1 | D8: =VLOOKUP(B8,BE!$B$5:$E$810,4,FALSE) -> Sud | E8: =VLOOKUP(B8,'M&L Rate'!$B$7:$J$159,4,FALSE) -> 110000 | F8: =D8 -> Sud | G8: =E8*C8 -> 3421000 | H8: P-18, No.20 | J8: =#REF!+#REF!+#REF!+#REF! -> #REF!
A9: 4 | B9: 6"x9" Stone Boulder | C9: =SUMIF(BE!$B$5:$B$810,B9,BE!$C$5:$C$810) -> 2.34 | D9: =VLOOKUP(B9,BE!$B$5:$E$810,4,FALSE) -> Sud | E9: =VLOOKUP(B9,'M&L Rate'!$B$7:$J$159,4,FALSE) -> 230000 | F9: =D9 -> Sud | G9: =E9*C9 -> 538200 | H9: P-18, No.21 | J9: =#REF! -> #REF!
A10: 5 | B10: Fuel | C10: =SUMIF(BE!$B$5:$B$810,B10,BE!$C$5:$C$810) -> 62.44 | D10: =VLOOKUP(B10,BE!$B$5:$E$810,4,FALSE) -> Gal | E10: =VLOOKUP(B10,'M&L Rate'!$B$7:$J$159,4,FALSE) -> 18800 | F10: =D10 -> Gal | G10: =E10*C10 -> 1173872 | H10: P-18, No.22 | J10: =#REF! -> #REF!
A11: 6 | B11: Jungle Wood | C11: =SUMIF(BE!$B$5:$B$810,B11,BE!$C$5:$C$810) -> 9.904 | D11: =VLOOKUP(B11,BE!$B$5:$E$810,4,FALSE) -> Ton | E11: =VLOOKUP(B11,'M&L Rate'!$B$7:$J$159,4,FALSE) -> 1250000 | F11: =D11 -> Ton | G11: =E11*C11 -> 12380000 | H11: P-18, No.23 | I11: =G11+G12 -> 18270530 | J11: =I11*40% -> 7308212
A12: 7 | B12: 5 Ply Wood (8'x4') | C12: =SUMIF(BE!$B$5:$B$810,B12,BE!$C$5:$C$810) -> 85.37 | D12: =VLOOKUP(B12,BE!$B$5:$E$810,4,FALSE) -> Sheet | E12: =VLOOKUP(B12,'M&L Rate'!$B$7:$J$159,4,FALSE) -> 69000 | F12: =D12 -> Sheet | G12: =E12*C12 -> 5890530 | H12: P-18, No.24
A13: 8 | B13: Nails | C13: =SUMIF(BE!$B$5:$B$810,B13,BE!$C$5:$C$810) -> 101.61 | D13: =VLOOKUP(B13,BE!$B$5:$E$810,4,FALSE) -> viss | E13: =VLOOKUP(B13,'M&L Rate'!$B$7:$J$159,4,FALSE) -> 11600 | F13: =D13 -> viss | G13: =E13*C13 -> 1178676 | H13: P-18, No.25
A14: 9 | B14: Brick | C14: =SUMIF(BE!$B$5:$B$810,B14,BE!$C$5:$C$810) -> 38256 | D14: =VLOOKUP(B14,BE!$B$5:$E$810,4,FALSE) -> Nos | E14: =VLOOKUP(B14,'M&L Rate'!$B$7:$J$159,4,FALSE) -> 380 | F14: =D14 -> Nos | G14: =E14*C14 -> 14537280 | I14: =500/550 -> 0.90909091
A15: 10 | B15: Reinforcement X-met | C15: =SUMIF(BE!$B$5:$B$810,B15,BE!$C$5:$C$810) -> 3977.03 | D15: =VLOOKUP(B15,BE!$B$5:$E$810,4,FALSE) -> Rft | E15: =VLOOKUP(B15,'M&L Rate'!$B$7:$J$159,4,FALSE) -> 65 | F15: =D15 -> Rft | G15: =E15*C15 -> 258506.95 | H15: P-18, No.27
A16: 11 | B16: Sikament-9 | C16: =SUMIF(BE!$B$5:$B$810,B16,BE!$C$5:$C$810) -> 63.51 | D16: =VLOOKUP(B16,BE!$B$5:$E$810,4,FALSE) -> Lit | E16: =VLOOKUP(B16,'M&L Rate'!$B$7:$J$159,4,FALSE) -> 8500 | F16: =D16 -> Lit | G16: =E16*C16 -> 539835 | H16: P-18, No.28
A17: 12 | B17: Bonding Agent | C17: =SUMIF(BE!$B$5:$B$810,B17,BE!$C$5:$C$810) -> 3 | D17: =VLOOKUP(B17,BE!$B$5:$E$810,4,FALSE) -> Lit | E17: =VLOOKUP(B17,'M&L Rate'!$B$7:$J$159,4,FALSE) -> 17000 | F17: =D17 -> Lit | G17: =E17*C17 -> 51000 | H17: P-18, No.29
A18: 13 | B18: Plastic Sheet | C18: =SUMIF(BE!$B$5:$B$810,B18,BE!$C$5:$C$810) -> 297.46 | D18: =VLOOKUP(B18,BE!$B$5:$E$810,4,FALSE) -> Rft | E18: =VLOOKUP(B18,'M&L Rate'!$B$7:$J$159,4,FALSE) -> 1200 | F18: =D18 -> Rft | G18: =E18*C18 -> 356952 | H18: P-18, No.31 | K18: =#REF!/3.6 -> #REF!
A19: 14 | B19: =BE!B502 -> Plaster Fibre Mesh | C19: =SUMIF(BE!$B$5:$B$810,B19,BE!$C$5:$C$810) -> 6 | D19: =VLOOKUP(B19,BE!$B$5:$E$810,4,FALSE) -> Coil | E19: =VLOOKUP(B19,'M&L Rate'!$B$7:$J$159,4,FALSE) -> 100000 | F19: =D19 -> Coil | G19: =E19*C19 -> 600000 | K19: =K18/30 -> #REF!
A20: 15 | B20: =BE!B319 -> Ø16mm (1.58 Kg/m)(⅝") | C20: =SUMIF(BE!$B$5:$B$810,B20,BE!$C$5:$C$810) -> 6.4567644 | D20: =VLOOKUP(B20,BE!$B$5:$E$810,4,FALSE) -> Ton | E20: =VLOOKUP(B20,'M&L Rate'!$B$7:$J$159,4,FALSE) -> 2130000 | F20: =D20 -> Ton | G20: =E20*C20 -> 13752908 | H20: P-18, No.33
A21: 16 | B21: =BE!B320 -> Ø12mm (0.89Kg/m)(½") | C21: =SUMIF(BE!$B$5:$B$810,B21,BE!$C$5:$C$810) -> 0.17745233 | D21: =VLOOKUP(B21,BE!$B$5:$E$810,4,FALSE) -> Ton | E21: =VLOOKUP(B21,'M&L Rate'!$B$7:$J$159,4,FALSE) -> 1930000 | F21: =D21 -> Ton | G21: =E21*C21 -> 342483 | H21: P-18, No.34
A22: 17 | B22: =BE!B321 -> Ø10mm (0.62 Kg/m)(⅜") | C22: =SUMIF(BE!$B$5:$B$810,B22,BE!$C$5:$C$810) -> 5.0567239 | D22: =VLOOKUP(B22,BE!$B$5:$E$810,4,FALSE) -> Ton | E22: =VLOOKUP(B22,'M&L Rate'!$B$7:$J$159,4,FALSE) -> 1640000 | F22: =D22 -> Ton | G22: =E22*C22 -> 8293027.3 | H22: P-18, No.35
A23: 18 | B23: =BE!B406 -> Ø6.5mm (0.26 Kg/m)(¼") | C23: =SUMIF(BE!$B$5:$B$810,B23,BE!$C$5:$C$810) -> 0.30798791 | D23: =VLOOKUP(B23,BE!$B$5:$E$810,4,FALSE) -> Ton | E23: =VLOOKUP(B23,'M&L Rate'!$B$7:$J$159,4,FALSE) -> 3450000 | F23: =D23 -> Ton | G23: =E23*C23 -> 1062558.3
A24: 19 | B24: Binding Wire | C24: =SUMIF(BE!$B$5:$B$810,B24,BE!$C$5:$C$810) -> 74.780714 | D24: =VLOOKUP(B24,BE!$B$5:$E$810,4,FALSE) -> Viss | E24: =VLOOKUP(B24,'M&L Rate'!$B$7:$J$159,4,FALSE) -> 9200 | F24: =D24 -> Viss | G24: =E24*C24 -> 687982.57 | H24: P-18, No.36
A25: 20 | B25: Putty | C25: =SUMIF(BE!$B$5:$B$810,B25,BE!$C$5:$C$810) -> 37 | D25: =VLOOKUP(B25,BE!$B$5:$E$810,4,FALSE) -> Bags | E25: =VLOOKUP(B25,'M&L Rate'!$B$7:$J$159,4,FALSE) -> 24000 | F25: =D25 -> Bags | G25: =E25*C25 -> 888000
A26: 21 | B26: Sealer | C26: =SUMIF(BE!$B$5:$B$810,B26,BE!$C$5:$C$810) -> 28.73 | D26: =VLOOKUP(B26,BE!$B$5:$E$810,4,FALSE) -> Gal | E26: =VLOOKUP(B26,'M&L Rate'!$B$7:$J$159,4,FALSE) -> 130200 | F26: =D26 -> Gal | G26: =E26*C26 -> 3740646
A27: 22 | B27: Sand Paper | C27: =SUMIF(BE!$B$5:$B$810,B27,BE!$C$5:$C$810) -> 34.38 | D27: =VLOOKUP(B27,BE!$B$5:$E$810,4,FALSE) -> Doz | E27: =VLOOKUP(B27,'M&L Rate'!$B$7:$J$159,4,FALSE) -> 21600 | F27: =D27 -> Doz | G27: =E27*C27 -> 742608
A28: 23 | B28: Putty Towel | C28: =SUMIF(BE!$B$5:$B$810,B28,BE!$C$5:$C$810) -> 28.73 | D28: =VLOOKUP(B28,BE!$B$5:$E$810,4,FALSE) -> Nos. | E28: =VLOOKUP(B28,'M&L Rate'!$B$7:$J$159,4,FALSE) -> 2000 | F28: =D28 -> Nos. | G28: =E28*C28 -> 57460
A29: 24 | B29: Emulsion Paint | C29: =SUMIF(BE!$B$5:$B$810,B29,BE!$C$5:$C$810) -> 46.16 | D29: =VLOOKUP(B29,BE!$B$5:$E$810,4,FALSE) -> Gal | E29: =VLOOKUP(B29,'M&L Rate'!$B$7:$J$159,4,FALSE) -> 109000 | F29: =D29 -> Gal | G29: =E29*C29 -> 5031440
A30: 25 | B30: Roller | C30: =SUMIF(BE!$B$5:$B$810,B30,BE!$C$5:$C$810) -> 35.03 | D30: =VLOOKUP(B30,BE!$B$5:$E$810,4,FALSE) -> Nos. | E30: =VLOOKUP(B30,'M&L Rate'!$B$7:$J$159,4,FALSE) -> 7500 | F30: =D30 -> Nos. | G30: =E30*C30 -> 262725
A31: 26 | B31: T Rental Charges | C31: =SUMIF(BE!$B$5:$B$810,B31,BE!$C$5:$C$810) -> 185.5 | D31: =VLOOKUP(B31,BE!$B$5:$E$810,4,FALSE) -> Nos. | E31: =VLOOKUP(B31,'M&L Rate'!$B$7:$J$159,4,FALSE) -> 90 | F31: =D31 -> Nos. | G31: =E31*C31 -> 16695
A32: 27 | B32: Concrete Nail | C32: =SUMIF(BE!$B$5:$B$810,B32,BE!$C$5:$C$810) -> 12.37 | D32: =VLOOKUP(B32,BE!$B$5:$E$810,4,FALSE) -> Box | E32: =VLOOKUP(B32,'M&L Rate'!$B$7:$J$159,4,FALSE) -> 8500 | F32: =D32 -> Box | G32: =E32*C32 -> 105145
A33: 28 | B33: Bamboo | C33: =SUMIF(BE!$B$5:$B$810,B33,BE!$C$5:$C$810) -> 406.67 | D33: =VLOOKUP(B33,BE!$B$5:$E$810,4,FALSE) -> Nos. | E33: =VLOOKUP(B33,'M&L Rate'!$B$7:$J$159,4,FALSE) -> 1750 | F33: =D33 -> Nos. | G33: =E33*C33 -> 711672.5 | H33: P-18, No.37
A34: 29 | B34: Coir Yarn | C34: =SUMIF(BE!$B$5:$B$810,B34,BE!$C$5:$C$810) -> 29.23 | D34: =VLOOKUP(B34,BE!$B$5:$E$810,4,FALSE) -> Viss | E34: =VLOOKUP(B34,'M&L Rate'!$B$7:$J$159,4,FALSE) -> 16000 | F34: =D34 -> Viss | G34: =E34*C34 -> 467680 | H34: P-18, No.38
A35: 30 | B35: 4"x2" Hollow (1.4mm thk;) | C35: =SUMIF(BE!$B$5:$B$810,B35,BE!$C$5:$C$810) -> 55 | D35: =VLOOKUP(B35,BE!$B$5:$E$810,4,FALSE) -> Nos. | E35: =VLOOKUP(B35,'M&L Rate'!$B$7:$J$159,4,FALSE) -> 61500 | F35: =D35 -> Nos. | G35: =E35*C35 -> 3382500 | I35: =C35/20 -> 2.75
A36: 31 | B36: 3"x1½" Hollow (1.2mm thk;) | C36: =SUMIF(BE!$B$5:$B$810,B36,BE!$C$5:$C$810) -> 67 | D36: =VLOOKUP(B36,BE!$B$5:$E$810,4,FALSE) -> Nos. | E36: =VLOOKUP(B36,'M&L Rate'!$B$7:$J$159,4,FALSE) -> 45000 | F36: =D36 -> Nos. | G36: =E36*C36 -> 3015000 | I36: =C36/20 -> 3.35
A37: 32 | B37: 2"x2" Angle | C37: =SUMIF(BE!$B$5:$B$810,B37,BE!$C$5:$C$810) -> 2 | D37: =VLOOKUP(B37,BE!$B$5:$E$810,4,FALSE) -> Nos. | E37: =VLOOKUP(B37,'M&L Rate'!$B$7:$J$159,4,FALSE) -> 57000 | F37: =D37 -> Nos. | G37: =E37*C37 -> 114000
A38: 33 | B38: No.12 Welding Rod | C38: =SUMIF(BE!$B$5:$B$810,B38,BE!$C$5:$C$810) -> 24 | D38: =VLOOKUP(B38,BE!$B$5:$E$810,4,FALSE) -> Pkt. | E38: =VLOOKUP(B38,'M&L Rate'!$B$7:$J$159,4,FALSE) -> 27000 | F38: =D38 -> Pkt. | G38: =E38*C38 -> 648000
A39: 34 | B39: 4" Cutting Wheel | C39: =SUMIF(BE!$B$5:$B$810,B39,BE!$C$5:$C$810) -> 156 | D39: =VLOOKUP(B39,BE!$B$5:$E$810,4,FALSE) -> Nos. | E39: =VLOOKUP(B39,'M&L Rate'!$B$7:$J$159,4,FALSE) -> 2000 | F39: =D39 -> Nos. | G39: =E39*C39 -> 312000
A40: 35 | B40: 4" Grinder Wheel | C40: =SUMIF(BE!$B$5:$B$810,B40,BE!$C$5:$C$810) -> 16 | D40: =VLOOKUP(B40,BE!$B$5:$E$810,4,FALSE) -> Nos. | E40: =VLOOKUP(B40,'M&L Rate'!$B$7:$J$159,4,FALSE) -> 7400 | F40: =D40 -> Nos. | G40: =E40*C40 -> 118400
...

Sheet BE
A1: =Detail!A1 -> One Storeyed RCC Building, Myat Lay Street
A2: =Detail!A2 -> 35'-0"x45'-0"x13'-0" Ht;
A3: Builder's Estimate
A4: No | B4: Particular | C4: Quantity | E4: Unit | F4: Rate(Kyats) | G4: Per | H4: Amount(Ks) | I4: Material | J4: Labour
A5: 1 | B5: Site Clearing | C5: =ROUND(D5,2) -> 24.75 | D5: =Detail!K11 -> 24.75 | E5: %Fs | H5: =H8 -> 134818.2
B6: Labour
B7: Worker | C7: =ROUND(D7,2) -> 6.19 | D7: =D5*0.25 -> 6.1875 | E7: No | F7: =VLOOKUP(B7,BQ!$B$6:$E$120,4,FALSE) -> 21780 | G7: No | H7: =F7*C7 -> 134818.2 | J7: =H7 -> 134818.2
F8: Total | G8: = | H8: =SUM(H7) -> 134818.2
A10: 2 | B10: Surveying & Levelling Work | C10: =ROUND(D10,2) -> 15.75 | D10: =Detail!K16 -> 15.75 | E10: %Fs | H10: =H20 -> 96977.9
B11: Material
B12: Jungle Wood | C12: =ROUND(D12,3) -> 0.024 | D12: =(C10/100*30/50/4) -> 0.023625 | E12: Ton | F12: =VLOOKUP(B12,BQ!$B$6:$E$111,4,FALSE) -> 1250000 | G12: No | H12: =F12*C12 -> 30000 | I12: =H12 -> 30000
B13: Nails | C13: =ROUND(D13,2) -> 0.33 | D13: =(C10/100*7.5)/3.6 -> 0.328125 | E13: viss | F13: =VLOOKUP(B13,BQ!$B$6:$E$111,4,FALSE) -> 11600 | G13: No | H13: =F13*C13 -> 3828 | I13: =H13 -> 3828
H14: =SUM(H12:H13) -> 33828
B15: Labour
B16: Surveyor | C16: =ROUND(D16,2) -> 0.16 | D16: =C10/100*1 -> 0.1575 | E16: No | F16: =VLOOKUP(B16,BQ!$B$6:$E$120,4,FALSE) -> 30250 | G16: No | H16: =F16*C16 -> 4840 | J16: =H16 -> 4840
B17: Carpenter | C17: =ROUND(D17,2) -> 0.79 | D17: =C10/100*5 -> 0.7875 | E17: No | F17: =VLOOKUP(B17,BQ!$B$6:$E$120,4,FALSE) -> 30250 | G17: No | H17: =F17*C17 -> 23897.5 | J17: =H17 -> 23897.5
B18: Worker | C18: =ROUND(D18,2) -> 1.58 | D18: =D10/100*10 -> 1.575 | E18: No | F18: =VLOOKUP(B18,BQ!$B$6:$E$120,4,FALSE) -> 21780 | G18: No | H18: =F18*C18 -> 34412.4 | J18: =H18 -> 34412.4
H19: =SUM(H16:H18) -> 63149.9
F20: Total | G20: = | H20: =H19+H14 -> 96977.9
A22: 3 | B22: Earthwork Excavation for foundation in medium soil | C22: =ROUND(D22,2) -> 56.07 | D22: =Detail!K43 -> 56.07123 | E22: %Fc | H22: =H25 -> 2442409.2
B23: Labour
B24: Worker | C24: =ROUND(D24,2) -> 112.14 | D24: =C22*2 -> 112.14 | E24: No | F24: =VLOOKUP(B24,BQ!$B$6:$E$120,4,FALSE) -> 21780 | G24: No | H24: =F24*C24 -> 2442409.2 | J24: =H24 -> 2442409.2
F25: Total | G25: = | H25: =SUM(H23:H24) -> 2442409.2
D26: =D39+D51+D63+D75+D87+D99+D111+D123+D135 -> 71.269812
A27: 4 | B27: Timber shuttering Formwork (3 Times) | C27: =ROUND(D27,2) -> 71.27 | D27: =Detail!K178 -> 71.269812 | E27: %Fs | H27: =H49+H61+H73+H85+H97+H109+H121+H133+H145 -> 34989192
B28: Material
B29: Jungle Wood | C29: =ROUND(D29,2) -> 0 | E29: Ton | F29: =VLOOKUP(B29,BQ!$B$6:$E$111,4,FALSE) -> 1250000 | G29: Ton | H29: =F29*C29 -> 0 | I29: =H29 -> 0
B30: 5 Ply Wood (8'x4') | C30: =ROUND(D30,2) -> 0 | E30: Sheet | F30: =VLOOKUP(B30,BQ!$B$6:$E$111,4,FALSE) -> 69000 | G30: Sheet | H30: =F30*C30 -> 0 | I30: =H30 -> 0
B31: Nails | C31: =ROUND(D31,2) -> 0 | E31: Viss | F31: =VLOOKUP(B31,BQ!$B$6:$E$111,4,FALSE) -> 11600 | G31: Viss | H31: =F31*C31 -> 0 | I31: =H31 -> 0
H32: =SUM(H29:H31) -> 0
B33: Labour
B34: Carpenter | C34: =ROUND(D34,2) -> 0 | E34: No | F34: =VLOOKUP(B34,BQ!$B$6:$E$120,4,FALSE) -> 30250 | G34: No | H34: =F34*C34 -> 0 | J34: =H34 -> 0
B35: Worker | C35: =ROUND(D35,2) -> 0 | E35: No | F35: =VLOOKUP(B35,BQ!$B$6:$E$120,4,FALSE) -> 21780 | G35: No | H35: =F35*C35 -> 0 | J35: =H35 -> 0
H36: =SUM(H34:H35) -> 0
F37: Total | G37: = | H37: =H36+H32 -> 0
B39: Footing Formwork | C39: =ROUND(D39,2) -> 4.4 | D39: =(Detail!K52+Detail!K76)/100 -> 4.401 | E39: %Fs | H39: =H49 -> 2163964.5
B40: Material
B41: Jungle Wood | C41: =ROUND(D41,2) -> 0.59 | D41: =(D39*20/50/3) -> 0.5868 | E41: Ton | F41: =VLOOKUP(B41,BQ!$B$6:$E$111,4,FALSE) -> 1250000 | G41: Ton | H41: =F41*C41 -> 737500 | I41: =H41 -> 737500
B42: 5 Ply Wood (8'x4') | C42: =ROUND(D42,2) -> 5.27 | D42: =D39*115/32/3 -> 5.2720312 | E42: Sheet | F42: =VLOOKUP(B42,BQ!$B$6:$E$111,4,FALSE) -> 69000 | G42: Sheet | H42: =F42*C42 -> 363630 | I42: =H42 -> 363630
B43: Nails | C43: =ROUND(D43,2) -> 6.23 | D43: =((D39*3)/3.6)*1.7 -> 6.23475 | E43: Viss | F43: =VLOOKUP(B43,BQ!$B$6:$E$111,4,FALSE) -> 11600 | G43: Viss | H43: =F43*C43 -> 72268 | I43: =H43 -> 72268
...

Sheet Price
A1: 119'-0" x 79'-0" x 71' -5"(8 Unit 6 Storyed)
A2: PRICE
A3: No | B3: Particular | C3: Unit | D3: Original
A4: 1 | B4: Cement | C4: Bag | D4: 5390
A5: 2 | B5: R/Sand | C5: Sud | D5: 12000
A6: 3 | B6: RSA | C6: Sud | D6: 35500
A7: 4 | B7: Jungle Wood | C7: Ton | D7: 680000
A8: 5 | B8: 5 Ply Wood ( 8'x4' ) | C8: Sht | D8: 20000 | F8: =23*110 -> 2530 | G8: =5.5*5 -> 27.5
A9: 6 | B9: Nails | C9: lb | D9: 700 | G9: =G8/7 -> 3.9285714 | H9: 90
A10: 9 | B10: Brick | C10: No | D10: 90
A11: 10 | B11: Reinforcement ( X met 2½ wide ) | C11: Rft | D11: 85
A12: 12 | B12: Ø25 mm MS Rod | C12: Ton | D12: 750000
A13: 13 | B13: Ø20 mm MS Rod | C13: Ton | D13: 750000
A14: 14 | B14: Ø18 mm MS Rod | C14: Ton | D14: 750000
A15: 15 | B15: Ø16 mm MS Rod | C15: Ton | D15: 750000
A16: 16 | B16: Ø12mm MS Rod | C16: Ton | D16: 750000
A17: 17 | B17: Ø10mm MS Rod | C17: Ton | D17: 750000
A18: 18 | B18: Ø6.5mm MS Rod | C18: Ton | D18: 850000
A19: 19 | B19: Binding Wire | C19: Lbs | D19: 1400
A20: 20 | B20: Putty | C20: Gal | D20: 5500
A21: 21 | B21: Sand Paper | C21: Doz | D21: 3600
... A52: 52 | B52: Teak Door including painting | C52: Sft | D52: 8000
A53: 53 | B53: Timber Louver Door | C53: Sft
A54: 54 | B54: Aluminium Window (M+L) | C54: Sft | D54: 5500
A55: 55 | B55: Aluminium Louver Window (M+L) | C55: Sft | D55: 4500
A56: 56 | B56: Iron Grille Work (M+L) | C56: Sft
A57: 57 | B57: Shera Board Ceiling ( Including Painting ) | C57: Sft
A58: 58 | B58: Steel Handrail (M+L) | C58: Sft | D58: 3000
A59: No | B59: Particular | C59: Unit | D59: Rate( Kyats )
B60: Labour
A61: 1 | B61: Mason | C61: No | D61: 5500
A62: 2 | B62: Surveyor | C62: No | D62: 5500
A63: 3 | B63: Carpenter | C63: No | D63: 5500
A64: 4 | B64: Painter | C64: No | D64: 5500
A65: 6 | B65: Worker | C65: No | D65: 4500

Sheet Sheet2
E12: =11.81*40 -> 472.4 | F12: 5000 | G12: =F12*E12 -> 2362000
E13: =22.97*40 -> 918.8 | F13: 4500 | G13: =F13*E13 -> 4134600
E14: =34.13*80 -> 2730.4 | F14: 5800 | G14: =F14*E14 -> 15836320
E15: =40*11.81 -> 472.4 | F15: 4500 | G15: =F15*E15 -> 2125800
E16: =SUM(E12:E15) -> 4594 | G16: =SUM(G12:G15) -> 24458720 | I16: =24000000+6279030+2000000 -> 32279030
I17: =I16*0.07 -> 2259532.1
E18: =E16-4200 -> 394
E19: =E18*5800 -> 2285200

Sheet Sheet3
A1: rdw¬Dvmc&dkif? 0rf;wGif;jrdKU (4)cef;wGJ(3)xyf
A2: =#REF! -> #REF!
A3: Labour Cost
A4: No | B4: Particular | C4: Labour Cost | F4: PAE
A5: 1 | B5: Main Building | C5: 146085795
A6: 2 | B6: Pump House | C6: 127121
A7: 3 | B7: Apron & Drain | C7: 1634960
A8: 4 | B8: Ground Tank (8000 Gals) | C8: 1058270
A9: 5 | B9: Septic Tank (For 200 persons) | C9: 743480
B10: Total | C10: =SUM(C5:C9) -> 149649626
J11: =10/1.5 -> 6.6666667
B14: =#REF!+#REF!+C5 -> #REF!
C15: =B14/27625 -> #REF!
E16: =31*14*2 -> 868

Sheet Sheet4
A1: 12 | B1: 4½ thk; Brick Work in (1:3) Cement Mortar
B2: Ground Floor
B3: Line A to K | E3: 11 | F3: =48-5*1 -> 43 | H3: =11.25-1.17 -> 10.08 | J3: =H3*F3*E3 -> 4767.84
B4: Line 2,7 | E4: 2 | F4: =(12.25*8)-(8*1) -> 90 | H4: =11.25-1.17 -> 10.08 | J4: =H4*F4*E4 -> 1814.4 | K4: =48-(5*1.17) -> 42.15 | L4: =2*42.15*9 -> 758.7 | M4: =L4-292.68 -> 466.02
B5: Line 3,6 | D5: 2 | E5: 4 | F5: =12.25-(4*1) -> 8.25 | H5: =11.25-1.17 -> 10.08 | J5: =H5*F5*E5*D5 -> 665.28 | L5: =4*42.15*9 -> 1517.4 | M5: =L5-355.04-104.93 -> 1057.43
B6: Bet Line 4 & 5 | E6: 4 | F6: =12.25 -> 12.25 | H6: =11.25-1.17 -> 10.08 | J6: =H6*F6*E6 -> 493.92 | K6: =48-(4*1.17)-7 -> 36.32 | L6: =K6*4*9 -> 1307.52 | M6: =L6-104.93 -> 1202.59
E7: 4 | F7: 6 | H7: =11.25-1.17 -> 10.08 | J7: =H7*F7*E7 -> 241.92 | K7: =48-(5*1.17) -> 42.15 | L7: =K7*9 -> 379.35
B8: Bet Line 7 & 8 | E8: 2 | F8: 8.5 | H8: =11.25-1.17 -> 10.08 | J8: =H8*F8*E8 -> 171.36 | K8: =115-(8.5*2)-(8*1.17) -> 88.64 | L8: =K8*2*9 -> 1595.52 | M8: =L8-292.68-198.59-157.68 -> 946.57
B9: Stair area | E9: 4 | F9: =6+6.25+6.25 -> 18.5 | H9: =11.25-1.17 -> 10.08 | J9: =H9*F9*E9 -> 745.92 | K9: =(12.25-1.17)*4 -> 44.32 | L9: =K9*2*9 -> 797.76
B10: Bath & W.C | E10: 8 | F10: =4+8+8 -> 20 | H10: =11.25-1.17 -> 10.08 | J10: =H10*F10*E10 -> 1612.8 | K10: =(12.25*4+24)-(6*4.5/12) -> 70.75 | L10: =K10*9 -> 636.75
B11: Varendah | E11: 8 | F11: =3+3 -> 6 | H11: 3 | J11: =H11*F11*E11 -> 144
B12: Deduction
B13: D1 | C13: -1 | D13: 4 | E13: 8 | F13: 6.75 | H13: 2.75 | J13: =H13*F13*E13*D13*C13 -> -594
B14: D2 | C14: -1 | D14: 1 | E14: 8 | F14: 6.5 | H14: 2.5 | J14: =H14*F14*E14*D14*C14 -> -130
B15: W1 | D15: -1 | E15: 8 | F15: 5 | H15: 2 | J15: =H15*F15*E15*D15 -> -80
B16: W2 | D16: -1 | E16: 8 | F16: 4 | H16: 5 | J16: =H16*F16*E16*D16 -> -160
B17: W3 | D17: -1 | E17: 16 | F17: 6 | H17: 5 | J17: =H17*F17*E17*D17 -> -480
B18: W4 | D18: -1 | E18: 8 | F18: 2 | H18: 5 | J18: =H18*F18*E18*D18 -> -80
J19: =SUM(J3:J18) -> 9133.44
B21: Ground Floor
B22: Line A to K | D22: 4 | E22: 11 | F22: =48-5*1 -> 43 | H22: =10-1 -> 9 | J22: =H22*F22*E22*D22 -> 17028 | L22: =91.33+320.28 -> 411.61
B23: Line 2,7 | D23: 4 | E23: 2 | F23: =(12.25*8)-(8*1) -> 90 | H23: =10-1 -> 9 | J23: =H23*F23*E23*D23 -> 6480
B24: Line 3,6 | C24: 4 | D24: 2 | E24: 4 | F24: =12.25-(4*1) -> 8.25 | H24: =10-1 -> 9 | J24: =H24*F24*E24*D24*C24 -> 2376
B25: Bet Line 4 & 5 | D25: 4 | E25: 4 | F25: =12.25 -> 12.25 | H25: =10-1 -> 9 | J25: =H25*F25*E25*D25 -> 1764
D26: 4 | E26: 4 | F26: 6 | H26: =10-1 -> 9 | J26: =H26*F26*E26*D26 -> 864
B27: Bet Line 7 & 8 | D27: 4 | E27: 2 | F27: 8.5 | H27: =10-1 -> 9 | J27: =H27*F27*E27*D27 -> 612
B28: Stair area | D28: 4 | E28: 4 | F28: =6+6.25+6.25 -> 18.5 | H28: =10-1 -> 9 | J28: =H28*F28*E28*D28 -> 2664
B29: Bath & W.C | D29: 4 | E29: 8 | F29: =4+8+8 -> 20 | H29: =10-1 -> 9 | J29: =H29*F29*E29*D29 -> 5760
B30: Varendah | D30: 4 | E30: 8 | F30: =3+3 -> 6 | H30: 3 | J30: =H30*F30*E30*D30 -> 576
B31: Deduction
B32: D1 | C32: -4 | D32: 4 | E32: 8 | F32: 6.75 | H32: 2.75 | J32: =H32*F32*E32*D32*C32 -> -2376
B33: D2 | C33: -4 | D33: 1 | E33: 8 | F33: 6.5 | H33: 2.5 | J33: =H33*F33*E33*D33*C33 -> -520 | N33: =2417000/300 -> 8056.6667
B34: W1 | D34: -4 | E34: 8 | F34: 5 | H34: 2 | J34: =H34*F34*E34*D34 -> -320
B35: W2 | D35: -4 | E35: 8 | F35: 4 | H35: 5 | J35: =H35*F35*E35*D35 -> -640
B36: W3 | D36: -4 | E36: 16 | F36: 6 | H36: 5 | J36: =H36*F36*E36*D36 -> -1920
B37: W4 | D37: -4 | E37: 8 | F37: 2 | H37: 5 | J37: =H37*F37*E37*D37 -> -320
J38: =SUM(J22:J37) -> 32028 | L38: =J38+J19 -> 41161.44 | N38: =420*42000 -> 17640000
J39: =J38/4 -> 8007 | L39: =L38/100 -> 411.6144
B48: First Floor to Fourth
B49: Line A to K | D49: 4 | E49: 11 | F49: =48-5*1 -> 43 | H49: =10-1.17 -> 8.83 | J49: =H49*F49*E49*D49 -> 16706.36
...

Sheet Sheet5
A1: rdw¬Dvmc&dkif? 0rf;wGif;jrdKU (4)cef;wGJ(3)xyf
A2: =BE!A2:H2 -> 35'-0"x45'-0"x13'-0" Ht;
A3: Bill of Quantities RC Work ( Materials )
A4: No | B4: Particular | C4: Unit | D4: Quantity | E4: Rate( Kyats ) | F4: Per | G4: Amount(Ks)
A5: 1 | B5: Cement | C5: Bag | D5: =BE!#REF! -> #REF! | E5: =BE!#REF! -> #REF! | F5: Bag | G5: =D5*E5 -> #REF!
A6: 2 | B6: R/Sand | C6: Sud | D6: =BE!#REF! -> #REF! | E6: =BE!#REF! -> #REF! | F6: Sud | G6: =D6*E6 -> #REF!
A7: 3 | B7: RSA | C7: Sud | D7: =BE!#REF! -> #REF! | E7: =BE!#REF! -> #REF! | F7: Sud | G7: =D7*E7 -> #REF!
A8: 4 | B8: Jungle Wood | C8: Ton | D8: =BE!#REF! -> #REF! | E8: =BE!#REF! -> #REF! | F8: Ton | G8: =D8*E8 -> #REF!
A9: 5 | B9: 5 Ply Wood ( 8'x4' ) | C9: Sht | D9: =BE!#REF! -> #REF! | E9: =BE!F30 -> 69000 | F9: Sht | G9: =D9*E9 -> #REF!
A10: 6 | B10: Nails | C10: lb | D10: =BE!#REF! -> #REF! | E10: =BE!F31 -> 11600 | F10: lb | G10: =D10*E10 -> #REF!
A11: 7 | B11: Earth Oil | C11: Gal | D11: =BE!#REF! -> #REF! | E11: =BE!#REF! -> #REF! | F11: Gal | G11: =D11*E11 -> #REF!
A12: 8 | B12: Brick | C12: No | D12: =BE!#REF! -> #REF! | E12: =BE!#REF! -> #REF! | F12: No | G12: =D12*E12 -> #REF!
A13: 9 | B13: Stone Boulder | C13: Sud | D13: =BE!#REF! -> #REF! | E13: =BE!#REF! -> #REF! | F13: Sud | G13: =D13*E13 -> #REF!
A14: 10 | B14: Ø20 mm MS Rod | C14: Ton | D14: =BE!#REF! -> #REF! | E14: =BE!#REF! -> #REF! | F14: Ton | G14: =D14*E14 -> #REF!
A15: 11 | B15: Ø18 mm MS Rod | C15: Ton | D15: =BE!#REF! -> #REF! | E15: =BE!#REF! -> #REF! | F15: Ton | G15: =D15*E15 -> #REF!
A16: 11 | B16: Ø16mm MS Rod | C16: Ton | D16: =BE!#REF! -> #REF! | E16: =BE!#REF! -> #REF! | F16: Ton | G16: =D16*E16 -> #REF!
A17: 12 | B17: Ø12mm MS Rod | C17: Ton | D17: =BE!#REF! -> #REF! | E17: =BE!#REF! -> #REF! | F17: Ton | G17: =D17*E17 -> #REF!
A18: 13 | B18: Ø10mm MS Rod | C18: Ton | D18: =BE!#REF! -> #REF! | E18: =BE!#REF! -> #REF! | F18: Ton | G18: =D18*E18 -> #REF!
A19: 14 | B19: Ø8mm MS Rod | C19: Ton | D19: =BE!#REF! -> #REF! | E19: =BE!#REF! -> #REF! | F19: Ton | G19: =D19*E19 -> #REF!
A20: 15 | B20: Ø6mm MS Rod | C20: Ton | D20: =BE!#REF! -> #REF! | E20: =BE!#REF! -> #REF! | F20: Ton | G20: =D20*E20 -> #REF!
A21: 16 | B21: Binding Wire | C21: Lbs | D21: =BE!#REF! -> #REF! | E21: =BE!#REF! -> #REF! | F21: Lbs | G21: =D21*E21 -> #REF!
A22: 17 | B22: Reinforcement ( X met 2½ wide ) | C22: Rft | D22: =BE!#REF! -> #REF! | E22: =BE!#REF! -> #REF! | F22: Rft | G22: =D22*E22 -> #REF!
... A31: 27 | B31: 4"x4" Glazes Tile ( Malay ) | C31: Sht | D31: =BE!#REF! -> #REF! | E31: =BE!#REF! -> #REF! | F31: Sht | G31: =D31*E31 -> #REF!
A32: 28 | B32: White Cement | C32: Lbs | D32: =BE!#REF!+BE!#REF! -> #REF! | E32: =BE!#REF! -> #REF! | F32: Lbs | G32: =D32*E32 -> #REF!
A33: 29 | B33: Acid | C33: Bottle | D33: =BE!#REF!+BE!#REF! -> #REF! | E33: =BE!#REF! -> #REF! | F33: Bottle | G33: =D33*E33 -> #REF!
A34: 30 | B34: Corner Beat | C34: Rft | D34: =BE!#REF!+BE!#REF! -> #REF! | E34: =BE!#REF! -> #REF! | F34: Rft | G34: =D34*E34 -> #REF!
A35: 31 | B35: 12mm thk M.S Plate | C35: Ton | D35: =BE!#REF! -> #REF! | E35: =BE!#REF! -> #REF! | F35: Ton | G35: =D35*E35 -> #REF!
A36: 31 | B36: =BE!#REF! -> #REF! | C36: M | D36: =BE!#REF! -> #REF! | E36: =BE!#REF! -> #REF! | F36: M | G36: =D36*E36 -> #REF!
A37: 32 | B37: M 20 Hight Strength Bolt & Nut | C37: No | D37: =BE!#REF! -> #REF! | E37: =BE!#REF! -> #REF! | F37: No | G37: =D37*E37 -> #REF!
A38: 33 | B38: Red Oxide Painting | C38: Gal | D38: =BE!#REF! -> #REF! | E38: =BE!#REF! -> #REF! | F38: Gal | G38: =D38*E38 -> #REF!
A39: 34 | B39: 3" x 1½" Purlin | C39: Ft | D39: =BE!#REF! -> #REF! | E39: =BE!#REF! -> #REF! | F39: Ft | G39: =D39*E39 -> #REF!
A40: 35 | B40: 4 Angle Metal Sheet Roofing | C40: Rft | D40: =BE!#REF! -> #REF! | E40: =BE!#REF! -> #REF! | F40: Rft | G40: =D40*E40 -> #REF!
A41: 36 | B41: Roofing Screw | C41: No | D41: =BE!#REF! -> #REF! | E41: =BE!#REF! -> #REF! | F41: No | G41: =D41*E41 -> #REF!
A42: 37 | B42: Ridging | C42: Rft | D42: =BE!#REF! -> #REF! | E42: =BE!#REF! -> #REF! | F42: Rft | G42: =D42*E42 -> #REF!
A43: 38 | B43: GI Plain Sheet 28G (3' wide) for Gutter | C43: Rft | D43: =BE!#REF! -> #REF! | E43: =BE!#REF! -> #REF! | F43: Rft | G43: =D43*E43 -> #REF!
A44: 39 | B44: Gutter Bracket | C44: No | D44: =BE!#REF! -> #REF! | E44: =BE!#REF! -> #REF! | F44: No | G44: =D44*E44 -> #REF!
A45: 38 | B45: Silicon | C45: No | D45: =BE!#REF! -> #REF! | E45: =BE!#REF! -> #REF! | F45: No | G45: =D45*E45 -> #REF!
A46: 39 | B46: Down Spout | C46: Rft | D46: =BE!#REF! -> #REF! | E46: =BE!#REF! -> #REF! | F46: Rft | G46: =D46*E46 -> #REF!
A47: 40 | B47: 45 . Elbow | C47: No | D47: =BE!#REF! -> #REF! | E47: =BE!#REF! -> #REF! | F47: No | G47: =D47*E47 -> #REF!
A48: 41 | B48: 90 . Elbow | C48: No | D48: =BE!#REF! -> #REF! | E48: =BE!#REF! -> #REF! | F48: No | G48: =D48*E48 -> #REF!
...

Sheet Sheet1
B1: Slab
B2: First to Fifth Floor
B3: 32'-0" x 36'-0" Span
B4: B Bar | C4: 5 | D4: 2 | E4: =32/0.5+1 -> 65 | F4: 38 | K4: =F4*E4*D4*C4 -> 24700
C5: 5 | D5: 2 | E5: =36/0.5+1 -> 73 | F5: 34 | K5: =F5*E5*D5*C5 -> 24820
B6: T Bar | C6: 5 | D6: 2 | E6: =36/0.5+1 -> 73 | F6: 3 | K6: =F6*E6*D6*C6 -> 2190 | O6: =10/4 -> 2.5
C7: 5 | D7: 2 | E7: =2.5/0.5+1 -> 6 | F7: 38 | K7: =F7*E7*D7*C7 -> 2280 | O7: =11.75/3 -> 3.9166667
C8: 5 | D8: 2 | E8: =36/0.5+1 -> 73 | F8: =3.33+3.917+1 -> 8.247 | K8: =F8*E8*D8*C8 -> 6020.31 | O8: =10.25/4 -> 2.5625
C9: 5 | D9: 2 | E9: =(3.33+3.917)/0.5+1 -> 15.494 | F9: 38 | K9: =F9*E9*D9*C9 -> 5887.72 | O9: =10.25/3 -> 3.4166667
C10: 5 | D10: 2 | E10: =36/0.5+1 -> 73 | F10: =3.917+3.417+1 -> 8.334 | K10: =F10*E10*D10*C10 -> 6083.82
C11: 5 | D11: 2 | E11: =(3.917+3.417)/0.5+1 -> 15.668 | F11: 38 | K11: =F11*E11*D11*C11 -> 5953.84
C12: 5 | D12: =2*2 -> 4 | E12: =32/0.5+1 -> 65 | F12: 4.5 | K12: =F12*E12*D12*C12 -> 5850 | O12: =18/4 -> 4.5
C13: 5 | D13: =2*2 -> 4 | E13: =4.5/0.5+1 -> 10 | F13: =32+2 -> 34 | K13: =F13*E13*D13*C13 -> 6800 | O13: =18/3 -> 6
C14: 5 | D14: 2 | E14: =32/0.5+1 -> 65 | F14: 13 | K14: =F14*E14*D14*C14 -> 8450
C15: 5 | D15: 2 | E15: =12/0.5+1 -> 25 | F15: 34 | K15: =F15*E15*D15*C15 -> 8500
C16: 5 | D16: =2*2 -> 4 | E16: =10.25/0.5+1 -> 21.5 | F16: 6 | K16: =F16*E16*D16*C16 -> 2580
C17: 6 | D17: =2*2 -> 4 | E17: =6/0.5+1 -> 13 | F17: 10.5 | K17: =F17*E17*D17*C17 -> 3276
K18: =SUM(K4:K17) -> 113391.69

Sheet D Form
A2: Details of Measurement
A3: No. | B3: Particulars | C3: No. | F3: Measurement | I3: Dedu- ction | J3: Content | K3: Total of Each | L3: Unit
F4: L | G4: B | H4: H

Sheet BE Form
A2: Builder's Estimate
A3: No. | B3: Particular | C3: Unit | D3: Quantity | F3: Rate | G3: Per | H3: Amount

Sheet Sheet8

Sheet Sheet14
B5: Cement | C5: - | D5: 2350522
B6: Earth Cutting | C6: - | D6: 6441120
B7: M&E | C7: - | D7: 10312250
B8: Nails | C8: - | D8: 585424
B9: B.W | C9: - | D9: 459560
B10: M.S Rod | C10: - | D10: 748200
B11: Aluminium | C11: - | D11: 4879875
B12: I.G | C12: - | D12: 1260815
B13: Handrail | C13: - | D13: 1536140
B14: Cabinet | C14: - | D14: 117000
B15: Kitchen Counter Door | C15: - | D15: 233415
B16: Bamboo | C16: - | D16: 600072
... B18: Commercial Tax | C18: - | D18: 1523809.8
D19: =SUM(D5:D18) -> 32168298
B24: Ground Tank | C24: - | D24: 494220
E26: =D19-D24 -> 31674078

Sheet Sheet12
A1: Minbu
A2: Main Building | B2: - | C2: 874464556 | G2: Tender Amount | H2: - | I2: 940000000 | K2: Remark:
A3: Auxiliary Work | B3: - | C3: 24000000 | K3: Bath&WC,Kitchen - Beam 6 ထပ္စာက်န္
A4: M&E Work | B4: - | C4: 160000000 | G4: F.A | H4: - | I4: 39684
B5: - | C5: =SUM(C2:C4) -> 1058464556
A6: Topping Work | B6: - | C6: 9300000 | G6: P.A.E | H6: - | I6: =I2/I4 -> 23687.128
A7: Total | B7: - | C7: =C6+C5 -> 1067764556
A8: 0.05 | B8: - | C8: =C7*5% -> 53388228
A9: Grand Total | B9: - | C9: =C7+C8 -> 1.1211528e+09
A10: F.A | B10: - | C10: 39684
A11: P.A.E | B11: - | C11: =C9/C10 -> 28252.01
A13: Min့hla
A14: Main Building | B14: - | C14: =#REF! -> #REF! | G14: Tender Amount | H14: - | I14: 900000000 | K14: Remark:
A15: Auxiliary Work | B15: - | C15: 24000000 | K15: Bath&WC,Kitchen - Beam 5 ထပ္စာ
A16: M&E Work | B16: - | C16: 152000000 | G16: F.A | H16: - | I16: =C20 -> 35969 | K16: Extra Beam
B17: - | C17: =SUM(C14:C16) -> #REF! | K17: Kitchen Counter 1 ခုပို
A18: 0.05 | B18: - | C18: =C17/21 -> #REF! | G18: P.A.E | H18: - | I18: =I14/I16 -> 25021.546 | K18: Cantilever Slab (Green area, Roof,Verandah)
A19: Grand Total | B19: - | C19: =C18+C17 -> #REF! | K19: Window sunshade
A20: F.A | B20: - | C20: 35969 | G20: Tender Amount | H20: - | I20: =C19-I14 -> #REF! | K20: Topping - 9,300,000
A21: P.A.E | B21: - | C21: =C19/C20 -> #REF! | G21: ကြာဟေငြ | K21: Ceiling - 1,989,000
K22: Kitchen Counter Door - 3,267,810
A23: (+6%) Contingency | B23: - | C23: =C17*6% -> #REF! | G23: Tender Amount | H23: - | I23: =C27-I14 -> #REF! | K23: Glazed Tile(8"x12")Wall - 8,823,000 (91 Sud)
A24: Miscellaneous | B24: - | C24: 55000000 | G24: ကြာဟေငြ(All)
C25: =SUM(C23:C24) -> #REF!
A27: All Total | C27: =C25+C19 -> #REF! | G27: မင္းဘူးႏွင့္မင္းလွ | H27: - | I27: =C9-C19 -> #REF!
A28: P.A.E | B28: - | C28: =C27/C20 -> #REF! | G28: ကြာဟေငြ
A30: Gant Gaw
A31: Main Building | B31: - | C31: 792798644 | G31: Tender Amount | H31: - | I31: 999000000 | K31: Remark:
A32: Auxiliary Work | B32: - | C32: 18597145
A33: M&E Work | B33: - | C33: 140033333 | G33: F.A | H33: - | I33: 38880
B34: - | C34: =SUM(C31:C33) -> 951429122
A35: 0.05 | B35: - | C35: =C34*5% -> 47571456 | G35: P.A.E | H35: - | I35: =I31/I33 -> 25694.444
A36: Grand Total | B36: - | C36: =C35+C34 -> 9.9900058e+08
A38: F.A | B38: - | C38: 38880
A39: P.A.E | B39: - | C39: =C36/C38 -> 25694.459

Sheet Sheet7
A3: Rebar Size | C3: Linear Weight | E3: Diameter | G3: Lateral Area
A4: US | B4: SI | C4: lb/ft | D4: Kg/m | E4: in | F4: mm | G4: in2 | H4: mm2
B5: 6 | C5: 0.067 | D5: 0.222
B6: 6.5
B7: 7
B8: 8
B9: 9
B10: 10 | C10: 0.617 | D10: 0.188 | E10: 0.39 | F10: =E10*25.4 -> 9.906 | G10: =3.14/4*0.39*0.39 -> 0.1193985 | H10: =G10*645.16 -> 77.031136
B11: 11
B12: 12
B13: 13
B14: 14
B15: 15
B16: 16
B17: 17
B18: 18
B19: 19
B20: 20
B21: 21
B22: 22
... B25: 25

Sheet Sheet9
B4: 1 | C4: =11.75*2-(0.5*1.67)-(0.5*1) -> 22.165 | D4: 0.83 | E4: =15/12 -> 1.25 | G4: =E4*D4*C4*B4 -> 22.996187
B5: 1 | C5: =31.5-(1*1.67)-(2*1) -> 27.83 | D5: 0.83 | E5: =15/12 -> 1.25 | G5: =E5*D5*C5*B5 -> 28.873625
B6: 2 | C6: =96.5-(7*1.33) -> 87.19 | D6: 0.83 | E6: =15/12 -> 1.25 | G6: =E6*D6*C6*B6 -> 180.91925
B7: 2 | C7: =16.25*4-(4*1) -> 61 | D7: 0.83 | E7: =15/12 -> 1.25 | G7: =E7*D7*C7*B7 -> 126.575
B8: 2 | C8: =16.25*4-(4*1.67) -> 58.32 | D8: 0.83 | E8: =15/12 -> 1.25 | G8: =E8*D8*C8*B8 -> 121.014
B9: =2*2 -> 4 | C9: =11.75-(1.5*1) -> 10.25 | D9: 0.83 | E9: =1 -> 1 | G9: =E9*D9*C9*B9 -> 34.03
B10: =2*2 -> 4 | C10: =8.25-(1*1) -> 7.25 | D10: 0.83 | E10: =1 -> 1 | G10: =E10*D10*C10*B10 -> 24.07
B11: =2*2 -> 4 | C11: =11.75-(1*1.5)-(0.5*1.67) -> 9.415 | D11: 0.83 | E11: =1 -> 1 | G11: =E11*D11*C11*B11 -> 31.2578
B12: =2*2 -> 4 | C12: =11.75-(1.5*1.33) -> 9.755 | D12: 0.83 | E12: =1 -> 1 | G12: =E12*D12*C12*B12 -> 32.3866
B13: =2*2 -> 4 | C13: =16-(2*0.83) -> 14.34 | D13: 0.83 | E13: =1 -> 1 | G13: =E13*D13*C13*B13 -> 47.6088
B15: 2 | C15: =7-(1*1) -> 6 | D15: 0.83 | E15: =15/12 -> 1.25 | G15: =E15*D15*C15*B15 -> 12.45
B16: =2*2 -> 4 | C16: =13-(1*1.67)-(0.5*1) -> 10.83 | D16: 0.83 | E16: =15/12 -> 1.25 | G16: =E16*D16*C16*B16 -> 44.9445
B17: 4 | C17: =54-(4*1)-(2*1.5) -> 47 | D17: 0.83 | E17: =1 -> 1 | G17: =E17*D17*C17*B17 -> 156.04
B18: 2 | C18: =47-(3*1)-(2*1.5) -> 41 | D18: 0.83 | E18: =1 -> 1 | G18: =E18*D18*C18*B18 -> 68.06
B19: 2 | C19: =28-(3*1) -> 25 | D19: 0.83 | E19: =1 -> 1 | G19: =E19*D19*C19*B19 -> 41.5
B20: 2 | C20: =26-(2*1.5)-(1*0.83) -> 22.17 | D20: 0.83 | E20: =1 -> 1 | G20: =E20*D20*C20*B20 -> 36.8022
B21: 2 | C21: =31.25-(1.5*1.5)-(2*1) -> 27 | D21: 0.83 | E21: =1 -> 1 | G21: =E21*D21*C21*B21 -> 44.82
B22: =4*2 -> 8 | C22: =13-(1*0.83) -> 12.17 | D22: 0.83 | E22: =1 -> 1 | G22: =E22*D22*C22*B22 -> 80.8088
B23: =4*2 -> 8 | C23: =8.25-(1*0.83)+4*2 -> 15.42 | D23: 0.83 | E23: =1 -> 1 | G23: =E23*D23*C23*B23 -> 102.3888
B24: =2*2 -> 4 | C24: =10.5-(1*0.83)+4*2 -> 17.67 | D24: 0.83 | E24: =1 -> 1 | G24: =E24*D24*C24*B24 -> 58.6644
G25: =SUM(G4:G24) -> 1296.21
G27: =G25/100 -> 12.9621
G28: =G27*2.83 -> 36.682742

Sheet Sheet13

Sheet Sheet6
A1: 120'-0" x 54'-0" x 70' -6"(8 Unit 6 Storeyed Dormitory) Gant Ghaw
A2: Details of Measurement
A3: No | B3: Particulars | C3: No | F3: Measurement | I3: Dedu- ction | J3: Contents | K3: Total of each | L3: Unit
F4: L | G4: B | H4: H
A5: 1 | B5: 12"x12" Floor Glazed Tiles in Cement mortar ( 1:3 )
B6: Ground Floor
B7: Kitchen
B8: Floor | D8: 8 | E8: 1 | F8: 8 | G8: 8 | J8: =G8*F8*E8*D8 -> 512
B9: Bath & WC
B10: Floor | D10: 8 | E10: 1 | F10: 8 | G10: 5 | J10: =G10*F10*E10*D10 -> 320
B11: မီးဖိုခံု
B12: Slab | D12: 8 | E12: 1 | F12: 4 | G12: =1.67 -> 1.67 | J12: =F12*E12*D12*G12 -> 53.44
B13: Slab | D13: 8 | E13: 1 | F13: 5 | G13: =1.67 -> 1.67 | J13: =F13*E13*D13*G13 -> 66.8
D14: 8 | E14: 1 | F14: =(4+1.67)+(5+1.67) -> 12.34 | G14: 0.33 | J14: =F14*E14*D14*G14 -> 32.5776
B15: 1st to 5th Floor
B16: Kitchen
B17: Floor | C17: 5 | D17: 8 | E17: 1 | F17: 8 | G17: 8 | J17: =G17*F17*E17*D17*C17 -> 2560
B18: Bath & WC
B19: Floor | C19: 5 | D19: 8 | E19: 1 | F19: 8 | G19: 5 | J19: =G19*F19*E19*D19*C19 -> 1600
B20: မီးဖိုခံု
B21: Slab | C21: 5 | D21: 8 | E21: 1 | F21: 4 | G21: =1.67 -> 1.67 | J21: =G21*F21*E21*D21*C21 -> 267.2
B22: Slab | C22: 5 | D22: 8 | E22: 1 | F22: 5 | G22: =1.67 -> 1.67 | J22: =G22*F22*E22*D22*C22 -> 334
C23: 5 | D23: 8 | E23: 1 | F23: =(4+1.67)+(5+1.67) -> 12.34 | G23: =0.33 -> 0.33 | J23: =G23*F23*E23*D23*C23 -> 162.888
K24: =SUM(J8:J23) -> 5908.9056 | L24: Fs
K25: =K24/100 -> 59.089056 | L25: %Fs
B26: 12"x12" Glazes Floor Tiles | E26: = | F26: =K24 -> 5908.9056 | G26: Sheet
E27: = | F27: =F26*1.05 -> 6204.3509 | G27: Sheet | H27: (5% Wastage)
E28: = | F28: 6,230 Sht x 600 Ks | K28: =6230*600 -> 3738000 | L28: Kyats
A30: 2 | B30: 8"x12" Wall Glazed Tiles in Cement mortar ( 1:3 )
B31: Ground Floor
B32: Bath & WC
B33: Wall | D33: 8 | E33: 1 | F33: =8*2+5*2 -> 26 | H33: 6.5 | J33: =H33*F33*E33*D33 -> 1352
B34: Deduction
B35: TL01 (2'-6"x6'-6") | D35: 4 | E35: 1 | F35: 2.5 | H35: 6.5 | I35: =H35*F35*E35*D35 -> 65
B36: TL01A (2'-6"x6'-6") | D36: 4 | E36: 1 | F36: 2.5 | H36: 6.5 | I36: =H36*F36*E36*D36 -> 65
B37: မီးဖိုခံု
B38: Wall | D38: 8 | E38: 1 | F38: 4 | H38: 2 | J38: =H38*F38*E38*D38 -> 64
B39: Wall | D39: 8 | E39: 1 | F39: 5 | H39: 2 | J39: =H39*F39*E39*D39 -> 80
D40: 8 | E40: 2 | F40: 1.67 | H40: 2 | J40: =H40*F40*E40*D40 -> 53.44
D41: 8 | E41: 6 | F41: =0.38 -> 0.38 | H41: =3-0.33 -> 2.67 | J41: =H41*F41*E41*D41 -> 48.7008
...

Sheet Sheet10
A1: Aluminium Window (Gant Gaw)
A2: No. | B2: Royal AAA | C2: Quantity | D2: Unit | E2: Rate | F2: Amount(Kyats)
A3: 1 | B3: 2 Inches Casement with 4mm Glass | C3: 2400 | D3: Fs | E3: 7500 | F3: =E3*C3 -> 18000000
A4: 2 | B4: 3 Inches Slide Door with 4mm Glass | C4: 2050 | D4: Fs | E4: 4200 | F4: =E4*C4 -> 8610000
B5: Total Amount | F5: =SUM(F3:F4) -> 26610000
A7: No. | B7: R.I.E.C Group of Co.,Ltd. | C7: Quantity | D7: Unit | E7: Rate | F7: Amount(Kyats)
A8: 1 | B8: Aluminium Frame Fixed Panel With Glazing | C8: 1812 | D8: Fs | E8: 8000 | F8: =E8*C8 -> 14496000
A9: 2 | B9: Aluminium Frame Casement Window With Glazing | C9: 2016 | D9: Fs | E9: 8000 | F9: =E9*C9 -> 16128000
A10: 3 | B10: Aluminium Frame Sliding Window With Glazing | C10: 1218 | D10: Fs | E10: 6500 | F10: =E10*C10 -> 7917000
A11: 4 | B11: Aluminium Frame Fixed Fanlight Window With Glazing | C11: 288 | D11: Fs | E11: 4000 | F11: =E11*C11 -> 1152000
B12: Total Amount | F12: =SUM(F8:F11) -> 39693000 | G12: =F12*0.7 -> 27785100
B13: (30% Off) | F13: =F12*0.7 -> 27785100 | G13: =F13-F5 -> 1175100

Sheet Sheet11
B3: 1 | C3: 178560000 | D3: =(120*30)*2 -> 7200 | E3: =C3/D3 -> 24800 | H3: 33.71
B4: 2 | C4: 108360000 | D4: =(70*30)*2 -> 4200 | E4: =C4/D4 -> 25800 | H4: 264.02
B5: 3 | C5: 212520000 | D5: =(140*30)*2 -> 8400 | E5: =C5/D5 -> 25300 | H5: 40.21
B6: 4 | C6: 41520000 | D6: =(60*30) -> 1800 | E6: =C6/D6 -> 23066.667 | H6: 114.7
B7: 5 | C7: 44100000 | D7: =(60*30) -> 1800 | E7: =C7/D7 -> 24500 | H7: 23.21
B8: 6 | C8: 40500000 | D8: =(40*30) -> 1200 | E8: =C8/D8 -> 33750 | H8: 1.39
B9: 7 | C9: 247500000 | D9: =(103*25) -> 2575 | E9: =C9/D9 -> 96116.505 | H9: 3.77
B10: 8 | C10: 81000000 | D10: =(120*30) -> 3600 | E10: =C10/D10 -> 22500 | H10: 331.57
B11: 9 | C11: 60750000 | D11: =(25*52)*2 -> 2600 | E11: =C11/D11 -> 23365.385 | H11: 4.39
B12: 10 | C12: 40500000 | D12: =(60*30) -> 1800 | E12: =C12/D12 -> 22500 | H12: 16.64
B13: 11 | C13: 136620000 | D13: =(90*30) -> 2700 | E13: =C13/D13 -> 50600 | H13: 34.29
B14: 12 | C14: 182160000 | D14: =(120*30)*2 -> 7200 | E14: =C14/D14 -> 25300 | H14: 62.31
B15: 13 | C15: 148800000 | D15: =(100*30) -> 3000 | E15: =C15/D15 -> 49600 | H15: 2.69
B16: 14 | C16: 208320000 | D16: =(140*30)*2 -> 8400 | E16: =C16/D16 -> 24800 | H16: 14.3
B17: 15 | C17: 44100000 | D17: =(60*30) -> 1800 | E17: =C17/D17 -> 24500 | H17: =SUM(H3:H16) -> 947.2
B18: 16 | C18: 40500000 | D18: =(60*30) -> 1800 | E18: =C18/D18 -> 22500 | H18: 26.17
B19: 17 | C19: 208320000 | D19: =(140*30)*2 -> 8400 | E19: =C19/D19 -> 24800 | H19: 24.98
B20: 18 | C20: 60750000 | D20: =(90*30) -> 2700 | E20: =C20/D20 -> 22500 | H20: 3.35
B21: 19 | C21: 44100000 | D21: =(60*30) -> 1800 | E21: =C21/D21 -> 24500 | H21: =SUM(H18:H20) -> 54.5
B22: 20 | C22: 68750000 | D22: =(90*30) -> 2700 | E22: =C22/D22 -> 25462.963
B23: 21 | C23: 40500000 | D23: =(60*30) -> 1800 | E23: =C23/D23 -> 22500
C24: 40500000 | H24: =H21+H17 -> 1001.7
C25: 81000000
C26: 135000000
C27: 44100000
C28: 212520000
C29: 243000000

Sheet Detail
A1: One Storeyed RCC Building, Myat Lay Street
A2: 35'-0"x45'-0"x13'-0" Ht; | M2: =14.5+6+14.5 -> 35 | N2: =15*3 -> 45
A3: Details of Measurement
A4: ItemNo. | B4: Particulars | C4: No | F4: Measurement | I4: Dedu- ction | J4: Content | K4: Total of each | L4: Unit | M4: L/B | N4: H | O4: Q'ty | P4: Cover | Q4: Mark&Type Skirt | R4: Bar Diameter | S4: Spacing | T4: No of Bars | U4: Length of Bars | V4: Total Length | W4: Total Quantity ( Tensile)
F5: L | G5: B | H5: D/H | W5: 6 | X5: 6.5 | Y5: 10 | Z5: 12 | AA5: 16 | AB5: 18 | AC5: 20 | AD5: 22 | AE5: 25
A6: 1 | B6: Site clearing | E6: 1 | F6: =((35))+5+5 -> 45 | G6: =45+5+5 -> 55 | J6: =IF(I6=0,1,I6)*IF(H6=0,1,H6)*IF(G6=0,1,G6)*IF(F6=0,1,F6)*IF(E6=0,1,E6)*IF(D6=0,1,D6)*IF(C6=0,1,C6) -> 2475 | L6: Sft | AF6: =3658/25 -> 146.32 | AG6: =3048/25 -> 121.92 | AN6: =6+27+10.5*2 -> 54
E7: 1 | F7: 9.5 | G7: 5 | J7: =IF(I7=0,1,I7)*IF(H7=0,1,H7)*IF(G7=0,1,G7)*IF(F7=0,1,F7)*IF(E7=0,1,E7)*IF(D7=0,1,D7)*IF(C7=0,1,C7) -> 47.5 | L7: Sft
E8: 1 | F8: 5 | G8: 5 | J8: =IF(I8=0,1,I8)*IF(H8=0,1,H8)*IF(G8=0,1,G8)*IF(F8=0,1,F8)*IF(E8=0,1,E8)*IF(D8=0,1,D8)*IF(C8=0,1,C8) -> 25 | L8: Sft
E9: 1 | F9: 6 | G9: 5 | J9: =IF(I9=0,1,I9)*IF(H9=0,1,H9)*IF(G9=0,1,G9)*IF(F9=0,1,F9)*IF(E9=0,1,E9)*IF(D9=0,1,D9)*IF(C9=0,1,C9) -> 30 | L9: Sft
K10: =SUM(J6:J9) -> 2577.5 | L10: Sft | W10: =IF($R10=W$5,$V10,0) -> 0 | X10: =IF($R10=X$5,$V10,0) -> 0 | Y10: =IF($R10=Y$5,$V10,0) -> 0 | Z10: =IF($R10=Z$5,$V10,0) -> 0 | AA10: =IF($R10=AA$5,$V10,0) -> 0 | AB10: =IF($R10=AB$5,$V10,0) -> 0 | AC10: =IF($R10=AC$5,$V10,0) -> 0 | AD10: =IF($R10=AD$5,$V10,0) -> 0 | AE10: =IF($R10=AE$5,$V10,0) -> 0 | AF10: =AF6/12 -> 12.193333 | AG10: =AG6/12 -> 10.16
K11: =J6/100 -> 24.75 | L11: %Sft | W11: =IF($R11=W$5,$V11,0) -> 0 | X11: =IF($R11=X$5,$V11,0) -> 0 | Y11: =IF($R11=Y$5,$V11,0) -> 0 | Z11: =IF($R11=Z$5,$V11,0) -> 0 | AA11: =IF($R11=AA$5,$V11,0) -> 0 | AB11: =IF($R11=AB$5,$V11,0) -> 0 | AC11: =IF($R11=AC$5,$V11,0) -> 0 | AD11: =IF($R11=AD$5,$V11,0) -> 0 | AE11: =IF($R11=AE$5,$V11,0) -> 0
W12: =IF($R12=W$5,$V12,0) -> 0 | X12: =IF($R12=X$5,$V12,0) -> 0 | Y12: =IF($R12=Y$5,$V12,0) -> 0 | Z12: =IF($R12=Z$5,$V12,0) -> 0 | AA12: =IF($R12=AA$5,$V12,0) -> 0 | AB12: =IF($R12=AB$5,$V12,0) -> 0 | AC12: =IF($R12=AC$5,$V12,0) -> 0 | AD12: =IF($R12=AD$5,$V12,0) -> 0 | AE12: =IF($R12=AE$5,$V12,0) -> 0
A13: 2 | B13: Surveying & Levelling Work | W13: =IF($R13=W$5,$V13,0) -> 0 | X13: =IF($R13=X$5,$V13,0) -> 0 | Y13: =IF($R13=Y$5,$V13,0) -> 0 | Z13: =IF($R13=Z$5,$V13,0) -> 0 | AA13: =IF($R13=AA$5,$V13,0) -> 0 | AB13: =IF($R13=AB$5,$V13,0) -> 0 | AC13: =IF($R13=AC$5,$V13,0) -> 0 | AD13: =IF($R13=AD$5,$V13,0) -> 0 | AE13: =IF($R13=AE$5,$V13,0) -> 0 | AF13: =3.142*7*7*40.5 -> 6235.299 | AG13: =AF14/0.52 -> 122.89077
